{
	yslice_prob = {
		{
			prob = 254,
			ypos = 0
		},
		{
			prob = 254,
			ypos = 1
		},
		{
			prob = 254,
			ypos = 2
		},
		{
			prob = 254,
			ypos = 3
		},
		{
			prob = 254,
			ypos = 4
		},
		{
			prob = 254,
			ypos = 5
		},
		{
			prob = 254,
			ypos = 6
		},
		{
			prob = 254,
			ypos = 7
		},
		{
			prob = 254,
			ypos = 8
		},
		{
			prob = 254,
			ypos = 9
		},
		{
			prob = 254,
			ypos = 10
		},
		{
			prob = 254,
			ypos = 11
		},
		{
			prob = 254,
			ypos = 12
		},
		{
			prob = 254,
			ypos = 13
		}
	},
	data = {
		{
			param2 = 0,
			name = "air",
			prob = 254
		},
		{
			param2 = 0,
			name = "air",
			prob = 254
		},
		{
			param2 = 0,
			name = "air",
			prob = 254
		},
		{
			param2 = 0,
			name = "air",
			prob = 254
		},
		{
			param2 = 0,
			name = "air",
			prob = 254
		},
		{
			param2 = 0,
			name = "air",
			prob = 254
		},
		{
			param2 = 0,
			name = "air",
			prob = 254
		},
		{
			param2 = 0,
			name = "air",
			prob = 254
		},
		{
			param2 = 0,
			name = "air",
			prob = 254
		},
		{
			param2 = 0,
			name = "air",
			prob = 254
		},
		{
			param2 = 0,
			name = "air",
			prob = 254
		},
		{
			param2 = 0,
			name = "air",
			prob = 254
		},
		{
			param2 = 0,
			name = "air",
			prob = 254
		},
		{
			param2 = 0,
			name = "air",
			prob = 254
		},
		{
			param2 = 0,
			name = "air",
			prob = 254
		},
		{
			param2 = 0,
			name = "air",
			prob = 254
		},
		{
			param2 = 0,
			name = "air",
			prob = 254
		},
		{
			param2 = 0,
			name = "air",
			prob = 254
		},
		{
			param2 = 0,
			name = "air",
			prob = 254
		},
		{
			param2 = 0,
			name = "air",
			prob = 254
		},
		{
			param2 = 0,
			name = "air",
			prob = 254
		},
		{
			param2 = 0,
			name = "air",
			prob = 254
		},
		{
			param2 = 0,
			name = "air",
			prob = 254
		},
		{
			param2 = 0,
			name = "air",
			prob = 254
		},
		{
			param2 = 0,
			name = "air",
			prob = 254
		},
		{
			param2 = 0,
			name = "air",
			prob = 254
		},
		{
			param2 = 0,
			name = "air",
			prob = 254
		},
		{
			param2 = 0,
			name = "air",
			prob = 254
		},
		{
			param2 = 0,
			name = "air",
			prob = 254
		},
		{
			param2 = 0,
			name = "air",
			prob = 254
		},
		{
			param2 = 0,
			name = "air",
			prob = 254
		},
		{
			param2 = 0,
			name = "air",
			prob = 254
		},
		{
			param2 = 1,
			name = "default:leaves",
			prob = 254
		},
		{
			param2 = 0,
			name = "air",
			prob = 254
		},
		{
			param2 = 0,
			name = "air",
			prob = 254
		},
		{
			param2 = 0,
			name = "air",
			prob = 254
		},
		{
			param2 = 0,
			name = "air",
			prob = 254
		},
		{
			param2 = 0,
			name = "air",
			prob = 254
		},
		{
			param2 = 0,
			name = "air",
			prob = 254
		},
		{
			param2 = 0,
			name = "air",
			prob = 254
		},
		{
			param2 = 0,
			name = "air",
			prob = 254
		},
		{
			param2 = 0,
			name = "air",
			prob = 254
		},
		{
			param2 = 0,
			name = "air",
			prob = 254
		},
		{
			param2 = 0,
			name = "air",
			prob = 254
		},
		{
			param2 = 0,
			name = "air",
			prob = 254
		},
		{
			param2 = 0,
			name = "air",
			prob = 254
		},
		{
			param2 = 0,
			name = "air",
			prob = 254
		},
		{
			param2 = 0,
			name = "air",
			prob = 254
		},
		{
			param2 = 1,
			name = "default:leaves",
			prob = 254
		},
		{
			param2 = 0,
			name = "air",
			prob = 254
		},
		{
			param2 = 0,
			name = "air",
			prob = 254
		},
		{
			param2 = 0,
			name = "air",
			prob = 254
		},
		{
			param2 = 0,
			name = "air",
			prob = 254
		},
		{
			param2 = 0,
			name = "air",
			prob = 254
		},
		{
			param2 = 0,
			name = "air",
			prob = 254
		},
		{
			param2 = 0,
			name = "air",
			prob = 254
		},
		{
			param2 = 0,
			name = "air",
			prob = 254
		},
		{
			param2 = 0,
			name = "air",
			prob = 254
		},
		{
			param2 = 0,
			name = "air",
			prob = 254
		},
		{
			param2 = 0,
			name = "air",
			prob = 254
		},
		{
			param2 = 0,
			name = "air",
			prob = 254
		},
		{
			param2 = 0,
			name = "air",
			prob = 254
		},
		{
			param2 = 0,
			name = "air",
			prob = 254
		},
		{
			param2 = 0,
			name = "air",
			prob = 254
		},
		{
			param2 = 0,
			name = "air",
			prob = 254
		},
		{
			param2 = 0,
			name = "air",
			prob = 254
		},
		{
			param2 = 0,
			name = "air",
			prob = 254
		},
		{
			param2 = 0,
			name = "air",
			prob = 254
		},
		{
			param2 = 0,
			name = "air",
			prob = 254
		},
		{
			param2 = 0,
			name = "air",
			prob = 254
		},
		{
			param2 = 0,
			name = "air",
			prob = 254
		},
		{
			param2 = 0,
			name = "air",
			prob = 254
		},
		{
			param2 = 0,
			name = "air",
			prob = 254
		},
		{
			param2 = 0,
			name = "air",
			prob = 254
		},
		{
			param2 = 0,
			name = "air",
			prob = 254
		},
		{
			param2 = 0,
			name = "air",
			prob = 254
		},
		{
			param2 = 0,
			name = "air",
			prob = 254
		},
		{
			param2 = 0,
			name = "air",
			prob = 254
		},
		{
			param2 = 0,
			name = "air",
			prob = 254
		},
		{
			param2 = 0,
			name = "air",
			prob = 254
		},
		{
			param2 = 0,
			name = "air",
			prob = 254
		},
		{
			param2 = 0,
			name = "air",
			prob = 254
		},
		{
			param2 = 0,
			name = "air",
			prob = 254
		},
		{
			param2 = 0,
			name = "air",
			prob = 254
		},
		{
			param2 = 0,
			name = "air",
			prob = 254
		},
		{
			param2 = 0,
			name = "air",
			prob = 254
		},
		{
			param2 = 0,
			name = "air",
			prob = 254
		},
		{
			param2 = 0,
			name = "air",
			prob = 254
		},
		{
			param2 = 1,
			name = "default:leaves",
			prob = 254
		},
		{
			param2 = 0,
			name = "air",
			prob = 254
		},
		{
			param2 = 0,
			name = "air",
			prob = 254
		},
		{
			param2 = 0,
			name = "air",
			prob = 254
		},
		{
			param2 = 1,
			name = "default:leaves",
			prob = 254
		},
		{
			param2 = 0,
			name = "air",
			prob = 254
		},
		{
			param2 = 0,
			name = "air",
			prob = 254
		},
		{
			param2 = 0,
			name = "air",
			prob = 254
		},
		{
			param2 = 0,
			name = "air",
			prob = 254
		},
		{
			param2 = 0,
			name = "air",
			prob = 254
		},
		{
			param2 = 0,
			name = "air",
			prob = 254
		},
		{
			param2 = 0,
			name = "air",
			prob = 254
		},
		{
			param2 = 0,
			name = "air",
			prob = 254
		},
		{
			param2 = 1,
			name = "default:leaves",
			prob = 254
		},
		{
			param2 = 0,
			name = "air",
			prob = 254
		},
		{
			param2 = 0,
			name = "air",
			prob = 254
		},
		{
			param2 = 1,
			name = "default:leaves",
			prob = 254
		},
		{
			param2 = 0,
			name = "air",
			prob = 254
		},
		{
			param2 = 0,
			name = "air",
			prob = 254
		},
		{
			param2 = 1,
			name = "default:leaves",
			prob = 254
		},
		{
			param2 = 1,
			name = "default:leaves",
			prob = 254
		},
		{
			param2 = 0,
			name = "air",
			prob = 254
		},
		{
			param2 = 0,
			name = "air",
			prob = 254
		},
		{
			param2 = 0,
			name = "air",
			prob = 254
		},
		{
			param2 = 0,
			name = "air",
			prob = 254
		},
		{
			param2 = 0,
			name = "air",
			prob = 254
		},
		{
			param2 = 0,
			name = "air",
			prob = 254
		},
		{
			param2 = 0,
			name = "air",
			prob = 254
		},
		{
			param2 = 1,
			name = "default:leaves",
			prob = 254
		},
		{
			param2 = 0,
			name = "air",
			prob = 254
		},
		{
			param2 = 1,
			name = "default:leaves",
			prob = 254
		},
		{
			param2 = 0,
			name = "air",
			prob = 254
		},
		{
			param2 = 0,
			name = "air",
			prob = 254
		},
		{
			param2 = 0,
			name = "air",
			prob = 254
		},
		{
			param2 = 1,
			name = "default:leaves",
			prob = 254
		},
		{
			param2 = 1,
			name = "default:leaves",
			prob = 254
		},
		{
			param2 = 0,
			name = "air",
			prob = 254
		},
		{
			param2 = 0,
			name = "air",
			prob = 254
		},
		{
			param2 = 0,
			name = "air",
			prob = 254
		},
		{
			param2 = 0,
			name = "air",
			prob = 254
		},
		{
			param2 = 0,
			name = "air",
			prob = 254
		},
		{
			param2 = 0,
			name = "air",
			prob = 254
		},
		{
			param2 = 0,
			name = "air",
			prob = 254
		},
		{
			param2 = 0,
			name = "air",
			prob = 254
		},
		{
			param2 = 1,
			name = "default:leaves",
			prob = 254
		},
		{
			param2 = 0,
			name = "air",
			prob = 254
		},
		{
			param2 = 0,
			name = "air",
			prob = 254
		},
		{
			param2 = 0,
			name = "air",
			prob = 254
		},
		{
			param2 = 0,
			name = "air",
			prob = 254
		},
		{
			param2 = 0,
			name = "air",
			prob = 254
		},
		{
			param2 = 0,
			name = "air",
			prob = 254
		},
		{
			param2 = 0,
			name = "air",
			prob = 254
		},
		{
			param2 = 0,
			name = "air",
			prob = 254
		},
		{
			param2 = 0,
			name = "air",
			prob = 254
		},
		{
			param2 = 0,
			name = "default:tree",
			prob = 254
		},
		{
			param2 = 0,
			name = "air",
			prob = 254
		},
		{
			param2 = 0,
			name = "air",
			prob = 254
		},
		{
			param2 = 0,
			name = "air",
			prob = 254
		},
		{
			param2 = 0,
			name = "air",
			prob = 254
		},
		{
			param2 = 0,
			name = "default:tree",
			prob = 254
		},
		{
			param2 = 0,
			name = "air",
			prob = 254
		},
		{
			param2 = 0,
			name = "air",
			prob = 254
		},
		{
			param2 = 0,
			name = "air",
			prob = 254
		},
		{
			param2 = 0,
			name = "air",
			prob = 254
		},
		{
			param2 = 0,
			name = "default:tree",
			prob = 254
		},
		{
			param2 = 0,
			name = "air",
			prob = 254
		},
		{
			param2 = 0,
			name = "air",
			prob = 254
		},
		{
			param2 = 0,
			name = "air",
			prob = 254
		},
		{
			param2 = 0,
			name = "air",
			prob = 254
		},
		{
			param2 = 0,
			name = "default:tree",
			prob = 254
		},
		{
			param2 = 0,
			name = "air",
			prob = 254
		},
		{
			param2 = 1,
			name = "default:leaves",
			prob = 254
		},
		{
			param2 = 0,
			name = "air",
			prob = 254
		},
		{
			param2 = 0,
			name = "air",
			prob = 254
		},
		{
			param2 = 0,
			name = "default:tree",
			prob = 254
		},
		{
			param2 = 1,
			name = "default:leaves",
			prob = 254
		},
		{
			param2 = 0,
			name = "air",
			prob = 254
		},
		{
			param2 = 0,
			name = "air",
			prob = 254
		},
		{
			param2 = 0,
			name = "air",
			prob = 254
		},
		{
			param2 = 0,
			name = "default:tree",
			prob = 254
		},
		{
			param2 = 0,
			name = "air",
			prob = 254
		},
		{
			param2 = 0,
			name = "air",
			prob = 254
		},
		{
			param2 = 1,
			name = "default:leaves",
			prob = 254
		},
		{
			param2 = 0,
			name = "air",
			prob = 254
		},
		{
			param2 = 0,
			name = "default:tree",
			prob = 254
		},
		{
			param2 = 0,
			name = "air",
			prob = 254
		},
		{
			param2 = 1,
			name = "default:leaves",
			prob = 254
		},
		{
			param2 = 0,
			name = "air",
			prob = 254
		},
		{
			param2 = 1,
			name = "default:leaves",
			prob = 254
		},
		{
			param2 = 0,
			name = "default:tree",
			prob = 254
		},
		{
			param2 = 1,
			name = "default:leaves",
			prob = 254
		},
		{
			param2 = 0,
			name = "air",
			prob = 254
		},
		{
			param2 = 0,
			name = "air",
			prob = 254
		},
		{
			param2 = 0,
			name = "air",
			prob = 254
		},
		{
			param2 = 0,
			name = "default:tree",
			prob = 254
		},
		{
			param2 = 0,
			name = "air",
			prob = 254
		},
		{
			param2 = 0,
			name = "air",
			prob = 254
		},
		{
			param2 = 1,
			name = "default:leaves",
			prob = 254
		},
		{
			param2 = 0,
			name = "air",
			prob = 254
		},
		{
			param2 = 0,
			name = "default:tree",
			prob = 254
		},
		{
			param2 = 0,
			name = "air",
			prob = 254
		},
		{
			param2 = 0,
			name = "air",
			prob = 254
		},
		{
			param2 = 0,
			name = "air",
			prob = 254
		},
		{
			param2 = 1,
			name = "default:leaves",
			prob = 254
		},
		{
			param2 = 0,
			name = "default:tree",
			prob = 254
		},
		{
			param2 = 1,
			name = "default:leaves",
			prob = 254
		},
		{
			param2 = 0,
			name = "air",
			prob = 254
		},
		{
			param2 = 0,
			name = "air",
			prob = 254
		},
		{
			param2 = 0,
			name = "air",
			prob = 254
		},
		{
			param2 = 1,
			name = "default:tree",
			prob = 254
		},
		{
			param2 = 0,
			name = "air",
			prob = 254
		},
		{
			param2 = 0,
			name = "air",
			prob = 254
		},
		{
			param2 = 0,
			name = "air",
			prob = 254
		},
		{
			param2 = 1,
			name = "default:leaves",
			prob = 254
		},
		{
			param2 = 1,
			name = "default:tree",
			prob = 254
		},
		{
			param2 = 1,
			name = "default:leaves",
			prob = 254
		},
		{
			param2 = 0,
			name = "air",
			prob = 254
		},
		{
			param2 = 0,
			name = "air",
			prob = 254
		},
		{
			param2 = 0,
			name = "air",
			prob = 254
		},
		{
			param2 = 1,
			name = "default:leaves",
			prob = 254
		},
		{
			param2 = 0,
			name = "air",
			prob = 254
		},
		{
			param2 = 0,
			name = "air",
			prob = 254
		},
		{
			param2 = 0,
			name = "air",
			prob = 254
		},
		{
			param2 = 0,
			name = "air",
			prob = 254
		},
		{
			param2 = 0,
			name = "air",
			prob = 254
		},
		{
			param2 = 0,
			name = "air",
			prob = 254
		},
		{
			param2 = 0,
			name = "air",
			prob = 254
		},
		{
			param2 = 0,
			name = "air",
			prob = 254
		},
		{
			param2 = 0,
			name = "air",
			prob = 254
		},
		{
			param2 = 0,
			name = "air",
			prob = 254
		},
		{
			param2 = 0,
			name = "air",
			prob = 254
		},
		{
			param2 = 0,
			name = "air",
			prob = 254
		},
		{
			param2 = 0,
			name = "air",
			prob = 254
		},
		{
			param2 = 0,
			name = "air",
			prob = 254
		},
		{
			param2 = 0,
			name = "air",
			prob = 254
		},
		{
			param2 = 0,
			name = "air",
			prob = 254
		},
		{
			param2 = 0,
			name = "air",
			prob = 254
		},
		{
			param2 = 0,
			name = "air",
			prob = 254
		},
		{
			param2 = 0,
			name = "air",
			prob = 254
		},
		{
			param2 = 0,
			name = "air",
			prob = 254
		},
		{
			param2 = 1,
			name = "default:leaves",
			prob = 254
		},
		{
			param2 = 0,
			name = "air",
			prob = 254
		},
		{
			param2 = 0,
			name = "air",
			prob = 254
		},
		{
			param2 = 0,
			name = "air",
			prob = 254
		},
		{
			param2 = 1,
			name = "default:leaves",
			prob = 254
		},
		{
			param2 = 0,
			name = "air",
			prob = 254
		},
		{
			param2 = 0,
			name = "air",
			prob = 254
		},
		{
			param2 = 0,
			name = "air",
			prob = 254
		},
		{
			param2 = 0,
			name = "air",
			prob = 254
		},
		{
			param2 = 0,
			name = "air",
			prob = 254
		},
		{
			param2 = 0,
			name = "air",
			prob = 254
		},
		{
			param2 = 0,
			name = "air",
			prob = 254
		},
		{
			param2 = 1,
			name = "default:leaves",
			prob = 254
		},
		{
			param2 = 0,
			name = "air",
			prob = 254
		},
		{
			param2 = 0,
			name = "air",
			prob = 254
		},
		{
			param2 = 0,
			name = "air",
			prob = 254
		},
		{
			param2 = 0,
			name = "air",
			prob = 254
		},
		{
			param2 = 0,
			name = "air",
			prob = 254
		},
		{
			param2 = 1,
			name = "default:leaves",
			prob = 254
		},
		{
			param2 = 1,
			name = "default:leaves",
			prob = 254
		},
		{
			param2 = 1,
			name = "default:leaves",
			prob = 254
		},
		{
			param2 = 0,
			name = "air",
			prob = 254
		},
		{
			param2 = 0,
			name = "air",
			prob = 254
		},
		{
			param2 = 0,
			name = "air",
			prob = 254
		},
		{
			param2 = 0,
			name = "air",
			prob = 254
		},
		{
			param2 = 0,
			name = "air",
			prob = 254
		},
		{
			param2 = 0,
			name = "air",
			prob = 254
		},
		{
			param2 = 0,
			name = "air",
			prob = 254
		},
		{
			param2 = 1,
			name = "default:leaves",
			prob = 254
		},
		{
			param2 = 0,
			name = "air",
			prob = 254
		},
		{
			param2 = 1,
			name = "default:leaves",
			prob = 254
		},
		{
			param2 = 0,
			name = "air",
			prob = 254
		},
		{
			param2 = 0,
			name = "air",
			prob = 254
		},
		{
			param2 = 0,
			name = "air",
			prob = 254
		},
		{
			param2 = 1,
			name = "default:leaves",
			prob = 254
		},
		{
			param2 = 0,
			name = "air",
			prob = 254
		},
		{
			param2 = 0,
			name = "air",
			prob = 254
		},
		{
			param2 = 0,
			name = "air",
			prob = 254
		},
		{
			param2 = 0,
			name = "air",
			prob = 254
		},
		{
			param2 = 0,
			name = "air",
			prob = 254
		},
		{
			param2 = 0,
			name = "air",
			prob = 254
		},
		{
			param2 = 0,
			name = "air",
			prob = 254
		},
		{
			param2 = 0,
			name = "air",
			prob = 254
		},
		{
			param2 = 0,
			name = "air",
			prob = 254
		},
		{
			param2 = 1,
			name = "default:leaves",
			prob = 254
		},
		{
			param2 = 0,
			name = "air",
			prob = 254
		},
		{
			param2 = 0,
			name = "air",
			prob = 254
		},
		{
			param2 = 0,
			name = "air",
			prob = 254
		},
		{
			param2 = 0,
			name = "air",
			prob = 254
		},
		{
			param2 = 0,
			name = "air",
			prob = 254
		},
		{
			param2 = 0,
			name = "air",
			prob = 254
		},
		{
			param2 = 0,
			name = "air",
			prob = 254
		},
		{
			param2 = 0,
			name = "air",
			prob = 254
		},
		{
			param2 = 0,
			name = "air",
			prob = 254
		},
		{
			param2 = 0,
			name = "air",
			prob = 254
		},
		{
			param2 = 0,
			name = "air",
			prob = 254
		},
		{
			param2 = 0,
			name = "air",
			prob = 254
		},
		{
			param2 = 0,
			name = "air",
			prob = 254
		},
		{
			param2 = 0,
			name = "air",
			prob = 254
		},
		{
			param2 = 0,
			name = "air",
			prob = 254
		},
		{
			param2 = 0,
			name = "air",
			prob = 254
		},
		{
			param2 = 0,
			name = "air",
			prob = 254
		},
		{
			param2 = 0,
			name = "air",
			prob = 254
		},
		{
			param2 = 0,
			name = "air",
			prob = 254
		},
		{
			param2 = 0,
			name = "air",
			prob = 254
		},
		{
			param2 = 0,
			name = "air",
			prob = 254
		},
		{
			param2 = 0,
			name = "air",
			prob = 254
		},
		{
			param2 = 0,
			name = "air",
			prob = 254
		},
		{
			param2 = 0,
			name = "air",
			prob = 254
		},
		{
			param2 = 0,
			name = "air",
			prob = 254
		},
		{
			param2 = 0,
			name = "air",
			prob = 254
		},
		{
			param2 = 0,
			name = "air",
			prob = 254
		},
		{
			param2 = 0,
			name = "air",
			prob = 254
		},
		{
			param2 = 0,
			name = "air",
			prob = 254
		},
		{
			param2 = 0,
			name = "air",
			prob = 254
		},
		{
			param2 = 0,
			name = "air",
			prob = 254
		},
		{
			param2 = 0,
			name = "air",
			prob = 254
		},
		{
			param2 = 0,
			name = "air",
			prob = 254
		},
		{
			param2 = 0,
			name = "air",
			prob = 254
		},
		{
			param2 = 0,
			name = "air",
			prob = 254
		},
		{
			param2 = 0,
			name = "air",
			prob = 254
		},
		{
			param2 = 0,
			name = "air",
			prob = 254
		},
		{
			param2 = 0,
			name = "air",
			prob = 254
		},
		{
			param2 = 0,
			name = "air",
			prob = 254
		},
		{
			param2 = 1,
			name = "default:leaves",
			prob = 254
		},
		{
			param2 = 0,
			name = "air",
			prob = 254
		},
		{
			param2 = 0,
			name = "air",
			prob = 254
		},
		{
			param2 = 0,
			name = "air",
			prob = 254
		},
		{
			param2 = 0,
			name = "air",
			prob = 254
		},
		{
			param2 = 0,
			name = "air",
			prob = 254
		},
		{
			param2 = 0,
			name = "air",
			prob = 254
		},
		{
			param2 = 0,
			name = "air",
			prob = 254
		},
		{
			param2 = 0,
			name = "air",
			prob = 254
		},
		{
			param2 = 0,
			name = "air",
			prob = 254
		},
		{
			param2 = 0,
			name = "air",
			prob = 254
		},
		{
			param2 = 0,
			name = "air",
			prob = 254
		},
		{
			param2 = 0,
			name = "air",
			prob = 254
		},
		{
			param2 = 0,
			name = "air",
			prob = 254
		},
		{
			param2 = 0,
			name = "air",
			prob = 254
		},
		{
			param2 = 0,
			name = "air",
			prob = 254
		},
		{
			param2 = 0,
			name = "air",
			prob = 254
		},
		{
			param2 = 0,
			name = "air",
			prob = 254
		},
		{
			param2 = 0,
			name = "air",
			prob = 254
		},
		{
			param2 = 0,
			name = "air",
			prob = 254
		},
		{
			param2 = 0,
			name = "air",
			prob = 254
		},
		{
			param2 = 0,
			name = "air",
			prob = 254
		},
		{
			param2 = 0,
			name = "air",
			prob = 254
		},
		{
			param2 = 0,
			name = "air",
			prob = 254
		},
		{
			param2 = 0,
			name = "air",
			prob = 254
		},
		{
			param2 = 0,
			name = "air",
			prob = 254
		},
		{
			param2 = 0,
			name = "air",
			prob = 254
		},
		{
			param2 = 0,
			name = "air",
			prob = 254
		},
		{
			param2 = 0,
			name = "air",
			prob = 254
		},
		{
			param2 = 0,
			name = "air",
			prob = 254
		},
		{
			param2 = 0,
			name = "air",
			prob = 254
		},
		{
			param2 = 0,
			name = "air",
			prob = 254
		},
		{
			param2 = 0,
			name = "air",
			prob = 254
		},
		{
			param2 = 0,
			name = "air",
			prob = 254
		},
		{
			param2 = 0,
			name = "air",
			prob = 254
		},
		{
			param2 = 0,
			name = "air",
			prob = 254
		},
		{
			param2 = 0,
			name = "air",
			prob = 254
		},
		{
			param2 = 0,
			name = "air",
			prob = 254
		}
	},
	size = {
		y = 14,
		x = 5,
		z = 5
	}
}