{
	yslice_prob = {
		{
			prob = 254,
			ypos = 0
		},
		{
			prob = 254,
			ypos = 1
		},
		{
			prob = 254,
			ypos = 2
		},
		{
			prob = 254,
			ypos = 3
		},
		{
			prob = 254,
			ypos = 4
		}
	},
	data = {
		{
			param2 = 0,
			name = "default:stone",
			prob = 254
		},
		{
			param2 = 0,
			name = "default:stone",
			prob = 254
		},
		{
			param2 = 0,
			name = "default:stone",
			prob = 254
		},
		{
			param2 = 0,
			name = "default:stone",
			prob = 254
		},
		{
			param2 = 0,
			name = "default:stone",
			prob = 254
		},
		{
			param2 = 0,
			name = "default:stone",
			prob = 254
		},
		{
			param2 = 0,
			name = "default:stonebrick",
			prob = 254
		},
		{
			param2 = 0,
			name = "default:stonebrick",
			prob = 254
		},
		{
			param2 = 0,
			name = "default:stonebrick",
			prob = 254
		},
		{
			param2 = 0,
			name = "default:stone",
			prob = 254
		},
		{
			param2 = 0,
			name = "default:stone",
			prob = 254
		},
		{
			param2 = 0,
			name = "default:cobble",
			prob = 254
		},
		{
			param2 = 0,
			name = "default:cobble",
			prob = 254
		},
		{
			param2 = 0,
			name = "default:cobble",
			prob = 254
		},
		{
			param2 = 0,
			name = "default:stone",
			prob = 254
		},
		{
			param2 = 0,
			name = "default:stone",
			prob = 254
		},
		{
			param2 = 0,
			name = "default:cobble",
			prob = 254
		},
		{
			param2 = 0,
			name = "default:cobble",
			prob = 254
		},
		{
			param2 = 0,
			name = "default:cobble",
			prob = 254
		},
		{
			param2 = 0,
			name = "default:stone",
			prob = 254
		},
		{
			param2 = 0,
			name = "default:stone",
			prob = 254
		},
		{
			param2 = 0,
			name = "default:stone",
			prob = 254
		},
		{
			param2 = 0,
			name = "default:stone",
			prob = 254
		},
		{
			param2 = 0,
			name = "default:stone",
			prob = 254
		},
		{
			param2 = 0,
			name = "default:stone",
			prob = 254
		},
		{
			param2 = 0,
			name = "default:stone",
			prob = 254
		},
		{
			param2 = 0,
			name = "decoblocks:old_stone_tiles_with_dirt",
			prob = 254
		},
		{
			param2 = 0,
			name = "decoblocks:old_stone_tiles",
			prob = 254
		},
		{
			param2 = 0,
			name = "decoblocks:old_stone_tiles",
			prob = 254
		},
		{
			param2 = 0,
			name = "default:stone",
			prob = 254
		},
		{
			param2 = 0,
			name = "default:stonebrick",
			prob = 254
		},
		{
			param2 = 0,
			name = "air",
			prob = 254
		},
		{
			param2 = 0,
			name = "air",
			prob = 254
		},
		{
			param2 = 0,
			name = "air",
			prob = 254
		},
		{
			param2 = 0,
			name = "default:stonebrick",
			prob = 254
		},
		{
			param2 = 0,
			name = "default:cobble",
			prob = 254
		},
		{
			param2 = 0,
			name = "air",
			prob = 254
		},
		{
			param2 = 0,
			name = "air",
			prob = 254
		},
		{
			param2 = 0,
			name = "air",
			prob = 254
		},
		{
			param2 = 0,
			name = "default:cobble",
			prob = 254
		},
		{
			param2 = 0,
			name = "default:cobble",
			prob = 254
		},
		{
			param2 = 0,
			name = "air",
			prob = 254
		},
		{
			param2 = 0,
			name = "air",
			prob = 254
		},
		{
			param2 = 0,
			name = "air",
			prob = 254
		},
		{
			param2 = 0,
			name = "default:cobble",
			prob = 254
		},
		{
			param2 = 0,
			name = "default:stone",
			prob = 254
		},
		{
			param2 = 0,
			name = "default:cobble",
			prob = 254
		},
		{
			param2 = 0,
			name = "default:cobble",
			prob = 254
		},
		{
			param2 = 0,
			name = "default:cobble",
			prob = 254
		},
		{
			param2 = 0,
			name = "default:stone",
			prob = 254
		},
		{
			param2 = 0,
			name = "default:stone",
			prob = 254
		},
		{
			param2 = 0,
			name = "decoblocks:old_stone_tiles_with_dirt",
			prob = 254
		},
		{
			param2 = 0,
			name = "decoblocks:old_stone_tiles_with_dirt",
			prob = 254
		},
		{
			param2 = 0,
			name = "decoblocks:old_stone_tiles_with_dirt",
			prob = 254
		},
		{
			param2 = 0,
			name = "default:stone",
			prob = 254
		},
		{
			param2 = 0,
			name = "default:stonebrick",
			prob = 254
		},
		{
			param2 = 0,
			name = "air",
			prob = 254
		},
		{
			param2 = 2,
			name = "mobs_m:mimic_chest",
			prob = 254
		},
		{
			param2 = 0,
			name = "air",
			prob = 254
		},
		{
			param2 = 0,
			name = "default:stonebrick",
			prob = 254
		},
		{
			param2 = 0,
			name = "default:cobble",
			prob = 254
		},
		{
			param2 = 0,
			name = "air",
			prob = 254
		},
		{
			param2 = 0,
			name = "air",
			prob = 254
		},
		{
			param2 = 0,
			name = "air",
			prob = 254
		},
		{
			param2 = 0,
			name = "default:cobble",
			prob = 254
		},
		{
			param2 = 0,
			name = "default:cobble",
			prob = 254
		},
		{
			param2 = 0,
			name = "air",
			prob = 254
		},
		{
			param2 = 0,
			name = "default:torch_ceiling",
			prob = 254
		},
		{
			param2 = 0,
			name = "air",
			prob = 254
		},
		{
			param2 = 0,
			name = "default:cobble",
			prob = 254
		},
		{
			param2 = 0,
			name = "default:stone",
			prob = 254
		},
		{
			param2 = 0,
			name = "default:cobble",
			prob = 254
		},
		{
			param2 = 0,
			name = "default:cobble",
			prob = 254
		},
		{
			param2 = 0,
			name = "default:cobble",
			prob = 254
		},
		{
			param2 = 0,
			name = "default:stone",
			prob = 254
		},
		{
			param2 = 0,
			name = "default:stone",
			prob = 254
		},
		{
			param2 = 0,
			name = "decoblocks:old_stone_tiles",
			prob = 254
		},
		{
			param2 = 0,
			name = "decoblocks:old_stone_tiles_with_dirt",
			prob = 254
		},
		{
			param2 = 0,
			name = "decoblocks:old_stone_tiles",
			prob = 254
		},
		{
			param2 = 0,
			name = "default:stone",
			prob = 254
		},
		{
			param2 = 0,
			name = "default:stonebrick",
			prob = 254
		},
		{
			param2 = 0,
			name = "air",
			prob = 254
		},
		{
			param2 = 0,
			name = "air",
			prob = 254
		},
		{
			param2 = 0,
			name = "air",
			prob = 254
		},
		{
			param2 = 0,
			name = "default:stonebrick",
			prob = 254
		},
		{
			param2 = 0,
			name = "default:cobble",
			prob = 254
		},
		{
			param2 = 0,
			name = "air",
			prob = 254
		},
		{
			param2 = 0,
			name = "air",
			prob = 254
		},
		{
			param2 = 0,
			name = "air",
			prob = 254
		},
		{
			param2 = 0,
			name = "default:cobble",
			prob = 254
		},
		{
			param2 = 0,
			name = "default:cobble",
			prob = 254
		},
		{
			param2 = 0,
			name = "air",
			prob = 254
		},
		{
			param2 = 0,
			name = "air",
			prob = 254
		},
		{
			param2 = 0,
			name = "air",
			prob = 254
		},
		{
			param2 = 0,
			name = "default:cobble",
			prob = 254
		},
		{
			param2 = 0,
			name = "default:stone",
			prob = 254
		},
		{
			param2 = 0,
			name = "default:cobble",
			prob = 254
		},
		{
			param2 = 0,
			name = "default:cobble",
			prob = 254
		},
		{
			param2 = 0,
			name = "default:cobble",
			prob = 254
		},
		{
			param2 = 0,
			name = "default:stone",
			prob = 254
		},
		{
			param2 = 0,
			name = "default:stone",
			prob = 254
		},
		{
			param2 = 0,
			name = "default:stone",
			prob = 254
		},
		{
			param2 = 0,
			name = "default:stone",
			prob = 254
		},
		{
			param2 = 0,
			name = "default:stone",
			prob = 254
		},
		{
			param2 = 0,
			name = "default:stone",
			prob = 254
		},
		{
			param2 = 0,
			name = "default:stone",
			prob = 254
		},
		{
			param2 = 0,
			name = "default:stonebrick",
			prob = 254
		},
		{
			param2 = 0,
			name = "default:stonebrick",
			prob = 254
		},
		{
			param2 = 0,
			name = "default:stonebrick",
			prob = 254
		},
		{
			param2 = 0,
			name = "default:stone",
			prob = 254
		},
		{
			param2 = 0,
			name = "default:stone",
			prob = 254
		},
		{
			param2 = 0,
			name = "default:cobble",
			prob = 254
		},
		{
			param2 = 0,
			name = "default:cobble",
			prob = 254
		},
		{
			param2 = 0,
			name = "default:cobble",
			prob = 254
		},
		{
			param2 = 0,
			name = "default:stone",
			prob = 254
		},
		{
			param2 = 0,
			name = "default:stone",
			prob = 254
		},
		{
			param2 = 0,
			name = "default:cobble",
			prob = 254
		},
		{
			param2 = 0,
			name = "default:cobble",
			prob = 254
		},
		{
			param2 = 0,
			name = "default:cobble",
			prob = 254
		},
		{
			param2 = 0,
			name = "default:stone",
			prob = 254
		},
		{
			param2 = 0,
			name = "default:stone",
			prob = 254
		},
		{
			param2 = 0,
			name = "default:stone",
			prob = 254
		},
		{
			param2 = 0,
			name = "default:stone",
			prob = 254
		},
		{
			param2 = 0,
			name = "default:stone",
			prob = 254
		},
		{
			param2 = 0,
			name = "default:stone",
			prob = 254
		}
	},
	size = {
		y = 5,
		x = 5,
		z = 5
	}
}