{
	yslice_prob = {
		{
			prob = 254,
			ypos = 0
		},
		{
			prob = 254,
			ypos = 1
		},
		{
			prob = 254,
			ypos = 2
		},
		{
			prob = 254,
			ypos = 3
		},
		{
			prob = 254,
			ypos = 4
		},
		{
			prob = 254,
			ypos = 5
		},
		{
			prob = 254,
			ypos = 6
		},
		{
			prob = 254,
			ypos = 7
		},
		{
			prob = 254,
			ypos = 8
		}
	},
	data = {
		{
			param2 = 0,
			name = "default:stone",
			prob = 254
		},
		{
			param2 = 0,
			name = "default:stone",
			prob = 254
		},
		{
			param2 = 0,
			name = "default:stone",
			prob = 254
		},
		{
			param2 = 0,
			name = "default:stone",
			prob = 254
		},
		{
			param2 = 0,
			name = "default:stone",
			prob = 254
		},
		{
			param2 = 0,
			name = "default:stone",
			prob = 254
		},
		{
			param2 = 0,
			name = "default:stone",
			prob = 254
		},
		{
			param2 = 0,
			name = "default:stone",
			prob = 254
		},
		{
			param2 = 0,
			name = "default:stone",
			prob = 254
		},
		{
			param2 = 0,
			name = "default:stone",
			prob = 254
		},
		{
			param2 = 0,
			name = "default:stone",
			prob = 254
		},
		{
			param2 = 0,
			name = "default:stone",
			prob = 254
		},
		{
			param2 = 0,
			name = "default:stone",
			prob = 254
		},
		{
			param2 = 0,
			name = "default:stone",
			prob = 254
		},
		{
			param2 = 0,
			name = "default:stone",
			prob = 254
		},
		{
			param2 = 0,
			name = "default:stone",
			prob = 254
		},
		{
			param2 = 0,
			name = "default:stone",
			prob = 254
		},
		{
			param2 = 0,
			name = "default:stone",
			prob = 254
		},
		{
			param2 = 0,
			name = "default:stone",
			prob = 254
		},
		{
			param2 = 0,
			name = "default:stone",
			prob = 254
		},
		{
			param2 = 0,
			name = "default:stone",
			prob = 254
		},
		{
			param2 = 0,
			name = "default:stone",
			prob = 254
		},
		{
			param2 = 0,
			name = "default:stone",
			prob = 254
		},
		{
			param2 = 0,
			name = "default:stone",
			prob = 254
		},
		{
			param2 = 0,
			name = "default:stone",
			prob = 254
		},
		{
			param2 = 0,
			name = "default:stone",
			prob = 254
		},
		{
			param2 = 0,
			name = "default:stone",
			prob = 254
		},
		{
			param2 = 0,
			name = "default:stone",
			prob = 254
		},
		{
			param2 = 0,
			name = "default:stone",
			prob = 254
		},
		{
			param2 = 0,
			name = "default:stone",
			prob = 254
		},
		{
			param2 = 0,
			name = "default:stone",
			prob = 254
		},
		{
			param2 = 0,
			name = "default:stone",
			prob = 254
		},
		{
			param2 = 0,
			name = "default:stone",
			prob = 254
		},
		{
			param2 = 0,
			name = "default:stone",
			prob = 254
		},
		{
			param2 = 0,
			name = "default:stone",
			prob = 254
		},
		{
			param2 = 0,
			name = "default:stone",
			prob = 254
		},
		{
			param2 = 0,
			name = "default:stone",
			prob = 254
		},
		{
			param2 = 0,
			name = "default:stone",
			prob = 254
		},
		{
			param2 = 0,
			name = "default:stone",
			prob = 254
		},
		{
			param2 = 0,
			name = "default:stone",
			prob = 254
		},
		{
			param2 = 0,
			name = "default:stone",
			prob = 254
		},
		{
			param2 = 0,
			name = "default:stone",
			prob = 254
		},
		{
			param2 = 0,
			name = "default:stone",
			prob = 254
		},
		{
			param2 = 0,
			name = "default:stone",
			prob = 254
		},
		{
			param2 = 0,
			name = "default:stone",
			prob = 254
		},
		{
			param2 = 0,
			name = "default:stone",
			prob = 254
		},
		{
			param2 = 0,
			name = "default:stone",
			prob = 254
		},
		{
			param2 = 0,
			name = "default:stone",
			prob = 254
		},
		{
			param2 = 0,
			name = "default:stone",
			prob = 254
		},
		{
			param2 = 0,
			name = "default:stone",
			prob = 254
		},
		{
			param2 = 0,
			name = "default:stone",
			prob = 254
		},
		{
			param2 = 0,
			name = "default:stone",
			prob = 254
		},
		{
			param2 = 0,
			name = "default:stone",
			prob = 254
		},
		{
			param2 = 0,
			name = "default:stone",
			prob = 254
		},
		{
			param2 = 0,
			name = "default:stone",
			prob = 254
		},
		{
			param2 = 0,
			name = "default:stone",
			prob = 254
		},
		{
			param2 = 0,
			name = "default:stone",
			prob = 254
		},
		{
			param2 = 0,
			name = "default:stone",
			prob = 254
		},
		{
			param2 = 0,
			name = "default:stone",
			prob = 254
		},
		{
			param2 = 0,
			name = "default:stone",
			prob = 254
		},
		{
			param2 = 0,
			name = "default:stone",
			prob = 254
		},
		{
			param2 = 0,
			name = "default:stone",
			prob = 254
		},
		{
			param2 = 0,
			name = "default:stone",
			prob = 254
		},
		{
			param2 = 0,
			name = "default:stone",
			prob = 254
		},
		{
			param2 = 0,
			name = "default:stone",
			prob = 254
		},
		{
			param2 = 0,
			name = "default:stone",
			prob = 254
		},
		{
			param2 = 0,
			name = "default:stone",
			prob = 254
		},
		{
			param2 = 0,
			name = "default:stone",
			prob = 254
		},
		{
			param2 = 0,
			name = "default:stone",
			prob = 254
		},
		{
			param2 = 0,
			name = "default:stone",
			prob = 254
		},
		{
			param2 = 0,
			name = "default:stone",
			prob = 254
		},
		{
			param2 = 0,
			name = "default:stone",
			prob = 254
		},
		{
			param2 = 0,
			name = "default:stone",
			prob = 254
		},
		{
			param2 = 0,
			name = "default:stone",
			prob = 254
		},
		{
			param2 = 0,
			name = "default:stone",
			prob = 254
		},
		{
			param2 = 0,
			name = "default:stone",
			prob = 254
		},
		{
			param2 = 0,
			name = "default:stone",
			prob = 254
		},
		{
			param2 = 0,
			name = "default:stone",
			prob = 254
		},
		{
			param2 = 0,
			name = "default:stone",
			prob = 254
		},
		{
			param2 = 0,
			name = "default:stone",
			prob = 254
		},
		{
			param2 = 0,
			name = "default:stone",
			prob = 254
		},
		{
			param2 = 0,
			name = "default:stone",
			prob = 254
		},
		{
			param2 = 0,
			name = "default:stone",
			prob = 254
		},
		{
			param2 = 0,
			name = "default:stone",
			prob = 254
		},
		{
			param2 = 0,
			name = "default:stone",
			prob = 254
		},
		{
			param2 = 0,
			name = "default:stone",
			prob = 254
		},
		{
			param2 = 0,
			name = "default:stone",
			prob = 254
		},
		{
			param2 = 0,
			name = "default:stone",
			prob = 254
		},
		{
			param2 = 0,
			name = "default:stone",
			prob = 254
		},
		{
			param2 = 0,
			name = "default:stone",
			prob = 254
		},
		{
			param2 = 0,
			name = "default:stone_with_coal",
			prob = 254
		},
		{
			param2 = 0,
			name = "default:stone",
			prob = 254
		},
		{
			param2 = 0,
			name = "default:stone",
			prob = 254
		},
		{
			param2 = 0,
			name = "default:stone",
			prob = 254
		},
		{
			param2 = 0,
			name = "default:stone",
			prob = 254
		},
		{
			param2 = 0,
			name = "default:stone",
			prob = 254
		},
		{
			param2 = 0,
			name = "default:stone",
			prob = 254
		},
		{
			param2 = 0,
			name = "default:stone",
			prob = 254
		},
		{
			param2 = 0,
			name = "default:stone",
			prob = 254
		},
		{
			param2 = 0,
			name = "default:stone",
			prob = 254
		},
		{
			param2 = 0,
			name = "default:stone",
			prob = 254
		},
		{
			param2 = 0,
			name = "default:stone",
			prob = 254
		},
		{
			param2 = 0,
			name = "default:stone",
			prob = 254
		},
		{
			param2 = 0,
			name = "default:stone",
			prob = 254
		},
		{
			param2 = 0,
			name = "default:stone",
			prob = 254
		},
		{
			param2 = 0,
			name = "default:stone",
			prob = 254
		},
		{
			param2 = 0,
			name = "default:stone",
			prob = 254
		},
		{
			param2 = 0,
			name = "default:stone",
			prob = 254
		},
		{
			param2 = 0,
			name = "default:stone",
			prob = 254
		},
		{
			param2 = 0,
			name = "default:stone_with_coal",
			prob = 254
		},
		{
			param2 = 0,
			name = "default:stone",
			prob = 254
		},
		{
			param2 = 0,
			name = "default:stone",
			prob = 254
		},
		{
			param2 = 0,
			name = "default:stone",
			prob = 254
		},
		{
			param2 = 0,
			name = "default:stone",
			prob = 254
		},
		{
			param2 = 0,
			name = "default:stone",
			prob = 254
		},
		{
			param2 = 0,
			name = "default:stone",
			prob = 254
		},
		{
			param2 = 0,
			name = "default:stone",
			prob = 254
		},
		{
			param2 = 0,
			name = "default:stone",
			prob = 254
		},
		{
			param2 = 0,
			name = "default:stone",
			prob = 254
		},
		{
			param2 = 0,
			name = "default:stone",
			prob = 254
		},
		{
			param2 = 0,
			name = "default:stone",
			prob = 254
		},
		{
			param2 = 0,
			name = "default:stone",
			prob = 254
		},
		{
			param2 = 0,
			name = "default:stone",
			prob = 254
		},
		{
			param2 = 0,
			name = "default:stone",
			prob = 254
		},
		{
			param2 = 0,
			name = "default:stone",
			prob = 254
		},
		{
			param2 = 0,
			name = "default:stone",
			prob = 254
		},
		{
			param2 = 0,
			name = "default:stone",
			prob = 254
		},
		{
			param2 = 0,
			name = "default:stone",
			prob = 254
		},
		{
			param2 = 0,
			name = "default:stone",
			prob = 254
		},
		{
			param2 = 0,
			name = "default:stone",
			prob = 254
		},
		{
			param2 = 0,
			name = "default:stone",
			prob = 254
		},
		{
			param2 = 0,
			name = "default:stone",
			prob = 254
		},
		{
			param2 = 0,
			name = "default:stone",
			prob = 254
		},
		{
			param2 = 0,
			name = "default:stone",
			prob = 254
		},
		{
			param2 = 0,
			name = "default:stone",
			prob = 254
		},
		{
			param2 = 0,
			name = "default:stone",
			prob = 254
		},
		{
			param2 = 0,
			name = "default:stone",
			prob = 254
		},
		{
			param2 = 0,
			name = "default:stone",
			prob = 254
		},
		{
			param2 = 0,
			name = "default:stone",
			prob = 254
		},
		{
			param2 = 0,
			name = "default:stone",
			prob = 254
		},
		{
			param2 = 0,
			name = "default:stone",
			prob = 254
		},
		{
			param2 = 0,
			name = "default:stone",
			prob = 254
		},
		{
			param2 = 0,
			name = "default:stone",
			prob = 254
		},
		{
			param2 = 0,
			name = "default:stone",
			prob = 254
		},
		{
			param2 = 0,
			name = "default:stone",
			prob = 254
		},
		{
			param2 = 0,
			name = "default:stone",
			prob = 254
		},
		{
			param2 = 0,
			name = "default:stone",
			prob = 254
		},
		{
			param2 = 0,
			name = "default:stone",
			prob = 254
		},
		{
			param2 = 0,
			name = "default:stone",
			prob = 254
		},
		{
			param2 = 0,
			name = "default:stone",
			prob = 254
		},
		{
			param2 = 0,
			name = "default:stone",
			prob = 254
		},
		{
			param2 = 0,
			name = "default:stone",
			prob = 254
		},
		{
			param2 = 0,
			name = "default:stone",
			prob = 254
		},
		{
			param2 = 0,
			name = "default:stone",
			prob = 254
		},
		{
			param2 = 0,
			name = "default:stone",
			prob = 254
		},
		{
			param2 = 0,
			name = "default:stone",
			prob = 254
		},
		{
			param2 = 0,
			name = "default:stone",
			prob = 254
		},
		{
			param2 = 0,
			name = "default:stone",
			prob = 254
		},
		{
			param2 = 0,
			name = "default:stone",
			prob = 254
		},
		{
			param2 = 0,
			name = "default:stone",
			prob = 254
		},
		{
			param2 = 0,
			name = "default:stone",
			prob = 254
		},
		{
			param2 = 0,
			name = "default:stone",
			prob = 254
		},
		{
			param2 = 0,
			name = "default:stone",
			prob = 254
		},
		{
			param2 = 0,
			name = "default:stone",
			prob = 254
		},
		{
			param2 = 0,
			name = "default:stone",
			prob = 254
		},
		{
			param2 = 0,
			name = "default:stone",
			prob = 254
		},
		{
			param2 = 0,
			name = "default:stone",
			prob = 254
		},
		{
			param2 = 0,
			name = "default:stone",
			prob = 254
		},
		{
			param2 = 0,
			name = "default:stone",
			prob = 254
		},
		{
			param2 = 0,
			name = "default:stone",
			prob = 254
		},
		{
			param2 = 0,
			name = "default:stone",
			prob = 254
		},
		{
			param2 = 0,
			name = "default:stone",
			prob = 254
		},
		{
			param2 = 0,
			name = "default:stone",
			prob = 254
		},
		{
			param2 = 0,
			name = "default:stone",
			prob = 254
		},
		{
			param2 = 0,
			name = "default:stone",
			prob = 254
		},
		{
			param2 = 0,
			name = "default:stone",
			prob = 254
		},
		{
			param2 = 0,
			name = "default:stone",
			prob = 254
		},
		{
			param2 = 0,
			name = "default:stone",
			prob = 254
		},
		{
			param2 = 0,
			name = "default:stone",
			prob = 254
		},
		{
			param2 = 0,
			name = "default:stone",
			prob = 254
		},
		{
			param2 = 0,
			name = "default:stone",
			prob = 254
		},
		{
			param2 = 0,
			name = "default:stone",
			prob = 254
		},
		{
			param2 = 0,
			name = "default:stone",
			prob = 254
		},
		{
			param2 = 0,
			name = "default:stone",
			prob = 254
		},
		{
			param2 = 0,
			name = "default:stone",
			prob = 254
		},
		{
			param2 = 0,
			name = "default:stone",
			prob = 254
		},
		{
			param2 = 0,
			name = "default:stone",
			prob = 254
		},
		{
			param2 = 0,
			name = "default:stone",
			prob = 254
		},
		{
			param2 = 0,
			name = "default:stone",
			prob = 254
		},
		{
			param2 = 0,
			name = "default:stone",
			prob = 254
		},
		{
			param2 = 0,
			name = "default:stone",
			prob = 254
		},
		{
			param2 = 0,
			name = "default:stone",
			prob = 254
		},
		{
			param2 = 0,
			name = "default:stone",
			prob = 254
		},
		{
			param2 = 0,
			name = "default:stone",
			prob = 254
		},
		{
			param2 = 0,
			name = "default:stone",
			prob = 254
		},
		{
			param2 = 0,
			name = "default:stone",
			prob = 254
		},
		{
			param2 = 0,
			name = "default:stone",
			prob = 254
		},
		{
			param2 = 0,
			name = "default:stone",
			prob = 254
		},
		{
			param2 = 0,
			name = "default:stone",
			prob = 254
		},
		{
			param2 = 0,
			name = "default:stone",
			prob = 254
		},
		{
			param2 = 0,
			name = "default:stone",
			prob = 254
		},
		{
			param2 = 0,
			name = "default:stone",
			prob = 254
		},
		{
			param2 = 0,
			name = "default:stone",
			prob = 254
		},
		{
			param2 = 0,
			name = "default:stone",
			prob = 254
		},
		{
			param2 = 0,
			name = "default:stone",
			prob = 254
		},
		{
			param2 = 0,
			name = "default:stone",
			prob = 254
		},
		{
			param2 = 0,
			name = "default:stone",
			prob = 254
		},
		{
			param2 = 0,
			name = "default:stone",
			prob = 254
		},
		{
			param2 = 0,
			name = "default:stone",
			prob = 254
		},
		{
			param2 = 0,
			name = "default:stone",
			prob = 254
		},
		{
			param2 = 0,
			name = "default:stone",
			prob = 254
		},
		{
			param2 = 0,
			name = "default:stone",
			prob = 254
		},
		{
			param2 = 0,
			name = "default:stone",
			prob = 254
		},
		{
			param2 = 0,
			name = "default:stone",
			prob = 254
		},
		{
			param2 = 0,
			name = "default:stone",
			prob = 254
		},
		{
			param2 = 0,
			name = "default:stone",
			prob = 254
		},
		{
			param2 = 0,
			name = "default:stone",
			prob = 254
		},
		{
			param2 = 0,
			name = "default:stone",
			prob = 254
		},
		{
			param2 = 0,
			name = "default:stone",
			prob = 254
		},
		{
			param2 = 0,
			name = "default:stone",
			prob = 254
		},
		{
			param2 = 0,
			name = "default:stone",
			prob = 254
		},
		{
			param2 = 0,
			name = "default:stone",
			prob = 254
		},
		{
			param2 = 0,
			name = "default:stone",
			prob = 254
		},
		{
			param2 = 0,
			name = "default:stone",
			prob = 254
		},
		{
			param2 = 0,
			name = "default:stone",
			prob = 254
		},
		{
			param2 = 0,
			name = "default:stone",
			prob = 254
		},
		{
			param2 = 0,
			name = "default:stone",
			prob = 254
		},
		{
			param2 = 0,
			name = "default:stone",
			prob = 254
		},
		{
			param2 = 0,
			name = "default:stone",
			prob = 254
		},
		{
			param2 = 0,
			name = "default:stone",
			prob = 254
		},
		{
			param2 = 0,
			name = "default:stone",
			prob = 254
		},
		{
			param2 = 0,
			name = "default:stone",
			prob = 254
		},
		{
			param2 = 0,
			name = "default:stone",
			prob = 254
		},
		{
			param2 = 0,
			name = "default:stone",
			prob = 254
		},
		{
			param2 = 0,
			name = "default:stone",
			prob = 254
		},
		{
			param2 = 0,
			name = "default:stone",
			prob = 254
		},
		{
			param2 = 0,
			name = "default:stone",
			prob = 254
		},
		{
			param2 = 0,
			name = "default:stone",
			prob = 254
		},
		{
			param2 = 0,
			name = "default:stone",
			prob = 254
		},
		{
			param2 = 0,
			name = "default:stone",
			prob = 254
		},
		{
			param2 = 0,
			name = "default:stone",
			prob = 254
		},
		{
			param2 = 0,
			name = "default:stone",
			prob = 254
		},
		{
			param2 = 0,
			name = "default:stone",
			prob = 254
		},
		{
			param2 = 0,
			name = "default:stone",
			prob = 254
		},
		{
			param2 = 0,
			name = "default:stone",
			prob = 254
		},
		{
			param2 = 0,
			name = "default:stone",
			prob = 254
		},
		{
			param2 = 0,
			name = "default:stone",
			prob = 254
		},
		{
			param2 = 0,
			name = "default:stone",
			prob = 254
		},
		{
			param2 = 0,
			name = "default:stone",
			prob = 254
		},
		{
			param2 = 0,
			name = "default:stone",
			prob = 254
		},
		{
			param2 = 0,
			name = "default:stone",
			prob = 254
		},
		{
			param2 = 0,
			name = "default:stone",
			prob = 254
		},
		{
			param2 = 0,
			name = "default:stone_with_iron",
			prob = 254
		},
		{
			param2 = 0,
			name = "default:stone_with_iron",
			prob = 254
		},
		{
			param2 = 0,
			name = "default:stone",
			prob = 254
		},
		{
			param2 = 0,
			name = "default:stone",
			prob = 254
		},
		{
			param2 = 0,
			name = "default:stone",
			prob = 254
		},
		{
			param2 = 0,
			name = "default:stone",
			prob = 254
		},
		{
			param2 = 0,
			name = "default:stone",
			prob = 254
		},
		{
			param2 = 0,
			name = "default:stone",
			prob = 254
		},
		{
			param2 = 0,
			name = "default:stone",
			prob = 254
		},
		{
			param2 = 3,
			name = "default:tree",
			prob = 254
		},
		{
			param2 = 3,
			name = "decoblocks:old_skeleton",
			prob = 254
		},
		{
			param2 = 0,
			name = "air",
			prob = 254
		},
		{
			param2 = 0,
			name = "air",
			prob = 254
		},
		{
			param2 = 2,
			name = "default:tree",
			prob = 254
		},
		{
			param2 = 0,
			name = "air",
			prob = 254
		},
		{
			param2 = 0,
			name = "air",
			prob = 254
		},
		{
			param2 = 0,
			name = "air",
			prob = 254
		},
		{
			param2 = 0,
			name = "air",
			prob = 254
		},
		{
			param2 = 0,
			name = "air",
			prob = 254
		},
		{
			param2 = 0,
			name = "air",
			prob = 254
		},
		{
			param2 = 0,
			name = "air",
			prob = 254
		},
		{
			param2 = 0,
			name = "air",
			prob = 254
		},
		{
			param2 = 2,
			name = "default:tree",
			prob = 254
		},
		{
			param2 = 2,
			name = "default:furnace",
			prob = 254
		},
		{
			param2 = 2,
			name = "default:furnace",
			prob = 254
		},
		{
			param2 = 2,
			name = "default:furnace",
			prob = 254
		},
		{
			param2 = 2,
			name = "default:tree",
			prob = 254
		},
		{
			param2 = 0,
			name = "default:stone",
			prob = 254
		},
		{
			param2 = 0,
			name = "default:stone",
			prob = 254
		},
		{
			param2 = 3,
			name = "default:tree",
			prob = 254
		},
		{
			param2 = 0,
			name = "air",
			prob = 254
		},
		{
			param2 = 0,
			name = "air",
			prob = 254
		},
		{
			param2 = 0,
			name = "air",
			prob = 254
		},
		{
			param2 = 2,
			name = "default:tree",
			prob = 254
		},
		{
			param2 = 0,
			name = "air",
			prob = 254
		},
		{
			param2 = 0,
			name = "air",
			prob = 254
		},
		{
			param2 = 0,
			name = "air",
			prob = 254
		},
		{
			param2 = 0,
			name = "air",
			prob = 254
		},
		{
			param2 = 0,
			name = "air",
			prob = 254
		},
		{
			param2 = 0,
			name = "air",
			prob = 254
		},
		{
			param2 = 0,
			name = "air",
			prob = 254
		},
		{
			param2 = 0,
			name = "air",
			prob = 254
		},
		{
			param2 = 2,
			name = "default:tree",
			prob = 254
		},
		{
			param2 = 0,
			name = "air",
			prob = 254
		},
		{
			param2 = 0,
			name = "air",
			prob = 254
		},
		{
			param2 = 0,
			name = "air",
			prob = 254
		},
		{
			param2 = 2,
			name = "default:tree",
			prob = 254
		},
		{
			param2 = 0,
			name = "default:stone",
			prob = 254
		},
		{
			param2 = 0,
			name = "default:stone",
			prob = 254
		},
		{
			param2 = 3,
			name = "default:tree",
			prob = 254
		},
		{
			param2 = 0,
			name = "air",
			prob = 254
		},
		{
			param2 = 0,
			name = "air",
			prob = 254
		},
		{
			param2 = 0,
			name = "air",
			prob = 254
		},
		{
			param2 = 2,
			name = "default:tree",
			prob = 254
		},
		{
			param2 = 0,
			name = "air",
			prob = 254
		},
		{
			param2 = 0,
			name = "air",
			prob = 254
		},
		{
			param2 = 0,
			name = "air",
			prob = 254
		},
		{
			param2 = 0,
			name = "air",
			prob = 254
		},
		{
			param2 = 0,
			name = "air",
			prob = 254
		},
		{
			param2 = 0,
			name = "air",
			prob = 254
		},
		{
			param2 = 5,
			name = "default:torch_wall",
			prob = 254
		},
		{
			param2 = 0,
			name = "air",
			prob = 254
		},
		{
			param2 = 2,
			name = "default:tree",
			prob = 254
		},
		{
			param2 = 0,
			name = "air",
			prob = 254
		},
		{
			param2 = 0,
			name = "air",
			prob = 254
		},
		{
			param2 = 0,
			name = "air",
			prob = 254
		},
		{
			param2 = 2,
			name = "default:tree",
			prob = 254
		},
		{
			param2 = 0,
			name = "default:stone",
			prob = 254
		},
		{
			param2 = 0,
			name = "default:stone",
			prob = 254
		},
		{
			param2 = 3,
			name = "default:tree",
			prob = 254
		},
		{
			param2 = 12,
			name = "default:tree",
			prob = 254
		},
		{
			param2 = 12,
			name = "default:tree",
			prob = 254
		},
		{
			param2 = 12,
			name = "default:tree",
			prob = 254
		},
		{
			param2 = 2,
			name = "default:tree",
			prob = 254
		},
		{
			param2 = 12,
			name = "default:tree",
			prob = 254
		},
		{
			param2 = 12,
			name = "default:tree",
			prob = 254
		},
		{
			param2 = 12,
			name = "default:tree",
			prob = 254
		},
		{
			param2 = 12,
			name = "default:tree",
			prob = 254
		},
		{
			param2 = 12,
			name = "default:tree",
			prob = 254
		},
		{
			param2 = 12,
			name = "default:tree",
			prob = 254
		},
		{
			param2 = 12,
			name = "default:tree",
			prob = 254
		},
		{
			param2 = 12,
			name = "default:tree",
			prob = 254
		},
		{
			param2 = 2,
			name = "default:tree",
			prob = 254
		},
		{
			param2 = 18,
			name = "default:tree",
			prob = 254
		},
		{
			param2 = 18,
			name = "default:tree",
			prob = 254
		},
		{
			param2 = 18,
			name = "default:tree",
			prob = 254
		},
		{
			param2 = 2,
			name = "default:tree",
			prob = 254
		},
		{
			param2 = 0,
			name = "default:stone",
			prob = 254
		},
		{
			param2 = 0,
			name = "default:stone",
			prob = 254
		},
		{
			param2 = 0,
			name = "default:stone",
			prob = 254
		},
		{
			param2 = 0,
			name = "default:stone",
			prob = 254
		},
		{
			param2 = 0,
			name = "default:stone",
			prob = 254
		},
		{
			param2 = 0,
			name = "default:stone",
			prob = 254
		},
		{
			param2 = 0,
			name = "default:stone",
			prob = 254
		},
		{
			param2 = 0,
			name = "default:stone",
			prob = 254
		},
		{
			param2 = 0,
			name = "default:stone",
			prob = 254
		},
		{
			param2 = 0,
			name = "default:stone",
			prob = 254
		},
		{
			param2 = 0,
			name = "default:stone",
			prob = 254
		},
		{
			param2 = 0,
			name = "default:stone",
			prob = 254
		},
		{
			param2 = 0,
			name = "default:stone",
			prob = 254
		},
		{
			param2 = 0,
			name = "default:stone",
			prob = 254
		},
		{
			param2 = 0,
			name = "default:stone",
			prob = 254
		},
		{
			param2 = 0,
			name = "default:stone",
			prob = 254
		},
		{
			param2 = 0,
			name = "default:stone",
			prob = 254
		},
		{
			param2 = 0,
			name = "default:stone",
			prob = 254
		},
		{
			param2 = 0,
			name = "default:stone",
			prob = 254
		},
		{
			param2 = 0,
			name = "default:stone",
			prob = 254
		},
		{
			param2 = 0,
			name = "default:stone",
			prob = 254
		},
		{
			param2 = 0,
			name = "default:stone",
			prob = 254
		},
		{
			param2 = 0,
			name = "default:stone",
			prob = 254
		},
		{
			param2 = 0,
			name = "default:stone",
			prob = 254
		},
		{
			param2 = 0,
			name = "default:stone",
			prob = 254
		},
		{
			param2 = 0,
			name = "default:stone",
			prob = 254
		},
		{
			param2 = 0,
			name = "default:stone",
			prob = 254
		},
		{
			param2 = 0,
			name = "default:stone",
			prob = 254
		},
		{
			param2 = 0,
			name = "default:stone",
			prob = 254
		},
		{
			param2 = 0,
			name = "default:stone",
			prob = 254
		},
		{
			param2 = 0,
			name = "default:stone",
			prob = 254
		},
		{
			param2 = 0,
			name = "default:stone",
			prob = 254
		},
		{
			param2 = 0,
			name = "default:stone",
			prob = 254
		},
		{
			param2 = 0,
			name = "default:stone",
			prob = 254
		},
		{
			param2 = 0,
			name = "default:stone",
			prob = 254
		},
		{
			param2 = 0,
			name = "default:stone",
			prob = 254
		},
		{
			param2 = 0,
			name = "default:stone",
			prob = 254
		},
		{
			param2 = 0,
			name = "default:stone",
			prob = 254
		},
		{
			param2 = 0,
			name = "default:stone",
			prob = 254
		},
		{
			param2 = 0,
			name = "default:stone",
			prob = 254
		},
		{
			param2 = 0,
			name = "default:stone",
			prob = 254
		},
		{
			param2 = 0,
			name = "default:stone",
			prob = 254
		},
		{
			param2 = 0,
			name = "default:stone",
			prob = 254
		},
		{
			param2 = 0,
			name = "default:stone",
			prob = 254
		},
		{
			param2 = 0,
			name = "default:stone",
			prob = 254
		},
		{
			param2 = 0,
			name = "default:stone",
			prob = 254
		},
		{
			param2 = 0,
			name = "default:stone",
			prob = 254
		},
		{
			param2 = 0,
			name = "default:stone",
			prob = 254
		},
		{
			param2 = 0,
			name = "default:stone",
			prob = 254
		},
		{
			param2 = 0,
			name = "default:stone",
			prob = 254
		},
		{
			param2 = 0,
			name = "default:stone",
			prob = 254
		},
		{
			param2 = 0,
			name = "default:stone",
			prob = 254
		},
		{
			param2 = 0,
			name = "default:stone",
			prob = 254
		},
		{
			param2 = 0,
			name = "default:stone",
			prob = 254
		},
		{
			param2 = 0,
			name = "default:stone",
			prob = 254
		},
		{
			param2 = 0,
			name = "default:stone",
			prob = 254
		},
		{
			param2 = 0,
			name = "default:stone",
			prob = 254
		},
		{
			param2 = 0,
			name = "default:stone",
			prob = 254
		},
		{
			param2 = 0,
			name = "default:stone",
			prob = 254
		},
		{
			param2 = 0,
			name = "default:stone",
			prob = 254
		},
		{
			param2 = 0,
			name = "default:stone",
			prob = 254
		},
		{
			param2 = 0,
			name = "default:stone",
			prob = 254
		},
		{
			param2 = 0,
			name = "default:stone",
			prob = 254
		},
		{
			param2 = 0,
			name = "default:stone",
			prob = 254
		},
		{
			param2 = 0,
			name = "default:stone",
			prob = 254
		},
		{
			param2 = 0,
			name = "default:stone",
			prob = 254
		},
		{
			param2 = 0,
			name = "default:stone",
			prob = 254
		},
		{
			param2 = 0,
			name = "default:stone",
			prob = 254
		},
		{
			param2 = 0,
			name = "default:stone",
			prob = 254
		},
		{
			param2 = 0,
			name = "default:stone",
			prob = 254
		},
		{
			param2 = 0,
			name = "default:stone",
			prob = 254
		},
		{
			param2 = 0,
			name = "default:stone",
			prob = 254
		},
		{
			param2 = 0,
			name = "default:stone",
			prob = 254
		},
		{
			param2 = 0,
			name = "default:stone",
			prob = 254
		},
		{
			param2 = 0,
			name = "default:stone",
			prob = 254
		},
		{
			param2 = 0,
			name = "default:stone",
			prob = 254
		},
		{
			param2 = 0,
			name = "default:stone",
			prob = 254
		},
		{
			param2 = 0,
			name = "default:stone",
			prob = 254
		},
		{
			param2 = 0,
			name = "default:stone",
			prob = 254
		},
		{
			param2 = 0,
			name = "default:stone",
			prob = 254
		},
		{
			param2 = 0,
			name = "default:stone",
			prob = 254
		},
		{
			param2 = 0,
			name = "default:stone",
			prob = 254
		},
		{
			param2 = 0,
			name = "default:stone",
			prob = 254
		},
		{
			param2 = 0,
			name = "carts:rail",
			prob = 254
		},
		{
			param2 = 0,
			name = "carts:rail",
			prob = 254
		},
		{
			param2 = 0,
			name = "default:stone",
			prob = 254
		},
		{
			param2 = 0,
			name = "default:stone",
			prob = 254
		},
		{
			param2 = 0,
			name = "default:stone",
			prob = 254
		},
		{
			param2 = 0,
			name = "default:stone",
			prob = 254
		},
		{
			param2 = 0,
			name = "default:stone",
			prob = 254
		},
		{
			param2 = 0,
			name = "default:stone",
			prob = 254
		},
		{
			param2 = 0,
			name = "default:stone",
			prob = 254
		},
		{
			param2 = 0,
			name = "default:stone",
			prob = 254
		},
		{
			param2 = 0,
			name = "default:stone",
			prob = 254
		},
		{
			param2 = 0,
			name = "default:stone",
			prob = 254
		},
		{
			param2 = 0,
			name = "default:stone",
			prob = 254
		},
		{
			param2 = 0,
			name = "default:stone",
			prob = 254
		},
		{
			param2 = 0,
			name = "default:stone",
			prob = 254
		},
		{
			param2 = 0,
			name = "default:stone",
			prob = 254
		},
		{
			param2 = 0,
			name = "default:stone",
			prob = 254
		},
		{
			param2 = 0,
			name = "default:stone",
			prob = 254
		},
		{
			param2 = 0,
			name = "default:stone",
			prob = 254
		},
		{
			param2 = 0,
			name = "air",
			prob = 254
		},
		{
			param2 = 0,
			name = "air",
			prob = 254
		},
		{
			param2 = 0,
			name = "air",
			prob = 254
		},
		{
			param2 = 0,
			name = "carts:rail",
			prob = 254
		},
		{
			param2 = 0,
			name = "carts:rail",
			prob = 254
		},
		{
			param2 = 0,
			name = "carts:rail",
			prob = 254
		},
		{
			param2 = 0,
			name = "carts:rail",
			prob = 254
		},
		{
			param2 = 0,
			name = "carts:rail",
			prob = 254
		},
		{
			param2 = 0,
			name = "carts:rail",
			prob = 254
		},
		{
			param2 = 0,
			name = "carts:rail",
			prob = 254
		},
		{
			param2 = 0,
			name = "carts:rail",
			prob = 254
		},
		{
			param2 = 0,
			name = "carts:rail",
			prob = 254
		},
		{
			param2 = 0,
			name = "carts:rail",
			prob = 254
		},
		{
			param2 = 0,
			name = "carts:rail",
			prob = 254
		},
		{
			param2 = 0,
			name = "carts:rail",
			prob = 254
		},
		{
			param2 = 0,
			name = "carts:rail",
			prob = 254
		},
		{
			param2 = 0,
			name = "carts:rail",
			prob = 254
		},
		{
			param2 = 1,
			name = "default:furnace",
			prob = 254
		},
		{
			param2 = 0,
			name = "default:stone",
			prob = 254
		},
		{
			param2 = 0,
			name = "default:stone",
			prob = 254
		},
		{
			param2 = 0,
			name = "air",
			prob = 254
		},
		{
			param2 = 0,
			name = "air",
			prob = 254
		},
		{
			param2 = 0,
			name = "air",
			prob = 254
		},
		{
			param2 = 0,
			name = "air",
			prob = 254
		},
		{
			param2 = 0,
			name = "air",
			prob = 254
		},
		{
			param2 = 0,
			name = "air",
			prob = 254
		},
		{
			param2 = 0,
			name = "air",
			prob = 254
		},
		{
			param2 = 0,
			name = "air",
			prob = 254
		},
		{
			param2 = 0,
			name = "air",
			prob = 254
		},
		{
			param2 = 0,
			name = "air",
			prob = 254
		},
		{
			param2 = 0,
			name = "air",
			prob = 254
		},
		{
			param2 = 0,
			name = "air",
			prob = 254
		},
		{
			param2 = 0,
			name = "air",
			prob = 254
		},
		{
			param2 = 0,
			name = "air",
			prob = 254
		},
		{
			param2 = 0,
			name = "air",
			prob = 254
		},
		{
			param2 = 0,
			name = "air",
			prob = 254
		},
		{
			param2 = 0,
			name = "air",
			prob = 254
		},
		{
			param2 = 0,
			name = "air",
			prob = 254
		},
		{
			param2 = 0,
			name = "default:stone",
			prob = 254
		},
		{
			param2 = 0,
			name = "default:stone",
			prob = 254
		},
		{
			param2 = 0,
			name = "air",
			prob = 254
		},
		{
			param2 = 0,
			name = "air",
			prob = 254
		},
		{
			param2 = 0,
			name = "air",
			prob = 254
		},
		{
			param2 = 0,
			name = "air",
			prob = 254
		},
		{
			param2 = 0,
			name = "air",
			prob = 254
		},
		{
			param2 = 0,
			name = "air",
			prob = 254
		},
		{
			param2 = 0,
			name = "air",
			prob = 254
		},
		{
			param2 = 0,
			name = "air",
			prob = 254
		},
		{
			param2 = 0,
			name = "air",
			prob = 254
		},
		{
			param2 = 0,
			name = "air",
			prob = 254
		},
		{
			param2 = 0,
			name = "air",
			prob = 254
		},
		{
			param2 = 0,
			name = "air",
			prob = 254
		},
		{
			param2 = 0,
			name = "air",
			prob = 254
		},
		{
			param2 = 0,
			name = "air",
			prob = 254
		},
		{
			param2 = 0,
			name = "air",
			prob = 254
		},
		{
			param2 = 0,
			name = "air",
			prob = 254
		},
		{
			param2 = 0,
			name = "air",
			prob = 254
		},
		{
			param2 = 0,
			name = "air",
			prob = 254
		},
		{
			param2 = 0,
			name = "default:stone",
			prob = 254
		},
		{
			param2 = 0,
			name = "default:stone",
			prob = 254
		},
		{
			param2 = 7,
			name = "default:tree",
			prob = 254
		},
		{
			param2 = 0,
			name = "mapgen:stalagtite1",
			prob = 254
		},
		{
			param2 = 0,
			name = "air",
			prob = 254
		},
		{
			param2 = 0,
			name = "air",
			prob = 254
		},
		{
			param2 = 7,
			name = "default:tree",
			prob = 254
		},
		{
			param2 = 0,
			name = "air",
			prob = 254
		},
		{
			param2 = 0,
			name = "air",
			prob = 254
		},
		{
			param2 = 0,
			name = "air",
			prob = 254
		},
		{
			param2 = 0,
			name = "mapgen:stalagtite",
			prob = 254
		},
		{
			param2 = 0,
			name = "air",
			prob = 254
		},
		{
			param2 = 0,
			name = "air",
			prob = 254
		},
		{
			param2 = 0,
			name = "air",
			prob = 254
		},
		{
			param2 = 0,
			name = "mapgen:stalagtite2",
			prob = 254
		},
		{
			param2 = 7,
			name = "default:tree",
			prob = 254
		},
		{
			param2 = 0,
			name = "air",
			prob = 254
		},
		{
			param2 = 0,
			name = "mapgen:stalagtite1",
			prob = 254
		},
		{
			param2 = 0,
			name = "air",
			prob = 254
		},
		{
			param2 = 7,
			name = "default:tree",
			prob = 254
		},
		{
			param2 = 0,
			name = "default:stone",
			prob = 254
		},
		{
			param2 = 0,
			name = "default:stone",
			prob = 254
		},
		{
			param2 = 0,
			name = "default:stone",
			prob = 254
		},
		{
			param2 = 0,
			name = "default:stone",
			prob = 254
		},
		{
			param2 = 0,
			name = "default:stone",
			prob = 254
		},
		{
			param2 = 0,
			name = "default:stone",
			prob = 254
		},
		{
			param2 = 0,
			name = "default:stone",
			prob = 254
		},
		{
			param2 = 0,
			name = "default:stone",
			prob = 254
		},
		{
			param2 = 0,
			name = "default:stone",
			prob = 254
		},
		{
			param2 = 0,
			name = "default:stone",
			prob = 254
		},
		{
			param2 = 0,
			name = "default:stone",
			prob = 254
		},
		{
			param2 = 0,
			name = "default:stone",
			prob = 254
		},
		{
			param2 = 0,
			name = "default:stone",
			prob = 254
		},
		{
			param2 = 0,
			name = "default:stone",
			prob = 254
		},
		{
			param2 = 0,
			name = "default:stone",
			prob = 254
		},
		{
			param2 = 0,
			name = "default:stone",
			prob = 254
		},
		{
			param2 = 0,
			name = "default:stone",
			prob = 254
		},
		{
			param2 = 0,
			name = "default:stone",
			prob = 254
		},
		{
			param2 = 0,
			name = "default:stone",
			prob = 254
		},
		{
			param2 = 0,
			name = "default:stone",
			prob = 254
		},
		{
			param2 = 0,
			name = "default:stone",
			prob = 254
		},
		{
			param2 = 0,
			name = "default:stone",
			prob = 254
		},
		{
			param2 = 0,
			name = "default:stone",
			prob = 254
		},
		{
			param2 = 0,
			name = "default:stone",
			prob = 254
		},
		{
			param2 = 0,
			name = "default:stone",
			prob = 254
		},
		{
			param2 = 0,
			name = "default:stone",
			prob = 254
		},
		{
			param2 = 0,
			name = "default:stone",
			prob = 254
		},
		{
			param2 = 0,
			name = "default:stone",
			prob = 254
		},
		{
			param2 = 0,
			name = "default:stone",
			prob = 254
		},
		{
			param2 = 0,
			name = "default:stone",
			prob = 254
		},
		{
			param2 = 0,
			name = "default:stone",
			prob = 254
		},
		{
			param2 = 0,
			name = "default:stone",
			prob = 254
		},
		{
			param2 = 0,
			name = "default:stone",
			prob = 254
		},
		{
			param2 = 0,
			name = "default:stone",
			prob = 254
		},
		{
			param2 = 0,
			name = "default:stone",
			prob = 254
		},
		{
			param2 = 0,
			name = "default:stone",
			prob = 254
		},
		{
			param2 = 0,
			name = "default:stone",
			prob = 254
		},
		{
			param2 = 0,
			name = "default:stone",
			prob = 254
		},
		{
			param2 = 0,
			name = "default:stone",
			prob = 254
		},
		{
			param2 = 0,
			name = "default:stone",
			prob = 254
		},
		{
			param2 = 0,
			name = "default:stone",
			prob = 254
		},
		{
			param2 = 0,
			name = "default:stone",
			prob = 254
		},
		{
			param2 = 0,
			name = "default:stone",
			prob = 254
		},
		{
			param2 = 0,
			name = "default:stone",
			prob = 254
		},
		{
			param2 = 0,
			name = "default:stone",
			prob = 254
		},
		{
			param2 = 0,
			name = "default:stone",
			prob = 254
		},
		{
			param2 = 0,
			name = "default:stone",
			prob = 254
		},
		{
			param2 = 0,
			name = "default:stone",
			prob = 254
		},
		{
			param2 = 0,
			name = "default:stone",
			prob = 254
		},
		{
			param2 = 0,
			name = "default:stone",
			prob = 254
		},
		{
			param2 = 0,
			name = "default:stone",
			prob = 254
		},
		{
			param2 = 0,
			name = "default:stone",
			prob = 254
		},
		{
			param2 = 0,
			name = "default:stone",
			prob = 254
		},
		{
			param2 = 0,
			name = "default:stone",
			prob = 254
		},
		{
			param2 = 0,
			name = "default:stone",
			prob = 254
		},
		{
			param2 = 0,
			name = "default:stone",
			prob = 254
		},
		{
			param2 = 0,
			name = "default:stone",
			prob = 254
		},
		{
			param2 = 0,
			name = "default:stone",
			prob = 254
		},
		{
			param2 = 0,
			name = "default:stone",
			prob = 254
		},
		{
			param2 = 0,
			name = "default:stone",
			prob = 254
		},
		{
			param2 = 0,
			name = "default:stone",
			prob = 254
		},
		{
			param2 = 0,
			name = "default:stone",
			prob = 254
		},
		{
			param2 = 0,
			name = "default:stone",
			prob = 254
		},
		{
			param2 = 0,
			name = "carts:rail",
			prob = 254
		},
		{
			param2 = 0,
			name = "default:stone",
			prob = 254
		},
		{
			param2 = 0,
			name = "default:stone",
			prob = 254
		},
		{
			param2 = 0,
			name = "default:stone",
			prob = 254
		},
		{
			param2 = 0,
			name = "default:stone",
			prob = 254
		},
		{
			param2 = 0,
			name = "default:stone",
			prob = 254
		},
		{
			param2 = 0,
			name = "default:stone",
			prob = 254
		},
		{
			param2 = 0,
			name = "default:stone",
			prob = 254
		},
		{
			param2 = 0,
			name = "default:stone",
			prob = 254
		},
		{
			param2 = 0,
			name = "default:stone",
			prob = 254
		},
		{
			param2 = 0,
			name = "default:stone",
			prob = 254
		},
		{
			param2 = 0,
			name = "default:stone",
			prob = 254
		},
		{
			param2 = 0,
			name = "default:stone",
			prob = 254
		},
		{
			param2 = 0,
			name = "default:stone",
			prob = 254
		},
		{
			param2 = 0,
			name = "default:stone",
			prob = 254
		},
		{
			param2 = 0,
			name = "default:stone",
			prob = 254
		},
		{
			param2 = 0,
			name = "default:stone",
			prob = 254
		},
		{
			param2 = 0,
			name = "default:stone",
			prob = 254
		},
		{
			param2 = 0,
			name = "default:stone",
			prob = 254
		},
		{
			param2 = 0,
			name = "default:stone",
			prob = 254
		},
		{
			param2 = 0,
			name = "air",
			prob = 254
		},
		{
			param2 = 0,
			name = "default:stone",
			prob = 254
		},
		{
			param2 = 0,
			name = "default:stone",
			prob = 254
		},
		{
			param2 = 0,
			name = "default:stone",
			prob = 254
		},
		{
			param2 = 0,
			name = "default:stone",
			prob = 254
		},
		{
			param2 = 0,
			name = "default:stone",
			prob = 254
		},
		{
			param2 = 0,
			name = "default:stone",
			prob = 254
		},
		{
			param2 = 0,
			name = "default:stone",
			prob = 254
		},
		{
			param2 = 0,
			name = "default:stone",
			prob = 254
		},
		{
			param2 = 0,
			name = "default:stone",
			prob = 254
		},
		{
			param2 = 0,
			name = "default:stone",
			prob = 254
		},
		{
			param2 = 0,
			name = "default:stone",
			prob = 254
		},
		{
			param2 = 0,
			name = "default:stone",
			prob = 254
		},
		{
			param2 = 0,
			name = "default:stone",
			prob = 254
		},
		{
			param2 = 0,
			name = "default:stone",
			prob = 254
		},
		{
			param2 = 0,
			name = "default:stone",
			prob = 254
		},
		{
			param2 = 0,
			name = "default:stone",
			prob = 254
		},
		{
			param2 = 0,
			name = "default:stone",
			prob = 254
		},
		{
			param2 = 0,
			name = "default:stone",
			prob = 254
		},
		{
			param2 = 0,
			name = "air",
			prob = 254
		},
		{
			param2 = 0,
			name = "air",
			prob = 254
		},
		{
			param2 = 0,
			name = "air",
			prob = 254
		},
		{
			param2 = 0,
			name = "air",
			prob = 254
		},
		{
			param2 = 0,
			name = "air",
			prob = 254
		},
		{
			param2 = 0,
			name = "air",
			prob = 254
		},
		{
			param2 = 0,
			name = "air",
			prob = 254
		},
		{
			param2 = 0,
			name = "air",
			prob = 254
		},
		{
			param2 = 0,
			name = "air",
			prob = 254
		},
		{
			param2 = 0,
			name = "air",
			prob = 254
		},
		{
			param2 = 0,
			name = "air",
			prob = 254
		},
		{
			param2 = 0,
			name = "air",
			prob = 254
		},
		{
			param2 = 0,
			name = "air",
			prob = 254
		},
		{
			param2 = 0,
			name = "air",
			prob = 254
		},
		{
			param2 = 0,
			name = "air",
			prob = 254
		},
		{
			param2 = 0,
			name = "air",
			prob = 254
		},
		{
			param2 = 0,
			name = "carts:rail",
			prob = 254
		},
		{
			param2 = 1,
			name = "default:furnace",
			prob = 254
		},
		{
			param2 = 0,
			name = "default:stone",
			prob = 254
		},
		{
			param2 = 0,
			name = "default:stone",
			prob = 254
		},
		{
			param2 = 0,
			name = "air",
			prob = 254
		},
		{
			param2 = 0,
			name = "air",
			prob = 254
		},
		{
			param2 = 0,
			name = "air",
			prob = 254
		},
		{
			param2 = 0,
			name = "air",
			prob = 254
		},
		{
			param2 = 0,
			name = "air",
			prob = 254
		},
		{
			param2 = 0,
			name = "air",
			prob = 254
		},
		{
			param2 = 0,
			name = "air",
			prob = 254
		},
		{
			param2 = 0,
			name = "air",
			prob = 254
		},
		{
			param2 = 0,
			name = "air",
			prob = 254
		},
		{
			param2 = 0,
			name = "air",
			prob = 254
		},
		{
			param2 = 0,
			name = "air",
			prob = 254
		},
		{
			param2 = 0,
			name = "air",
			prob = 254
		},
		{
			param2 = 0,
			name = "air",
			prob = 254
		},
		{
			param2 = 0,
			name = "air",
			prob = 254
		},
		{
			param2 = 0,
			name = "air",
			prob = 254
		},
		{
			param2 = 0,
			name = "air",
			prob = 254
		},
		{
			param2 = 0,
			name = "air",
			prob = 254
		},
		{
			param2 = 0,
			name = "air",
			prob = 254
		},
		{
			param2 = 0,
			name = "default:stone",
			prob = 254
		},
		{
			param2 = 0,
			name = "default:stone",
			prob = 254
		},
		{
			param2 = 0,
			name = "air",
			prob = 254
		},
		{
			param2 = 0,
			name = "air",
			prob = 254
		},
		{
			param2 = 0,
			name = "air",
			prob = 254
		},
		{
			param2 = 0,
			name = "air",
			prob = 254
		},
		{
			param2 = 0,
			name = "air",
			prob = 254
		},
		{
			param2 = 0,
			name = "air",
			prob = 254
		},
		{
			param2 = 0,
			name = "air",
			prob = 254
		},
		{
			param2 = 0,
			name = "air",
			prob = 254
		},
		{
			param2 = 0,
			name = "air",
			prob = 254
		},
		{
			param2 = 0,
			name = "air",
			prob = 254
		},
		{
			param2 = 0,
			name = "air",
			prob = 254
		},
		{
			param2 = 0,
			name = "air",
			prob = 254
		},
		{
			param2 = 0,
			name = "air",
			prob = 254
		},
		{
			param2 = 0,
			name = "air",
			prob = 254
		},
		{
			param2 = 0,
			name = "air",
			prob = 254
		},
		{
			param2 = 0,
			name = "air",
			prob = 254
		},
		{
			param2 = 0,
			name = "air",
			prob = 254
		},
		{
			param2 = 0,
			name = "air",
			prob = 254
		},
		{
			param2 = 0,
			name = "default:stone",
			prob = 254
		},
		{
			param2 = 0,
			name = "default:stone",
			prob = 254
		},
		{
			param2 = 7,
			name = "default:tree",
			prob = 254
		},
		{
			param2 = 0,
			name = "air",
			prob = 254
		},
		{
			param2 = 0,
			name = "air",
			prob = 254
		},
		{
			param2 = 0,
			name = "mapgen:stalagtite2",
			prob = 254
		},
		{
			param2 = 7,
			name = "default:tree",
			prob = 254
		},
		{
			param2 = 0,
			name = "air",
			prob = 254
		},
		{
			param2 = 0,
			name = "air",
			prob = 254
		},
		{
			param2 = 0,
			name = "air",
			prob = 254
		},
		{
			param2 = 0,
			name = "air",
			prob = 254
		},
		{
			param2 = 0,
			name = "air",
			prob = 254
		},
		{
			param2 = 0,
			name = "air",
			prob = 254
		},
		{
			param2 = 0,
			name = "air",
			prob = 254
		},
		{
			param2 = 0,
			name = "air",
			prob = 254
		},
		{
			param2 = 7,
			name = "default:tree",
			prob = 254
		},
		{
			param2 = 0,
			name = "air",
			prob = 254
		},
		{
			param2 = 0,
			name = "air",
			prob = 254
		},
		{
			param2 = 0,
			name = "air",
			prob = 254
		},
		{
			param2 = 7,
			name = "default:tree",
			prob = 254
		},
		{
			param2 = 0,
			name = "default:stone",
			prob = 254
		},
		{
			param2 = 0,
			name = "default:stone",
			prob = 254
		},
		{
			param2 = 0,
			name = "default:stone",
			prob = 254
		},
		{
			param2 = 0,
			name = "default:stone",
			prob = 254
		},
		{
			param2 = 0,
			name = "default:stone",
			prob = 254
		},
		{
			param2 = 0,
			name = "default:stone",
			prob = 254
		},
		{
			param2 = 0,
			name = "default:stone",
			prob = 254
		},
		{
			param2 = 0,
			name = "default:stone",
			prob = 254
		},
		{
			param2 = 0,
			name = "default:stone",
			prob = 254
		},
		{
			param2 = 0,
			name = "default:stone",
			prob = 254
		},
		{
			param2 = 0,
			name = "default:stone",
			prob = 254
		},
		{
			param2 = 0,
			name = "default:stone",
			prob = 254
		},
		{
			param2 = 0,
			name = "default:stone",
			prob = 254
		},
		{
			param2 = 0,
			name = "default:stone",
			prob = 254
		},
		{
			param2 = 0,
			name = "default:stone",
			prob = 254
		},
		{
			param2 = 0,
			name = "default:stone",
			prob = 254
		},
		{
			param2 = 0,
			name = "default:stone",
			prob = 254
		},
		{
			param2 = 0,
			name = "default:stone",
			prob = 254
		},
		{
			param2 = 0,
			name = "default:stone",
			prob = 254
		},
		{
			param2 = 0,
			name = "default:stone",
			prob = 254
		},
		{
			param2 = 0,
			name = "default:stone",
			prob = 254
		},
		{
			param2 = 0,
			name = "default:stone",
			prob = 254
		},
		{
			param2 = 0,
			name = "default:stone",
			prob = 254
		},
		{
			param2 = 0,
			name = "default:stone",
			prob = 254
		},
		{
			param2 = 0,
			name = "default:stone",
			prob = 254
		},
		{
			param2 = 0,
			name = "default:stone",
			prob = 254
		},
		{
			param2 = 0,
			name = "default:stone",
			prob = 254
		},
		{
			param2 = 0,
			name = "default:stone",
			prob = 254
		},
		{
			param2 = 0,
			name = "default:stone",
			prob = 254
		},
		{
			param2 = 0,
			name = "default:stone",
			prob = 254
		},
		{
			param2 = 0,
			name = "default:stone",
			prob = 254
		},
		{
			param2 = 0,
			name = "default:stone",
			prob = 254
		},
		{
			param2 = 0,
			name = "default:stone",
			prob = 254
		},
		{
			param2 = 0,
			name = "default:stone",
			prob = 254
		},
		{
			param2 = 0,
			name = "default:stone",
			prob = 254
		},
		{
			param2 = 0,
			name = "default:stone",
			prob = 254
		},
		{
			param2 = 0,
			name = "default:stone",
			prob = 254
		},
		{
			param2 = 0,
			name = "default:stone",
			prob = 254
		},
		{
			param2 = 0,
			name = "default:stone",
			prob = 254
		},
		{
			param2 = 0,
			name = "default:stone",
			prob = 254
		},
		{
			param2 = 0,
			name = "default:stone",
			prob = 254
		},
		{
			param2 = 0,
			name = "default:stone",
			prob = 254
		},
		{
			param2 = 2,
			name = "default:tree",
			prob = 254
		},
		{
			param2 = 0,
			name = "carts:rail",
			prob = 254
		},
		{
			param2 = 0,
			name = "default:stone",
			prob = 254
		},
		{
			param2 = 0,
			name = "default:stone",
			prob = 254
		},
		{
			param2 = 2,
			name = "default:tree",
			prob = 254
		},
		{
			param2 = 0,
			name = "default:stone",
			prob = 254
		},
		{
			param2 = 0,
			name = "default:stone",
			prob = 254
		},
		{
			param2 = 0,
			name = "default:stone",
			prob = 254
		},
		{
			param2 = 2,
			name = "default:tree",
			prob = 254
		},
		{
			param2 = 0,
			name = "default:stone",
			prob = 254
		},
		{
			param2 = 0,
			name = "default:stone",
			prob = 254
		},
		{
			param2 = 0,
			name = "default:stone",
			prob = 254
		},
		{
			param2 = 2,
			name = "default:tree",
			prob = 254
		},
		{
			param2 = 0,
			name = "default:stone",
			prob = 254
		},
		{
			param2 = 0,
			name = "default:stone",
			prob = 254
		},
		{
			param2 = 0,
			name = "default:stone",
			prob = 254
		},
		{
			param2 = 0,
			name = "default:stone",
			prob = 254
		},
		{
			param2 = 0,
			name = "default:stone",
			prob = 254
		},
		{
			param2 = 0,
			name = "default:stone",
			prob = 254
		},
		{
			param2 = 0,
			name = "default:stone",
			prob = 254
		},
		{
			param2 = 2,
			name = "default:tree",
			prob = 254
		},
		{
			param2 = 0,
			name = "air",
			prob = 254
		},
		{
			param2 = 0,
			name = "default:stone",
			prob = 254
		},
		{
			param2 = 0,
			name = "default:stone",
			prob = 254
		},
		{
			param2 = 2,
			name = "default:tree",
			prob = 254
		},
		{
			param2 = 0,
			name = "default:stone",
			prob = 254
		},
		{
			param2 = 0,
			name = "default:stone",
			prob = 254
		},
		{
			param2 = 0,
			name = "default:stone",
			prob = 254
		},
		{
			param2 = 2,
			name = "default:tree",
			prob = 254
		},
		{
			param2 = 0,
			name = "default:stone",
			prob = 254
		},
		{
			param2 = 0,
			name = "default:stone",
			prob = 254
		},
		{
			param2 = 0,
			name = "default:stone",
			prob = 254
		},
		{
			param2 = 2,
			name = "default:tree",
			prob = 254
		},
		{
			param2 = 0,
			name = "default:stone",
			prob = 254
		},
		{
			param2 = 0,
			name = "default:stone",
			prob = 254
		},
		{
			param2 = 0,
			name = "default:stone",
			prob = 254
		},
		{
			param2 = 0,
			name = "default:stone",
			prob = 254
		},
		{
			param2 = 0,
			name = "default:stone",
			prob = 254
		},
		{
			param2 = 0,
			name = "default:stone",
			prob = 254
		},
		{
			param2 = 0,
			name = "default:stone",
			prob = 254
		},
		{
			param2 = 2,
			name = "default:tree",
			prob = 254
		},
		{
			param2 = 0,
			name = "air",
			prob = 254
		},
		{
			param2 = 0,
			name = "default:wood",
			prob = 254
		},
		{
			param2 = 0,
			name = "default:wood",
			prob = 254
		},
		{
			param2 = 2,
			name = "default:tree",
			prob = 254
		},
		{
			param2 = 0,
			name = "default:wood",
			prob = 254
		},
		{
			param2 = 0,
			name = "default:wood",
			prob = 254
		},
		{
			param2 = 0,
			name = "default:wood",
			prob = 254
		},
		{
			param2 = 2,
			name = "default:tree",
			prob = 254
		},
		{
			param2 = 0,
			name = "default:wood",
			prob = 254
		},
		{
			param2 = 0,
			name = "default:wood",
			prob = 254
		},
		{
			param2 = 0,
			name = "default:wood",
			prob = 254
		},
		{
			param2 = 2,
			name = "default:tree",
			prob = 254
		},
		{
			param2 = 0,
			name = "default:wood",
			prob = 254
		},
		{
			param2 = 0,
			name = "default:wood",
			prob = 254
		},
		{
			param2 = 0,
			name = "default:stone",
			prob = 254
		},
		{
			param2 = 0,
			name = "default:stone",
			prob = 254
		},
		{
			param2 = 0,
			name = "default:stone",
			prob = 254
		},
		{
			param2 = 0,
			name = "default:stone",
			prob = 254
		},
		{
			param2 = 0,
			name = "default:stone",
			prob = 254
		},
		{
			param2 = 0,
			name = "air",
			prob = 254
		},
		{
			param2 = 0,
			name = "air",
			prob = 254
		},
		{
			param2 = 0,
			name = "air",
			prob = 254
		},
		{
			param2 = 0,
			name = "air",
			prob = 254
		},
		{
			param2 = 0,
			name = "air",
			prob = 254
		},
		{
			param2 = 0,
			name = "air",
			prob = 254
		},
		{
			param2 = 0,
			name = "air",
			prob = 254
		},
		{
			param2 = 0,
			name = "air",
			prob = 254
		},
		{
			param2 = 0,
			name = "air",
			prob = 254
		},
		{
			param2 = 0,
			name = "air",
			prob = 254
		},
		{
			param2 = 0,
			name = "air",
			prob = 254
		},
		{
			param2 = 0,
			name = "air",
			prob = 254
		},
		{
			param2 = 0,
			name = "air",
			prob = 254
		},
		{
			param2 = 0,
			name = "mobs_m:mimic_chest2",
			prob = 254
		},
		{
			param2 = 0,
			name = "default:wood",
			prob = 254
		},
		{
			param2 = 0,
			name = "air",
			prob = 254
		},
		{
			param2 = 0,
			name = "carts:rail",
			prob = 254
		},
		{
			param2 = 1,
			name = "default:furnace",
			prob = 254
		},
		{
			param2 = 0,
			name = "default:stone",
			prob = 254
		},
		{
			param2 = 0,
			name = "default:stone",
			prob = 254
		},
		{
			param2 = 0,
			name = "air",
			prob = 254
		},
		{
			param2 = 0,
			name = "air",
			prob = 254
		},
		{
			param2 = 0,
			name = "air",
			prob = 254
		},
		{
			param2 = 0,
			name = "air",
			prob = 254
		},
		{
			param2 = 0,
			name = "air",
			prob = 254
		},
		{
			param2 = 0,
			name = "air",
			prob = 254
		},
		{
			param2 = 0,
			name = "air",
			prob = 254
		},
		{
			param2 = 0,
			name = "air",
			prob = 254
		},
		{
			param2 = 0,
			name = "air",
			prob = 254
		},
		{
			param2 = 0,
			name = "air",
			prob = 254
		},
		{
			param2 = 0,
			name = "air",
			prob = 254
		},
		{
			param2 = 0,
			name = "air",
			prob = 254
		},
		{
			param2 = 0,
			name = "air",
			prob = 254
		},
		{
			param2 = 0,
			name = "air",
			prob = 254
		},
		{
			param2 = 0,
			name = "air",
			prob = 254
		},
		{
			param2 = 0,
			name = "air",
			prob = 254
		},
		{
			param2 = 0,
			name = "air",
			prob = 254
		},
		{
			param2 = 0,
			name = "air",
			prob = 254
		},
		{
			param2 = 0,
			name = "default:stone",
			prob = 254
		},
		{
			param2 = 0,
			name = "default:stone",
			prob = 254
		},
		{
			param2 = 0,
			name = "air",
			prob = 254
		},
		{
			param2 = 0,
			name = "air",
			prob = 254
		},
		{
			param2 = 0,
			name = "air",
			prob = 254
		},
		{
			param2 = 0,
			name = "air",
			prob = 254
		},
		{
			param2 = 0,
			name = "air",
			prob = 254
		},
		{
			param2 = 0,
			name = "air",
			prob = 254
		},
		{
			param2 = 0,
			name = "air",
			prob = 254
		},
		{
			param2 = 0,
			name = "air",
			prob = 254
		},
		{
			param2 = 0,
			name = "air",
			prob = 254
		},
		{
			param2 = 0,
			name = "air",
			prob = 254
		},
		{
			param2 = 0,
			name = "air",
			prob = 254
		},
		{
			param2 = 0,
			name = "air",
			prob = 254
		},
		{
			param2 = 0,
			name = "air",
			prob = 254
		},
		{
			param2 = 0,
			name = "air",
			prob = 254
		},
		{
			param2 = 0,
			name = "air",
			prob = 254
		},
		{
			param2 = 0,
			name = "air",
			prob = 254
		},
		{
			param2 = 0,
			name = "air",
			prob = 254
		},
		{
			param2 = 0,
			name = "air",
			prob = 254
		},
		{
			param2 = 0,
			name = "default:stone",
			prob = 254
		},
		{
			param2 = 0,
			name = "default:stone",
			prob = 254
		},
		{
			param2 = 7,
			name = "default:tree",
			prob = 254
		},
		{
			param2 = 0,
			name = "mapgen:stalagtite2",
			prob = 254
		},
		{
			param2 = 0,
			name = "air",
			prob = 254
		},
		{
			param2 = 0,
			name = "air",
			prob = 254
		},
		{
			param2 = 7,
			name = "default:tree",
			prob = 254
		},
		{
			param2 = 0,
			name = "mapgen:stalagtite1",
			prob = 254
		},
		{
			param2 = 0,
			name = "air",
			prob = 254
		},
		{
			param2 = 0,
			name = "air",
			prob = 254
		},
		{
			param2 = 0,
			name = "air",
			prob = 254
		},
		{
			param2 = 0,
			name = "air",
			prob = 254
		},
		{
			param2 = 0,
			name = "mapgen:stalagtite2",
			prob = 254
		},
		{
			param2 = 0,
			name = "mapgen:stalagtite",
			prob = 254
		},
		{
			param2 = 0,
			name = "air",
			prob = 254
		},
		{
			param2 = 7,
			name = "default:tree",
			prob = 254
		},
		{
			param2 = 0,
			name = "air",
			prob = 254
		},
		{
			param2 = 0,
			name = "air",
			prob = 254
		},
		{
			param2 = 0,
			name = "mapgen:stalagtite2",
			prob = 254
		},
		{
			param2 = 7,
			name = "default:tree",
			prob = 254
		},
		{
			param2 = 0,
			name = "default:stone",
			prob = 254
		},
		{
			param2 = 0,
			name = "default:stone",
			prob = 254
		},
		{
			param2 = 0,
			name = "default:stone",
			prob = 254
		},
		{
			param2 = 0,
			name = "default:stone",
			prob = 254
		},
		{
			param2 = 0,
			name = "default:stone",
			prob = 254
		},
		{
			param2 = 0,
			name = "default:stone",
			prob = 254
		},
		{
			param2 = 0,
			name = "default:stone",
			prob = 254
		},
		{
			param2 = 0,
			name = "default:stone",
			prob = 254
		},
		{
			param2 = 0,
			name = "default:stone",
			prob = 254
		},
		{
			param2 = 0,
			name = "default:stone",
			prob = 254
		},
		{
			param2 = 0,
			name = "default:stone",
			prob = 254
		},
		{
			param2 = 0,
			name = "default:stone",
			prob = 254
		},
		{
			param2 = 0,
			name = "default:stone",
			prob = 254
		},
		{
			param2 = 0,
			name = "default:stone",
			prob = 254
		},
		{
			param2 = 0,
			name = "default:stone",
			prob = 254
		},
		{
			param2 = 0,
			name = "default:stone",
			prob = 254
		},
		{
			param2 = 0,
			name = "default:stone",
			prob = 254
		},
		{
			param2 = 0,
			name = "default:stone",
			prob = 254
		},
		{
			param2 = 0,
			name = "default:stone",
			prob = 254
		},
		{
			param2 = 0,
			name = "default:stone",
			prob = 254
		},
		{
			param2 = 0,
			name = "default:stone",
			prob = 254
		},
		{
			param2 = 0,
			name = "default:stone",
			prob = 254
		},
		{
			param2 = 0,
			name = "default:stone",
			prob = 254
		},
		{
			param2 = 0,
			name = "default:stone",
			prob = 254
		},
		{
			param2 = 0,
			name = "default:stone",
			prob = 254
		},
		{
			param2 = 0,
			name = "default:stone",
			prob = 254
		},
		{
			param2 = 0,
			name = "default:stone",
			prob = 254
		},
		{
			param2 = 0,
			name = "default:stone",
			prob = 254
		},
		{
			param2 = 0,
			name = "default:stone",
			prob = 254
		},
		{
			param2 = 0,
			name = "default:stone",
			prob = 254
		},
		{
			param2 = 0,
			name = "default:stone",
			prob = 254
		},
		{
			param2 = 0,
			name = "default:stone",
			prob = 254
		},
		{
			param2 = 0,
			name = "default:stone",
			prob = 254
		},
		{
			param2 = 0,
			name = "default:stone",
			prob = 254
		},
		{
			param2 = 0,
			name = "default:stone",
			prob = 254
		},
		{
			param2 = 0,
			name = "default:stone",
			prob = 254
		},
		{
			param2 = 0,
			name = "default:stone",
			prob = 254
		},
		{
			param2 = 0,
			name = "default:stone",
			prob = 254
		},
		{
			param2 = 0,
			name = "default:stone",
			prob = 254
		},
		{
			param2 = 0,
			name = "default:stone",
			prob = 254
		},
		{
			param2 = 0,
			name = "default:stone",
			prob = 254
		},
		{
			param2 = 0,
			name = "default:stone",
			prob = 254
		},
		{
			param2 = 0,
			name = "air",
			prob = 254
		},
		{
			param2 = 0,
			name = "carts:rail",
			prob = 254
		},
		{
			param2 = 0,
			name = "air",
			prob = 254
		},
		{
			param2 = 0,
			name = "air",
			prob = 254
		},
		{
			param2 = 0,
			name = "air",
			prob = 254
		},
		{
			param2 = 0,
			name = "air",
			prob = 254
		},
		{
			param2 = 0,
			name = "air",
			prob = 254
		},
		{
			param2 = 0,
			name = "air",
			prob = 254
		},
		{
			param2 = 0,
			name = "air",
			prob = 254
		},
		{
			param2 = 0,
			name = "air",
			prob = 254
		},
		{
			param2 = 0,
			name = "air",
			prob = 254
		},
		{
			param2 = 0,
			name = "air",
			prob = 254
		},
		{
			param2 = 0,
			name = "air",
			prob = 254
		},
		{
			param2 = 2,
			name = "mobs_m:mimic_chest2",
			prob = 254
		},
		{
			param2 = 0,
			name = "default:stone",
			prob = 254
		},
		{
			param2 = 0,
			name = "default:stone",
			prob = 254
		},
		{
			param2 = 0,
			name = "default:stone",
			prob = 254
		},
		{
			param2 = 0,
			name = "default:stone",
			prob = 254
		},
		{
			param2 = 0,
			name = "default:stone",
			prob = 254
		},
		{
			param2 = 0,
			name = "default:stone",
			prob = 254
		},
		{
			param2 = 0,
			name = "air",
			prob = 254
		},
		{
			param2 = 0,
			name = "air",
			prob = 254
		},
		{
			param2 = 0,
			name = "air",
			prob = 254
		},
		{
			param2 = 0,
			name = "air",
			prob = 254
		},
		{
			param2 = 0,
			name = "air",
			prob = 254
		},
		{
			param2 = 0,
			name = "air",
			prob = 254
		},
		{
			param2 = 0,
			name = "air",
			prob = 254
		},
		{
			param2 = 0,
			name = "air",
			prob = 254
		},
		{
			param2 = 0,
			name = "air",
			prob = 254
		},
		{
			param2 = 0,
			name = "air",
			prob = 254
		},
		{
			param2 = 0,
			name = "air",
			prob = 254
		},
		{
			param2 = 0,
			name = "air",
			prob = 254
		},
		{
			param2 = 0,
			name = "air",
			prob = 254
		},
		{
			param2 = 0,
			name = "air",
			prob = 254
		},
		{
			param2 = 0,
			name = "default:stone",
			prob = 254
		},
		{
			param2 = 0,
			name = "default:stone",
			prob = 254
		},
		{
			param2 = 0,
			name = "default:stone",
			prob = 254
		},
		{
			param2 = 0,
			name = "default:stone",
			prob = 254
		},
		{
			param2 = 0,
			name = "default:stone",
			prob = 254
		},
		{
			param2 = 0,
			name = "default:stone",
			prob = 254
		},
		{
			param2 = 0,
			name = "default:wood",
			prob = 254
		},
		{
			param2 = 0,
			name = "default:wood",
			prob = 254
		},
		{
			param2 = 0,
			name = "default:wood",
			prob = 254
		},
		{
			param2 = 0,
			name = "default:wood",
			prob = 254
		},
		{
			param2 = 0,
			name = "default:wood",
			prob = 254
		},
		{
			param2 = 0,
			name = "default:wood",
			prob = 254
		},
		{
			param2 = 0,
			name = "default:wood",
			prob = 254
		},
		{
			param2 = 0,
			name = "default:wood",
			prob = 254
		},
		{
			param2 = 0,
			name = "default:wood",
			prob = 254
		},
		{
			param2 = 0,
			name = "default:wood",
			prob = 254
		},
		{
			param2 = 0,
			name = "default:wood",
			prob = 254
		},
		{
			param2 = 0,
			name = "default:wood",
			prob = 254
		},
		{
			param2 = 0,
			name = "default:wood",
			prob = 254
		},
		{
			param2 = 0,
			name = "default:wood",
			prob = 254
		},
		{
			param2 = 0,
			name = "default:wood",
			prob = 254
		},
		{
			param2 = 0,
			name = "default:stone",
			prob = 254
		},
		{
			param2 = 0,
			name = "default:stone",
			prob = 254
		},
		{
			param2 = 0,
			name = "default:stone",
			prob = 254
		},
		{
			param2 = 0,
			name = "default:stone",
			prob = 254
		},
		{
			param2 = 0,
			name = "default:stone",
			prob = 254
		},
		{
			param2 = 3,
			name = "default:tree",
			prob = 254
		},
		{
			param2 = 0,
			name = "air",
			prob = 254
		},
		{
			param2 = 0,
			name = "air",
			prob = 254
		},
		{
			param2 = 0,
			name = "air",
			prob = 254
		},
		{
			param2 = 2,
			name = "default:tree",
			prob = 254
		},
		{
			param2 = 0,
			name = "air",
			prob = 254
		},
		{
			param2 = 0,
			name = "air",
			prob = 254
		},
		{
			param2 = 0,
			name = "air",
			prob = 254
		},
		{
			param2 = 0,
			name = "air",
			prob = 254
		},
		{
			param2 = 0,
			name = "air",
			prob = 254
		},
		{
			param2 = 0,
			name = "air",
			prob = 254
		},
		{
			param2 = 0,
			name = "air",
			prob = 254
		},
		{
			param2 = 0,
			name = "air",
			prob = 254
		},
		{
			param2 = 1,
			name = "default:tree",
			prob = 254
		},
		{
			param2 = 3,
			name = "decoblocks:chest",
			prob = 254
		},
		{
			param2 = 0,
			name = "air",
			prob = 254
		},
		{
			param2 = 0,
			name = "carts:rail",
			prob = 254
		},
		{
			param2 = 1,
			name = "default:tree",
			prob = 254
		},
		{
			param2 = 0,
			name = "default:stone",
			prob = 254
		},
		{
			param2 = 0,
			name = "default:stone",
			prob = 254
		},
		{
			param2 = 3,
			name = "default:tree",
			prob = 254
		},
		{
			param2 = 0,
			name = "air",
			prob = 254
		},
		{
			param2 = 0,
			name = "air",
			prob = 254
		},
		{
			param2 = 0,
			name = "air",
			prob = 254
		},
		{
			param2 = 2,
			name = "default:tree",
			prob = 254
		},
		{
			param2 = 0,
			name = "air",
			prob = 254
		},
		{
			param2 = 0,
			name = "air",
			prob = 254
		},
		{
			param2 = 0,
			name = "air",
			prob = 254
		},
		{
			param2 = 0,
			name = "air",
			prob = 254
		},
		{
			param2 = 0,
			name = "air",
			prob = 254
		},
		{
			param2 = 0,
			name = "air",
			prob = 254
		},
		{
			param2 = 0,
			name = "air",
			prob = 254
		},
		{
			param2 = 0,
			name = "air",
			prob = 254
		},
		{
			param2 = 1,
			name = "default:tree",
			prob = 254
		},
		{
			param2 = 0,
			name = "air",
			prob = 254
		},
		{
			param2 = 0,
			name = "air",
			prob = 254
		},
		{
			param2 = 0,
			name = "air",
			prob = 254
		},
		{
			param2 = 1,
			name = "default:tree",
			prob = 254
		},
		{
			param2 = 0,
			name = "default:stone",
			prob = 254
		},
		{
			param2 = 0,
			name = "default:stone",
			prob = 254
		},
		{
			param2 = 3,
			name = "default:tree",
			prob = 254
		},
		{
			param2 = 0,
			name = "air",
			prob = 254
		},
		{
			param2 = 0,
			name = "air",
			prob = 254
		},
		{
			param2 = 0,
			name = "air",
			prob = 254
		},
		{
			param2 = 2,
			name = "default:tree",
			prob = 254
		},
		{
			param2 = 0,
			name = "air",
			prob = 254
		},
		{
			param2 = 0,
			name = "air",
			prob = 254
		},
		{
			param2 = 0,
			name = "air",
			prob = 254
		},
		{
			param2 = 0,
			name = "air",
			prob = 254
		},
		{
			param2 = 0,
			name = "air",
			prob = 254
		},
		{
			param2 = 0,
			name = "air",
			prob = 254
		},
		{
			param2 = 0,
			name = "air",
			prob = 254
		},
		{
			param2 = 0,
			name = "air",
			prob = 254
		},
		{
			param2 = 1,
			name = "default:tree",
			prob = 254
		},
		{
			param2 = 0,
			name = "air",
			prob = 254
		},
		{
			param2 = 0,
			name = "air",
			prob = 254
		},
		{
			param2 = 0,
			name = "air",
			prob = 254
		},
		{
			param2 = 1,
			name = "default:tree",
			prob = 254
		},
		{
			param2 = 0,
			name = "default:stone",
			prob = 254
		},
		{
			param2 = 0,
			name = "default:stone",
			prob = 254
		},
		{
			param2 = 3,
			name = "default:tree",
			prob = 254
		},
		{
			param2 = 12,
			name = "default:tree",
			prob = 254
		},
		{
			param2 = 12,
			name = "default:tree",
			prob = 254
		},
		{
			param2 = 12,
			name = "default:tree",
			prob = 254
		},
		{
			param2 = 2,
			name = "default:tree",
			prob = 254
		},
		{
			param2 = 18,
			name = "default:tree",
			prob = 254
		},
		{
			param2 = 18,
			name = "default:tree",
			prob = 254
		},
		{
			param2 = 18,
			name = "default:tree",
			prob = 254
		},
		{
			param2 = 18,
			name = "default:tree",
			prob = 254
		},
		{
			param2 = 18,
			name = "default:tree",
			prob = 254
		},
		{
			param2 = 18,
			name = "default:tree",
			prob = 254
		},
		{
			param2 = 18,
			name = "default:tree",
			prob = 254
		},
		{
			param2 = 18,
			name = "default:tree",
			prob = 254
		},
		{
			param2 = 1,
			name = "default:tree",
			prob = 254
		},
		{
			param2 = 18,
			name = "default:tree",
			prob = 254
		},
		{
			param2 = 18,
			name = "default:tree",
			prob = 254
		},
		{
			param2 = 18,
			name = "default:tree",
			prob = 254
		},
		{
			param2 = 1,
			name = "default:tree",
			prob = 254
		},
		{
			param2 = 0,
			name = "default:stone",
			prob = 254
		},
		{
			param2 = 0,
			name = "default:stone",
			prob = 254
		},
		{
			param2 = 0,
			name = "default:stone",
			prob = 254
		},
		{
			param2 = 0,
			name = "default:stone",
			prob = 254
		},
		{
			param2 = 0,
			name = "default:stone",
			prob = 254
		},
		{
			param2 = 0,
			name = "default:stone",
			prob = 254
		},
		{
			param2 = 0,
			name = "default:stone",
			prob = 254
		},
		{
			param2 = 0,
			name = "default:stone",
			prob = 254
		},
		{
			param2 = 0,
			name = "default:stone",
			prob = 254
		},
		{
			param2 = 0,
			name = "default:stone",
			prob = 254
		},
		{
			param2 = 0,
			name = "default:stone",
			prob = 254
		},
		{
			param2 = 0,
			name = "default:stone",
			prob = 254
		},
		{
			param2 = 0,
			name = "default:stone",
			prob = 254
		},
		{
			param2 = 0,
			name = "default:stone",
			prob = 254
		},
		{
			param2 = 0,
			name = "default:stone",
			prob = 254
		},
		{
			param2 = 0,
			name = "default:stone",
			prob = 254
		},
		{
			param2 = 0,
			name = "default:stone",
			prob = 254
		},
		{
			param2 = 0,
			name = "default:stone",
			prob = 254
		},
		{
			param2 = 0,
			name = "default:stone",
			prob = 254
		},
		{
			param2 = 0,
			name = "default:stone",
			prob = 254
		},
		{
			param2 = 0,
			name = "default:stone",
			prob = 254
		},
		{
			param2 = 0,
			name = "default:stone",
			prob = 254
		},
		{
			param2 = 0,
			name = "default:stone",
			prob = 254
		},
		{
			param2 = 0,
			name = "default:stone",
			prob = 254
		},
		{
			param2 = 0,
			name = "default:stone",
			prob = 254
		},
		{
			param2 = 0,
			name = "default:stone",
			prob = 254
		},
		{
			param2 = 0,
			name = "default:stone",
			prob = 254
		},
		{
			param2 = 0,
			name = "default:stone",
			prob = 254
		},
		{
			param2 = 0,
			name = "default:stone",
			prob = 254
		},
		{
			param2 = 0,
			name = "default:stone",
			prob = 254
		},
		{
			param2 = 0,
			name = "default:stone",
			prob = 254
		},
		{
			param2 = 0,
			name = "default:stone",
			prob = 254
		},
		{
			param2 = 0,
			name = "default:stone",
			prob = 254
		},
		{
			param2 = 0,
			name = "default:stone",
			prob = 254
		},
		{
			param2 = 0,
			name = "default:stone",
			prob = 254
		},
		{
			param2 = 0,
			name = "default:stone",
			prob = 254
		},
		{
			param2 = 0,
			name = "default:stone",
			prob = 254
		},
		{
			param2 = 0,
			name = "default:stone",
			prob = 254
		},
		{
			param2 = 0,
			name = "default:stone",
			prob = 254
		},
		{
			param2 = 0,
			name = "default:stone",
			prob = 254
		},
		{
			param2 = 0,
			name = "default:stone",
			prob = 254
		},
		{
			param2 = 0,
			name = "default:stone",
			prob = 254
		},
		{
			param2 = 0,
			name = "air",
			prob = 254
		},
		{
			param2 = 0,
			name = "carts:rail",
			prob = 254
		},
		{
			param2 = 0,
			name = "air",
			prob = 254
		},
		{
			param2 = 0,
			name = "air",
			prob = 254
		},
		{
			param2 = 0,
			name = "air",
			prob = 254
		},
		{
			param2 = 0,
			name = "air",
			prob = 254
		},
		{
			param2 = 0,
			name = "air",
			prob = 254
		},
		{
			param2 = 0,
			name = "air",
			prob = 254
		},
		{
			param2 = 0,
			name = "air",
			prob = 254
		},
		{
			param2 = 0,
			name = "air",
			prob = 254
		},
		{
			param2 = 0,
			name = "air",
			prob = 254
		},
		{
			param2 = 0,
			name = "air",
			prob = 254
		},
		{
			param2 = 0,
			name = "air",
			prob = 254
		},
		{
			param2 = 0,
			name = "air",
			prob = 254
		},
		{
			param2 = 1,
			name = "default:tree",
			prob = 254
		},
		{
			param2 = 0,
			name = "default:stone",
			prob = 254
		},
		{
			param2 = 0,
			name = "default:stone",
			prob = 254
		},
		{
			param2 = 0,
			name = "default:stone",
			prob = 254
		},
		{
			param2 = 0,
			name = "default:stone",
			prob = 254
		},
		{
			param2 = 0,
			name = "default:stone",
			prob = 254
		},
		{
			param2 = 0,
			name = "air",
			prob = 254
		},
		{
			param2 = 0,
			name = "air",
			prob = 254
		},
		{
			param2 = 0,
			name = "air",
			prob = 254
		},
		{
			param2 = 0,
			name = "air",
			prob = 254
		},
		{
			param2 = 0,
			name = "air",
			prob = 254
		},
		{
			param2 = 0,
			name = "air",
			prob = 254
		},
		{
			param2 = 0,
			name = "air",
			prob = 254
		},
		{
			param2 = 0,
			name = "air",
			prob = 254
		},
		{
			param2 = 0,
			name = "air",
			prob = 254
		},
		{
			param2 = 0,
			name = "air",
			prob = 254
		},
		{
			param2 = 0,
			name = "air",
			prob = 254
		},
		{
			param2 = 0,
			name = "air",
			prob = 254
		},
		{
			param2 = 0,
			name = "air",
			prob = 254
		},
		{
			param2 = 0,
			name = "air",
			prob = 254
		},
		{
			param2 = 1,
			name = "default:tree",
			prob = 254
		},
		{
			param2 = 0,
			name = "default:stone",
			prob = 254
		},
		{
			param2 = 0,
			name = "default:stone",
			prob = 254
		},
		{
			param2 = 0,
			name = "default:stone",
			prob = 254
		},
		{
			param2 = 0,
			name = "default:stone",
			prob = 254
		},
		{
			param2 = 0,
			name = "default:stone",
			prob = 254
		},
		{
			param2 = 0,
			name = "default:wood",
			prob = 254
		},
		{
			param2 = 0,
			name = "default:wood",
			prob = 254
		},
		{
			param2 = 0,
			name = "default:wood",
			prob = 254
		},
		{
			param2 = 0,
			name = "default:wood",
			prob = 254
		},
		{
			param2 = 0,
			name = "default:wood",
			prob = 254
		},
		{
			param2 = 0,
			name = "default:wood",
			prob = 254
		},
		{
			param2 = 0,
			name = "default:wood",
			prob = 254
		},
		{
			param2 = 0,
			name = "default:wood",
			prob = 254
		},
		{
			param2 = 0,
			name = "default:wood",
			prob = 254
		},
		{
			param2 = 0,
			name = "default:wood",
			prob = 254
		},
		{
			param2 = 0,
			name = "default:wood",
			prob = 254
		},
		{
			param2 = 0,
			name = "default:wood",
			prob = 254
		},
		{
			param2 = 0,
			name = "default:wood",
			prob = 254
		},
		{
			param2 = 0,
			name = "default:wood",
			prob = 254
		},
		{
			param2 = 1,
			name = "default:tree",
			prob = 254
		},
		{
			param2 = 0,
			name = "default:stone",
			prob = 254
		},
		{
			param2 = 0,
			name = "default:stone",
			prob = 254
		},
		{
			param2 = 0,
			name = "default:stone",
			prob = 254
		},
		{
			param2 = 0,
			name = "default:stone",
			prob = 254
		},
		{
			param2 = 0,
			name = "default:stone",
			prob = 254
		},
		{
			param2 = 0,
			name = "air",
			prob = 254
		},
		{
			param2 = 0,
			name = "air",
			prob = 254
		},
		{
			param2 = 0,
			name = "air",
			prob = 254
		},
		{
			param2 = 0,
			name = "air",
			prob = 254
		},
		{
			param2 = 0,
			name = "air",
			prob = 254
		},
		{
			param2 = 0,
			name = "air",
			prob = 254
		},
		{
			param2 = 0,
			name = "air",
			prob = 254
		},
		{
			param2 = 0,
			name = "air",
			prob = 254
		},
		{
			param2 = 0,
			name = "air",
			prob = 254
		},
		{
			param2 = 0,
			name = "air",
			prob = 254
		},
		{
			param2 = 0,
			name = "air",
			prob = 254
		},
		{
			param2 = 0,
			name = "air",
			prob = 254
		},
		{
			param2 = 0,
			name = "air",
			prob = 254
		},
		{
			param2 = 0,
			name = "air",
			prob = 254
		},
		{
			param2 = 0,
			name = "air",
			prob = 254
		},
		{
			param2 = 0,
			name = "air",
			prob = 254
		},
		{
			param2 = 0,
			name = "carts:rail",
			prob = 254
		},
		{
			param2 = 0,
			name = "air",
			prob = 254
		},
		{
			param2 = 0,
			name = "default:stone",
			prob = 254
		},
		{
			param2 = 0,
			name = "default:stone",
			prob = 254
		},
		{
			param2 = 0,
			name = "air",
			prob = 254
		},
		{
			param2 = 0,
			name = "air",
			prob = 254
		},
		{
			param2 = 0,
			name = "air",
			prob = 254
		},
		{
			param2 = 0,
			name = "air",
			prob = 254
		},
		{
			param2 = 0,
			name = "air",
			prob = 254
		},
		{
			param2 = 0,
			name = "air",
			prob = 254
		},
		{
			param2 = 0,
			name = "air",
			prob = 254
		},
		{
			param2 = 0,
			name = "air",
			prob = 254
		},
		{
			param2 = 0,
			name = "air",
			prob = 254
		},
		{
			param2 = 0,
			name = "air",
			prob = 254
		},
		{
			param2 = 0,
			name = "air",
			prob = 254
		},
		{
			param2 = 0,
			name = "air",
			prob = 254
		},
		{
			param2 = 0,
			name = "air",
			prob = 254
		},
		{
			param2 = 0,
			name = "air",
			prob = 254
		},
		{
			param2 = 0,
			name = "air",
			prob = 254
		},
		{
			param2 = 0,
			name = "air",
			prob = 254
		},
		{
			param2 = 0,
			name = "air",
			prob = 254
		},
		{
			param2 = 0,
			name = "air",
			prob = 254
		},
		{
			param2 = 0,
			name = "default:stone",
			prob = 254
		},
		{
			param2 = 0,
			name = "default:stone",
			prob = 254
		},
		{
			param2 = 0,
			name = "air",
			prob = 254
		},
		{
			param2 = 0,
			name = "air",
			prob = 254
		},
		{
			param2 = 0,
			name = "air",
			prob = 254
		},
		{
			param2 = 0,
			name = "air",
			prob = 254
		},
		{
			param2 = 0,
			name = "air",
			prob = 254
		},
		{
			param2 = 0,
			name = "air",
			prob = 254
		},
		{
			param2 = 0,
			name = "air",
			prob = 254
		},
		{
			param2 = 0,
			name = "air",
			prob = 254
		},
		{
			param2 = 0,
			name = "air",
			prob = 254
		},
		{
			param2 = 0,
			name = "air",
			prob = 254
		},
		{
			param2 = 0,
			name = "air",
			prob = 254
		},
		{
			param2 = 0,
			name = "air",
			prob = 254
		},
		{
			param2 = 0,
			name = "air",
			prob = 254
		},
		{
			param2 = 0,
			name = "air",
			prob = 254
		},
		{
			param2 = 0,
			name = "air",
			prob = 254
		},
		{
			param2 = 0,
			name = "air",
			prob = 254
		},
		{
			param2 = 0,
			name = "air",
			prob = 254
		},
		{
			param2 = 0,
			name = "air",
			prob = 254
		},
		{
			param2 = 0,
			name = "default:stone",
			prob = 254
		},
		{
			param2 = 0,
			name = "default:stone",
			prob = 254
		},
		{
			param2 = 9,
			name = "default:tree",
			prob = 254
		},
		{
			param2 = 0,
			name = "air",
			prob = 254
		},
		{
			param2 = 0,
			name = "air",
			prob = 254
		},
		{
			param2 = 0,
			name = "air",
			prob = 254
		},
		{
			param2 = 7,
			name = "default:tree",
			prob = 254
		},
		{
			param2 = 0,
			name = "air",
			prob = 254
		},
		{
			param2 = 0,
			name = "air",
			prob = 254
		},
		{
			param2 = 0,
			name = "air",
			prob = 254
		},
		{
			param2 = 0,
			name = "air",
			prob = 254
		},
		{
			param2 = 0,
			name = "air",
			prob = 254
		},
		{
			param2 = 0,
			name = "air",
			prob = 254
		},
		{
			param2 = 0,
			name = "air",
			prob = 254
		},
		{
			param2 = 0,
			name = "air",
			prob = 254
		},
		{
			param2 = 7,
			name = "default:tree",
			prob = 254
		},
		{
			param2 = 0,
			name = "air",
			prob = 254
		},
		{
			param2 = 0,
			name = "air",
			prob = 254
		},
		{
			param2 = 0,
			name = "mapgen:stalagtite1",
			prob = 254
		},
		{
			param2 = 9,
			name = "default:tree",
			prob = 254
		},
		{
			param2 = 0,
			name = "default:stone",
			prob = 254
		},
		{
			param2 = 0,
			name = "default:stone",
			prob = 254
		},
		{
			param2 = 0,
			name = "default:stone",
			prob = 254
		},
		{
			param2 = 0,
			name = "default:stone",
			prob = 254
		},
		{
			param2 = 0,
			name = "default:stone",
			prob = 254
		},
		{
			param2 = 0,
			name = "default:stone",
			prob = 254
		},
		{
			param2 = 0,
			name = "default:stone",
			prob = 254
		},
		{
			param2 = 0,
			name = "default:stone",
			prob = 254
		},
		{
			param2 = 0,
			name = "default:stone",
			prob = 254
		},
		{
			param2 = 0,
			name = "default:stone",
			prob = 254
		},
		{
			param2 = 0,
			name = "default:stone",
			prob = 254
		},
		{
			param2 = 0,
			name = "default:stone",
			prob = 254
		},
		{
			param2 = 0,
			name = "default:stone",
			prob = 254
		},
		{
			param2 = 0,
			name = "default:stone",
			prob = 254
		},
		{
			param2 = 0,
			name = "default:stone",
			prob = 254
		},
		{
			param2 = 0,
			name = "default:stone",
			prob = 254
		},
		{
			param2 = 0,
			name = "default:stone",
			prob = 254
		},
		{
			param2 = 0,
			name = "default:stone",
			prob = 254
		},
		{
			param2 = 0,
			name = "default:stone",
			prob = 254
		},
		{
			param2 = 0,
			name = "default:stone",
			prob = 254
		},
		{
			param2 = 0,
			name = "default:stone",
			prob = 254
		},
		{
			param2 = 0,
			name = "default:stone",
			prob = 254
		},
		{
			param2 = 0,
			name = "default:stone",
			prob = 254
		},
		{
			param2 = 0,
			name = "default:stone",
			prob = 254
		},
		{
			param2 = 0,
			name = "default:stone",
			prob = 254
		},
		{
			param2 = 0,
			name = "default:stone",
			prob = 254
		},
		{
			param2 = 0,
			name = "default:stone",
			prob = 254
		},
		{
			param2 = 0,
			name = "default:stone",
			prob = 254
		},
		{
			param2 = 0,
			name = "default:stone",
			prob = 254
		},
		{
			param2 = 0,
			name = "default:stone",
			prob = 254
		},
		{
			param2 = 0,
			name = "default:stone",
			prob = 254
		},
		{
			param2 = 0,
			name = "default:stone",
			prob = 254
		},
		{
			param2 = 0,
			name = "default:stone",
			prob = 254
		},
		{
			param2 = 0,
			name = "default:stone",
			prob = 254
		},
		{
			param2 = 0,
			name = "default:stone",
			prob = 254
		},
		{
			param2 = 0,
			name = "default:stone",
			prob = 254
		},
		{
			param2 = 0,
			name = "default:stone",
			prob = 254
		},
		{
			param2 = 0,
			name = "default:stone",
			prob = 254
		},
		{
			param2 = 0,
			name = "default:stone",
			prob = 254
		},
		{
			param2 = 0,
			name = "default:stone",
			prob = 254
		},
		{
			param2 = 0,
			name = "default:stone",
			prob = 254
		},
		{
			param2 = 0,
			name = "default:stone",
			prob = 254
		},
		{
			param2 = 2,
			name = "default:tree",
			prob = 254
		},
		{
			param2 = 0,
			name = "carts:rail",
			prob = 254
		},
		{
			param2 = 0,
			name = "air",
			prob = 254
		},
		{
			param2 = 0,
			name = "air",
			prob = 254
		},
		{
			param2 = 2,
			name = "default:tree",
			prob = 254
		},
		{
			param2 = 0,
			name = "air",
			prob = 254
		},
		{
			param2 = 0,
			name = "air",
			prob = 254
		},
		{
			param2 = 0,
			name = "air",
			prob = 254
		},
		{
			param2 = 1,
			name = "default:tree",
			prob = 254
		},
		{
			param2 = 0,
			name = "air",
			prob = 254
		},
		{
			param2 = 0,
			name = "air",
			prob = 254
		},
		{
			param2 = 0,
			name = "air",
			prob = 254
		},
		{
			param2 = 0,
			name = "air",
			prob = 254
		},
		{
			param2 = 0,
			name = "air",
			prob = 254
		},
		{
			param2 = 0,
			name = "default:stone",
			prob = 254
		},
		{
			param2 = 0,
			name = "default:stone",
			prob = 254
		},
		{
			param2 = 0,
			name = "default:stone",
			prob = 254
		},
		{
			param2 = 0,
			name = "default:stone",
			prob = 254
		},
		{
			param2 = 0,
			name = "default:stone",
			prob = 254
		},
		{
			param2 = 0,
			name = "default:stone",
			prob = 254
		},
		{
			param2 = 2,
			name = "default:tree",
			prob = 254
		},
		{
			param2 = 0,
			name = "air",
			prob = 254
		},
		{
			param2 = 0,
			name = "air",
			prob = 254
		},
		{
			param2 = 0,
			name = "air",
			prob = 254
		},
		{
			param2 = 2,
			name = "default:tree",
			prob = 254
		},
		{
			param2 = 0,
			name = "air",
			prob = 254
		},
		{
			param2 = 0,
			name = "air",
			prob = 254
		},
		{
			param2 = 0,
			name = "air",
			prob = 254
		},
		{
			param2 = 1,
			name = "default:tree",
			prob = 254
		},
		{
			param2 = 0,
			name = "air",
			prob = 254
		},
		{
			param2 = 0,
			name = "air",
			prob = 254
		},
		{
			param2 = 0,
			name = "air",
			prob = 254
		},
		{
			param2 = 0,
			name = "air",
			prob = 254
		},
		{
			param2 = 0,
			name = "air",
			prob = 254
		},
		{
			param2 = 0,
			name = "default:stone",
			prob = 254
		},
		{
			param2 = 0,
			name = "default:stone",
			prob = 254
		},
		{
			param2 = 0,
			name = "default:stone",
			prob = 254
		},
		{
			param2 = 0,
			name = "default:stone",
			prob = 254
		},
		{
			param2 = 0,
			name = "default:stone",
			prob = 254
		},
		{
			param2 = 0,
			name = "default:stone",
			prob = 254
		},
		{
			param2 = 2,
			name = "default:tree",
			prob = 254
		},
		{
			param2 = 0,
			name = "default:wood",
			prob = 254
		},
		{
			param2 = 0,
			name = "default:wood",
			prob = 254
		},
		{
			param2 = 0,
			name = "default:wood",
			prob = 254
		},
		{
			param2 = 2,
			name = "default:tree",
			prob = 254
		},
		{
			param2 = 0,
			name = "default:wood",
			prob = 254
		},
		{
			param2 = 0,
			name = "default:wood",
			prob = 254
		},
		{
			param2 = 0,
			name = "default:wood",
			prob = 254
		},
		{
			param2 = 2,
			name = "default:tree",
			prob = 254
		},
		{
			param2 = 0,
			name = "default:wood",
			prob = 254
		},
		{
			param2 = 0,
			name = "default:wood",
			prob = 254
		},
		{
			param2 = 0,
			name = "default:wood",
			prob = 254
		},
		{
			param2 = 0,
			name = "default:wood",
			prob = 254
		},
		{
			param2 = 0,
			name = "default:wood",
			prob = 254
		},
		{
			param2 = 0,
			name = "default:wood",
			prob = 254
		},
		{
			param2 = 0,
			name = "default:stone",
			prob = 254
		},
		{
			param2 = 0,
			name = "default:stone",
			prob = 254
		},
		{
			param2 = 0,
			name = "default:stone",
			prob = 254
		},
		{
			param2 = 0,
			name = "default:stone",
			prob = 254
		},
		{
			param2 = 0,
			name = "default:stone",
			prob = 254
		},
		{
			param2 = 0,
			name = "air",
			prob = 254
		},
		{
			param2 = 0,
			name = "air",
			prob = 254
		},
		{
			param2 = 0,
			name = "air",
			prob = 254
		},
		{
			param2 = 0,
			name = "air",
			prob = 254
		},
		{
			param2 = 0,
			name = "air",
			prob = 254
		},
		{
			param2 = 0,
			name = "air",
			prob = 254
		},
		{
			param2 = 0,
			name = "air",
			prob = 254
		},
		{
			param2 = 0,
			name = "air",
			prob = 254
		},
		{
			param2 = 0,
			name = "air",
			prob = 254
		},
		{
			param2 = 0,
			name = "air",
			prob = 254
		},
		{
			param2 = 0,
			name = "air",
			prob = 254
		},
		{
			param2 = 0,
			name = "air",
			prob = 254
		},
		{
			param2 = 0,
			name = "air",
			prob = 254
		},
		{
			param2 = 0,
			name = "air",
			prob = 254
		},
		{
			param2 = 0,
			name = "air",
			prob = 254
		},
		{
			param2 = 0,
			name = "air",
			prob = 254
		},
		{
			param2 = 0,
			name = "carts:rail",
			prob = 254
		},
		{
			param2 = 0,
			name = "air",
			prob = 254
		},
		{
			param2 = 0,
			name = "default:stone",
			prob = 254
		},
		{
			param2 = 0,
			name = "default:stone",
			prob = 254
		},
		{
			param2 = 3,
			name = "default:torch_wall",
			prob = 254
		},
		{
			param2 = 0,
			name = "air",
			prob = 254
		},
		{
			param2 = 0,
			name = "air",
			prob = 254
		},
		{
			param2 = 0,
			name = "air",
			prob = 254
		},
		{
			param2 = 0,
			name = "air",
			prob = 254
		},
		{
			param2 = 0,
			name = "air",
			prob = 254
		},
		{
			param2 = 0,
			name = "air",
			prob = 254
		},
		{
			param2 = 0,
			name = "air",
			prob = 254
		},
		{
			param2 = 0,
			name = "air",
			prob = 254
		},
		{
			param2 = 0,
			name = "air",
			prob = 254
		},
		{
			param2 = 0,
			name = "air",
			prob = 254
		},
		{
			param2 = 0,
			name = "air",
			prob = 254
		},
		{
			param2 = 0,
			name = "air",
			prob = 254
		},
		{
			param2 = 0,
			name = "air",
			prob = 254
		},
		{
			param2 = 0,
			name = "air",
			prob = 254
		},
		{
			param2 = 0,
			name = "air",
			prob = 254
		},
		{
			param2 = 0,
			name = "air",
			prob = 254
		},
		{
			param2 = 0,
			name = "air",
			prob = 254
		},
		{
			param2 = 0,
			name = "default:stone_with_iron",
			prob = 254
		},
		{
			param2 = 0,
			name = "default:stone",
			prob = 254
		},
		{
			param2 = 0,
			name = "air",
			prob = 254
		},
		{
			param2 = 0,
			name = "air",
			prob = 254
		},
		{
			param2 = 0,
			name = "air",
			prob = 254
		},
		{
			param2 = 0,
			name = "air",
			prob = 254
		},
		{
			param2 = 0,
			name = "air",
			prob = 254
		},
		{
			param2 = 0,
			name = "air",
			prob = 254
		},
		{
			param2 = 0,
			name = "air",
			prob = 254
		},
		{
			param2 = 0,
			name = "air",
			prob = 254
		},
		{
			param2 = 0,
			name = "air",
			prob = 254
		},
		{
			param2 = 0,
			name = "air",
			prob = 254
		},
		{
			param2 = 0,
			name = "air",
			prob = 254
		},
		{
			param2 = 0,
			name = "air",
			prob = 254
		},
		{
			param2 = 0,
			name = "air",
			prob = 254
		},
		{
			param2 = 0,
			name = "air",
			prob = 254
		},
		{
			param2 = 0,
			name = "air",
			prob = 254
		},
		{
			param2 = 0,
			name = "air",
			prob = 254
		},
		{
			param2 = 0,
			name = "air",
			prob = 254
		},
		{
			param2 = 0,
			name = "air",
			prob = 254
		},
		{
			param2 = 0,
			name = "default:stone_with_iron",
			prob = 254
		},
		{
			param2 = 0,
			name = "default:stone",
			prob = 254
		},
		{
			param2 = 9,
			name = "default:tree",
			prob = 254
		},
		{
			param2 = 0,
			name = "air",
			prob = 254
		},
		{
			param2 = 0,
			name = "air",
			prob = 254
		},
		{
			param2 = 0,
			name = "air",
			prob = 254
		},
		{
			param2 = 7,
			name = "default:tree",
			prob = 254
		},
		{
			param2 = 0,
			name = "air",
			prob = 254
		},
		{
			param2 = 0,
			name = "air",
			prob = 254
		},
		{
			param2 = 0,
			name = "mapgen:stalagtite1",
			prob = 254
		},
		{
			param2 = 0,
			name = "air",
			prob = 254
		},
		{
			param2 = 0,
			name = "air",
			prob = 254
		},
		{
			param2 = 0,
			name = "air",
			prob = 254
		},
		{
			param2 = 0,
			name = "mapgen:stalagtite2",
			prob = 254
		},
		{
			param2 = 0,
			name = "air",
			prob = 254
		},
		{
			param2 = 7,
			name = "default:tree",
			prob = 254
		},
		{
			param2 = 0,
			name = "air",
			prob = 254
		},
		{
			param2 = 0,
			name = "air",
			prob = 254
		},
		{
			param2 = 0,
			name = "air",
			prob = 254
		},
		{
			param2 = 9,
			name = "default:tree",
			prob = 254
		},
		{
			param2 = 0,
			name = "default:stone",
			prob = 254
		},
		{
			param2 = 0,
			name = "default:stone",
			prob = 254
		},
		{
			param2 = 0,
			name = "default:stone",
			prob = 254
		},
		{
			param2 = 0,
			name = "default:stone",
			prob = 254
		},
		{
			param2 = 0,
			name = "default:stone",
			prob = 254
		},
		{
			param2 = 0,
			name = "default:stone",
			prob = 254
		},
		{
			param2 = 0,
			name = "default:stone",
			prob = 254
		},
		{
			param2 = 0,
			name = "default:stone",
			prob = 254
		},
		{
			param2 = 0,
			name = "default:stone",
			prob = 254
		},
		{
			param2 = 0,
			name = "default:stone",
			prob = 254
		},
		{
			param2 = 0,
			name = "default:stone",
			prob = 254
		},
		{
			param2 = 0,
			name = "default:stone",
			prob = 254
		},
		{
			param2 = 0,
			name = "default:stone",
			prob = 254
		},
		{
			param2 = 0,
			name = "default:stone",
			prob = 254
		},
		{
			param2 = 0,
			name = "default:stone",
			prob = 254
		},
		{
			param2 = 0,
			name = "default:stone",
			prob = 254
		},
		{
			param2 = 0,
			name = "default:stone",
			prob = 254
		},
		{
			param2 = 0,
			name = "default:stone",
			prob = 254
		},
		{
			param2 = 0,
			name = "default:stone",
			prob = 254
		},
		{
			param2 = 0,
			name = "default:stone",
			prob = 254
		},
		{
			param2 = 0,
			name = "default:stone",
			prob = 254
		},
		{
			param2 = 0,
			name = "default:stone",
			prob = 254
		},
		{
			param2 = 0,
			name = "default:stone",
			prob = 254
		},
		{
			param2 = 0,
			name = "default:stone",
			prob = 254
		},
		{
			param2 = 0,
			name = "default:stone",
			prob = 254
		},
		{
			param2 = 0,
			name = "default:stone",
			prob = 254
		},
		{
			param2 = 0,
			name = "default:stone",
			prob = 254
		},
		{
			param2 = 0,
			name = "default:stone",
			prob = 254
		},
		{
			param2 = 0,
			name = "default:stone",
			prob = 254
		},
		{
			param2 = 0,
			name = "default:stone",
			prob = 254
		},
		{
			param2 = 0,
			name = "default:stone",
			prob = 254
		},
		{
			param2 = 0,
			name = "default:stone",
			prob = 254
		},
		{
			param2 = 0,
			name = "default:stone",
			prob = 254
		},
		{
			param2 = 0,
			name = "default:stone",
			prob = 254
		},
		{
			param2 = 0,
			name = "default:stone",
			prob = 254
		},
		{
			param2 = 0,
			name = "default:stone",
			prob = 254
		},
		{
			param2 = 0,
			name = "default:stone",
			prob = 254
		},
		{
			param2 = 0,
			name = "default:stone",
			prob = 254
		},
		{
			param2 = 0,
			name = "default:stone",
			prob = 254
		},
		{
			param2 = 0,
			name = "default:stone",
			prob = 254
		},
		{
			param2 = 0,
			name = "default:stone",
			prob = 254
		},
		{
			param2 = 0,
			name = "default:stone",
			prob = 254
		},
		{
			param2 = 0,
			name = "air",
			prob = 254
		},
		{
			param2 = 0,
			name = "carts:rail",
			prob = 254
		},
		{
			param2 = 0,
			name = "air",
			prob = 254
		},
		{
			param2 = 0,
			name = "air",
			prob = 254
		},
		{
			param2 = 5,
			name = "default:ladder_wood",
			prob = 254
		},
		{
			param2 = 0,
			name = "air",
			prob = 254
		},
		{
			param2 = 0,
			name = "air",
			prob = 254
		},
		{
			param2 = 0,
			name = "air",
			prob = 254
		},
		{
			param2 = 2,
			name = "decoblocks:old_skeleton",
			prob = 254
		},
		{
			param2 = 0,
			name = "air",
			prob = 254
		},
		{
			param2 = 0,
			name = "air",
			prob = 254
		},
		{
			param2 = 0,
			name = "air",
			prob = 254
		},
		{
			param2 = 0,
			name = "air",
			prob = 254
		},
		{
			param2 = 0,
			name = "air",
			prob = 254
		},
		{
			param2 = 0,
			name = "default:stone",
			prob = 254
		},
		{
			param2 = 0,
			name = "default:stone",
			prob = 254
		},
		{
			param2 = 0,
			name = "default:stone",
			prob = 254
		},
		{
			param2 = 0,
			name = "default:stone",
			prob = 254
		},
		{
			param2 = 0,
			name = "default:stone",
			prob = 254
		},
		{
			param2 = 0,
			name = "default:stone",
			prob = 254
		},
		{
			param2 = 5,
			name = "default:torch_wall",
			prob = 254
		},
		{
			param2 = 0,
			name = "air",
			prob = 254
		},
		{
			param2 = 0,
			name = "air",
			prob = 254
		},
		{
			param2 = 0,
			name = "air",
			prob = 254
		},
		{
			param2 = 5,
			name = "default:ladder_wood",
			prob = 254
		},
		{
			param2 = 0,
			name = "air",
			prob = 254
		},
		{
			param2 = 0,
			name = "air",
			prob = 254
		},
		{
			param2 = 0,
			name = "air",
			prob = 254
		},
		{
			param2 = 5,
			name = "default:torch_wall",
			prob = 254
		},
		{
			param2 = 0,
			name = "air",
			prob = 254
		},
		{
			param2 = 0,
			name = "air",
			prob = 254
		},
		{
			param2 = 0,
			name = "air",
			prob = 254
		},
		{
			param2 = 0,
			name = "air",
			prob = 254
		},
		{
			param2 = 0,
			name = "air",
			prob = 254
		},
		{
			param2 = 0,
			name = "default:stone",
			prob = 254
		},
		{
			param2 = 0,
			name = "default:stone",
			prob = 254
		},
		{
			param2 = 0,
			name = "default:stone",
			prob = 254
		},
		{
			param2 = 0,
			name = "default:stone",
			prob = 254
		},
		{
			param2 = 0,
			name = "default:stone",
			prob = 254
		},
		{
			param2 = 0,
			name = "default:stone",
			prob = 254
		},
		{
			param2 = 0,
			name = "air",
			prob = 254
		},
		{
			param2 = 0,
			name = "air",
			prob = 254
		},
		{
			param2 = 0,
			name = "air",
			prob = 254
		},
		{
			param2 = 0,
			name = "air",
			prob = 254
		},
		{
			param2 = 5,
			name = "default:ladder_wood",
			prob = 254
		},
		{
			param2 = 0,
			name = "air",
			prob = 254
		},
		{
			param2 = 0,
			name = "air",
			prob = 254
		},
		{
			param2 = 0,
			name = "air",
			prob = 254
		},
		{
			param2 = 0,
			name = "air",
			prob = 254
		},
		{
			param2 = 0,
			name = "air",
			prob = 254
		},
		{
			param2 = 0,
			name = "air",
			prob = 254
		},
		{
			param2 = 0,
			name = "default:wood",
			prob = 254
		},
		{
			param2 = 0,
			name = "default:wood",
			prob = 254
		},
		{
			param2 = 0,
			name = "default:wood",
			prob = 254
		},
		{
			param2 = 0,
			name = "default:wood",
			prob = 254
		},
		{
			param2 = 0,
			name = "default:stone",
			prob = 254
		},
		{
			param2 = 0,
			name = "default:stone",
			prob = 254
		},
		{
			param2 = 0,
			name = "default:stone",
			prob = 254
		},
		{
			param2 = 0,
			name = "default:stone",
			prob = 254
		},
		{
			param2 = 0,
			name = "default:stone",
			prob = 254
		},
		{
			param2 = 0,
			name = "air",
			prob = 254
		},
		{
			param2 = 0,
			name = "air",
			prob = 254
		},
		{
			param2 = 0,
			name = "air",
			prob = 254
		},
		{
			param2 = 0,
			name = "air",
			prob = 254
		},
		{
			param2 = 0,
			name = "air",
			prob = 254
		},
		{
			param2 = 0,
			name = "air",
			prob = 254
		},
		{
			param2 = 0,
			name = "air",
			prob = 254
		},
		{
			param2 = 0,
			name = "air",
			prob = 254
		},
		{
			param2 = 0,
			name = "air",
			prob = 254
		},
		{
			param2 = 0,
			name = "air",
			prob = 254
		},
		{
			param2 = 0,
			name = "air",
			prob = 254
		},
		{
			param2 = 0,
			name = "air",
			prob = 254
		},
		{
			param2 = 0,
			name = "air",
			prob = 254
		},
		{
			param2 = 0,
			name = "air",
			prob = 254
		},
		{
			param2 = 0,
			name = "air",
			prob = 254
		},
		{
			param2 = 0,
			name = "air",
			prob = 254
		},
		{
			param2 = 0,
			name = "carts:rail",
			prob = 254
		},
		{
			param2 = 0,
			name = "air",
			prob = 254
		},
		{
			param2 = 0,
			name = "default:stone_with_iron",
			prob = 254
		},
		{
			param2 = 0,
			name = "default:stone",
			prob = 254
		},
		{
			param2 = 0,
			name = "air",
			prob = 254
		},
		{
			param2 = 0,
			name = "air",
			prob = 254
		},
		{
			param2 = 0,
			name = "air",
			prob = 254
		},
		{
			param2 = 0,
			name = "air",
			prob = 254
		},
		{
			param2 = 0,
			name = "air",
			prob = 254
		},
		{
			param2 = 0,
			name = "air",
			prob = 254
		},
		{
			param2 = 0,
			name = "air",
			prob = 254
		},
		{
			param2 = 0,
			name = "air",
			prob = 254
		},
		{
			param2 = 0,
			name = "air",
			prob = 254
		},
		{
			param2 = 0,
			name = "air",
			prob = 254
		},
		{
			param2 = 0,
			name = "air",
			prob = 254
		},
		{
			param2 = 0,
			name = "air",
			prob = 254
		},
		{
			param2 = 0,
			name = "air",
			prob = 254
		},
		{
			param2 = 0,
			name = "air",
			prob = 254
		},
		{
			param2 = 0,
			name = "air",
			prob = 254
		},
		{
			param2 = 0,
			name = "air",
			prob = 254
		},
		{
			param2 = 0,
			name = "air",
			prob = 254
		},
		{
			param2 = 0,
			name = "air",
			prob = 254
		},
		{
			param2 = 0,
			name = "default:stone_with_iron",
			prob = 254
		},
		{
			param2 = 0,
			name = "default:stone_with_iron",
			prob = 254
		},
		{
			param2 = 0,
			name = "air",
			prob = 254
		},
		{
			param2 = 0,
			name = "air",
			prob = 254
		},
		{
			param2 = 0,
			name = "air",
			prob = 254
		},
		{
			param2 = 0,
			name = "air",
			prob = 254
		},
		{
			param2 = 0,
			name = "air",
			prob = 254
		},
		{
			param2 = 0,
			name = "air",
			prob = 254
		},
		{
			param2 = 0,
			name = "air",
			prob = 254
		},
		{
			param2 = 0,
			name = "air",
			prob = 254
		},
		{
			param2 = 0,
			name = "air",
			prob = 254
		},
		{
			param2 = 0,
			name = "air",
			prob = 254
		},
		{
			param2 = 0,
			name = "air",
			prob = 254
		},
		{
			param2 = 0,
			name = "air",
			prob = 254
		},
		{
			param2 = 0,
			name = "air",
			prob = 254
		},
		{
			param2 = 0,
			name = "air",
			prob = 254
		},
		{
			param2 = 0,
			name = "air",
			prob = 254
		},
		{
			param2 = 0,
			name = "air",
			prob = 254
		},
		{
			param2 = 0,
			name = "air",
			prob = 254
		},
		{
			param2 = 0,
			name = "air",
			prob = 254
		},
		{
			param2 = 0,
			name = "default:stone",
			prob = 254
		},
		{
			param2 = 0,
			name = "default:stone",
			prob = 254
		},
		{
			param2 = 9,
			name = "default:tree",
			prob = 254
		},
		{
			param2 = 0,
			name = "air",
			prob = 254
		},
		{
			param2 = 0,
			name = "air",
			prob = 254
		},
		{
			param2 = 0,
			name = "mapgen:stalagtite2",
			prob = 254
		},
		{
			param2 = 7,
			name = "default:tree",
			prob = 254
		},
		{
			param2 = 0,
			name = "air",
			prob = 254
		},
		{
			param2 = 0,
			name = "air",
			prob = 254
		},
		{
			param2 = 0,
			name = "air",
			prob = 254
		},
		{
			param2 = 0,
			name = "air",
			prob = 254
		},
		{
			param2 = 0,
			name = "air",
			prob = 254
		},
		{
			param2 = 0,
			name = "air",
			prob = 254
		},
		{
			param2 = 0,
			name = "air",
			prob = 254
		},
		{
			param2 = 0,
			name = "air",
			prob = 254
		},
		{
			param2 = 7,
			name = "default:tree",
			prob = 254
		},
		{
			param2 = 0,
			name = "air",
			prob = 254
		},
		{
			param2 = 0,
			name = "air",
			prob = 254
		},
		{
			param2 = 0,
			name = "air",
			prob = 254
		},
		{
			param2 = 9,
			name = "default:tree",
			prob = 254
		},
		{
			param2 = 0,
			name = "default:stone",
			prob = 254
		},
		{
			param2 = 0,
			name = "default:stone",
			prob = 254
		},
		{
			param2 = 0,
			name = "default:stone",
			prob = 254
		},
		{
			param2 = 0,
			name = "default:stone",
			prob = 254
		},
		{
			param2 = 0,
			name = "default:stone",
			prob = 254
		},
		{
			param2 = 0,
			name = "default:stone",
			prob = 254
		},
		{
			param2 = 0,
			name = "default:stone",
			prob = 254
		},
		{
			param2 = 0,
			name = "default:stone",
			prob = 254
		},
		{
			param2 = 0,
			name = "default:stone",
			prob = 254
		},
		{
			param2 = 0,
			name = "default:stone",
			prob = 254
		},
		{
			param2 = 0,
			name = "default:stone",
			prob = 254
		},
		{
			param2 = 0,
			name = "default:stone",
			prob = 254
		},
		{
			param2 = 0,
			name = "default:stone",
			prob = 254
		},
		{
			param2 = 0,
			name = "default:stone",
			prob = 254
		},
		{
			param2 = 0,
			name = "default:stone",
			prob = 254
		},
		{
			param2 = 0,
			name = "default:stone",
			prob = 254
		},
		{
			param2 = 0,
			name = "default:stone",
			prob = 254
		},
		{
			param2 = 0,
			name = "default:stone",
			prob = 254
		},
		{
			param2 = 0,
			name = "default:stone",
			prob = 254
		},
