{
	yslice_prob = {
		{
			prob = 254,
			ypos = 0
		},
		{
			prob = 254,
			ypos = 1
		},
		{
			prob = 254,
			ypos = 2
		}
	},
	data = {
		{
			param2 = 0,
			name = "decoblocks:bone_pillar",
			prob = 254
		},
		{
			param2 = 0,
			name = "default:stone_with_coal",
			prob = 254
		},
		{
			param2 = 0,
			name = "default:stone",
			prob = 254
		},
		{
			param2 = 0,
			name = "decoblocks:bone_pillar",
			prob = 254
		},
		{
			param2 = 0,
			name = "decoblocks:bone_pillar",
			prob = 254
		},
		{
			param2 = 0,
			name = "default:stone",
			prob = 254
		},
		{
			param2 = 0,
			name = "default:cobble",
			prob = 254
		},
		{
			param2 = 0,
			name = "decoblocks:bone_pillar",
			prob = 254
		},
		{
			param2 = 0,
			name = "default:stone",
			prob = 254
		},
		{
			param2 = 12,
			name = "decoblocks:bone_pillar",
			prob = 254
		},
		{
			param2 = 12,
			name = "decoblocks:bone_pillar",
			prob = 254
		},
		{
			param2 = 0,
			name = "default:stone_with_coal",
			prob = 254
		},
		{
			param2 = 0,
			name = "default:cobble",
			prob = 254
		},
		{
			param2 = 0,
			name = "default:stone",
			prob = 254
		},
		{
			param2 = 0,
			name = "default:cobble",
			prob = 254
		},
		{
			param2 = 0,
			name = "default:stone",
			prob = 254
		},
		{
			param2 = 0,
			name = "default:stone",
			prob = 254
		},
		{
			param2 = 0,
			name = "default:stone",
			prob = 254
		},
		{
			param2 = 0,
			name = "default:stone",
			prob = 254
		},
		{
			param2 = 0,
			name = "default:stone",
			prob = 254
		},
		{
			param2 = 0,
			name = "default:stone",
			prob = 254
		},
		{
			param2 = 0,
			name = "default:stone",
			prob = 254
		},
		{
			param2 = 0,
			name = "default:stone",
			prob = 254
		},
		{
			param2 = 0,
			name = "default:stone",
			prob = 254
		},
		{
			param2 = 0,
			name = "decoblocks:bone_pillar",
			prob = 254
		},
		{
			param2 = 0,
			name = "default:cobble",
			prob = 254
		},
		{
			param2 = 0,
			name = "default:stone_with_coal",
			prob = 254
		},
		{
			param2 = 0,
			name = "decoblocks:bone_pillar",
			prob = 254
		},
		{
			param2 = 0,
			name = "decoblocks:bone_pillar",
			prob = 254
		},
		{
			param2 = 0,
			name = "default:stone",
			prob = 254
		},
		{
			param2 = 0,
			name = "default:cobble",
			prob = 254
		},
		{
			param2 = 0,
			name = "decoblocks:bone_pillar",
			prob = 254
		},
		{
			param2 = 0,
			name = "default:stone",
			prob = 254
		},
		{
			param2 = 18,
			name = "decoblocks:bone_pillar",
			prob = 254
		},
		{
			param2 = 18,
			name = "decoblocks:bone_pillar",
			prob = 254
		},
		{
			param2 = 0,
			name = "default:stone",
			prob = 254
		},
		{
			param2 = 0,
			name = "default:stone_with_coal",
			prob = 254
		},
		{
			param2 = 0,
			name = "default:stone",
			prob = 254
		},
		{
			param2 = 0,
			name = "default:stone",
			prob = 254
		},
		{
			param2 = 0,
			name = "default:stone_with_coal",
			prob = 254
		},
		{
			param2 = 0,
			name = "default:stone",
			prob = 254
		},
		{
			param2 = 0,
			name = "default:stone",
			prob = 254
		},
		{
			param2 = 0,
			name = "default:stone",
			prob = 254
		},
		{
			param2 = 0,
			name = "default:stone",
			prob = 254
		},
		{
			param2 = 0,
			name = "default:stone",
			prob = 254
		},
		{
			param2 = 0,
			name = "default:cobble",
			prob = 254
		},
		{
			param2 = 0,
			name = "default:stone",
			prob = 254
		},
		{
			param2 = 0,
			name = "default:stone",
			prob = 254
		},
		{
			param2 = 1,
			name = "decoblocks:bone_pillar",
			prob = 254
		},
		{
			param2 = 0,
			name = "default:stone_with_coal",
			prob = 254
		},
		{
			param2 = 0,
			name = "default:cobble",
			prob = 254
		},
		{
			param2 = 1,
			name = "decoblocks:bone_pillar",
			prob = 254
		},
		{
			param2 = 1,
			name = "decoblocks:bone_pillar",
			prob = 254
		},
		{
			param2 = 0,
			name = "default:stone",
			prob = 254
		},
		{
			param2 = 0,
			name = "default:stone",
			prob = 254
		},
		{
			param2 = 1,
			name = "decoblocks:bone_pillar",
			prob = 254
		},
		{
			param2 = 0,
			name = "default:stone",
			prob = 254
		},
		{
			param2 = 18,
			name = "decoblocks:bone_pillar",
			prob = 254
		},
		{
			param2 = 12,
			name = "decoblocks:bone_pillar",
			prob = 254
		},
		{
			param2 = 0,
			name = "default:stone_with_coal",
			prob = 254
		},
		{
			param2 = 0,
			name = "default:stone",
			prob = 254
		},
		{
			param2 = 0,
			name = "default:cobble",
			prob = 254
		},
		{
			param2 = 0,
			name = "default:stone",
			prob = 254
		},
		{
			param2 = 0,
			name = "default:stone_with_coal",
			prob = 254
		},
		{
			param2 = 0,
			name = "default:stone",
			prob = 254
		},
		{
			param2 = 0,
			name = "default:stone",
			prob = 254
		},
		{
			param2 = 0,
			name = "default:cobble",
			prob = 254
		},
		{
			param2 = 0,
			name = "default:stone",
			prob = 254
		},
		{
			param2 = 0,
			name = "default:stone",
			prob = 254
		},
		{
			param2 = 0,
			name = "default:stone",
			prob = 254
		},
		{
			param2 = 0,
			name = "default:cobble",
			prob = 254
		},
		{
			param2 = 0,
			name = "default:stone",
			prob = 254
		},
		{
			param2 = 2,
			name = "decoblocks:bone_pillar",
			prob = 254
		},
		{
			param2 = 0,
			name = "default:stone_with_coal",
			prob = 254
		},
		{
			param2 = 0,
			name = "default:stone",
			prob = 254
		},
		{
			param2 = 3,
			name = "decoblocks:bone_pillar",
			prob = 254
		},
		{
			param2 = 2,
			name = "decoblocks:bone_pillar",
			prob = 254
		},
		{
			param2 = 0,
			name = "default:stone",
			prob = 254
		},
		{
			param2 = 0,
			name = "default:cobble",
			prob = 254
		},
		{
			param2 = 3,
			name = "decoblocks:bone_pillar",
			prob = 254
		},
		{
			param2 = 0,
			name = "default:stone_with_coal",
			prob = 254
		},
		{
			param2 = 18,
			name = "decoblocks:bone_pillar",
			prob = 254
		},
		{
			param2 = 18,
			name = "decoblocks:bone_pillar",
			prob = 254
		},
		{
			param2 = 0,
			name = "default:cobble",
			prob = 254
		}
	},
	size = {
		y = 3,
		x = 4,
		z = 7
	}
}