{
	yslice_prob = {
		{
			prob = 254,
			ypos = 0
		},
		{
			prob = 254,
			ypos = 1
		},
		{
			prob = 254,
			ypos = 2
		},
		{
			prob = 254,
			ypos = 3
		},
		{
			prob = 254,
			ypos = 4
		},
		{
			prob = 254,
			ypos = 5
		},
		{
			prob = 254,
			ypos = 6
		}
	},
	data = {
		{
			param2 = 0,
			name = "air",
			prob = 254
		},
		{
			param2 = 0,
			name = "air",
			prob = 254
		},
		{
			param2 = 0,
			name = "air",
			prob = 254
		},
		{
			param2 = 0,
			name = "air",
			prob = 254
		},
		{
			param2 = 0,
			name = "air",
			prob = 254
		},
		{
			param2 = 0,
			name = "air",
			prob = 254
		},
		{
			param2 = 0,
			name = "air",
			prob = 254
		},
		{
			param2 = 0,
			name = "air",
			prob = 254
		},
		{
			param2 = 0,
			name = "air",
			prob = 254
		},
		{
			param2 = 0,
			name = "air",
			prob = 254
		},
		{
			param2 = 0,
			name = "air",
			prob = 254
		},
		{
			param2 = 0,
			name = "air",
			prob = 254
		},
		{
			param2 = 0,
			name = "air",
			prob = 254
		},
		{
			param2 = 0,
			name = "air",
			prob = 254
		},
		{
			param2 = 0,
			name = "air",
			prob = 254
		},
		{
			param2 = 0,
			name = "air",
			prob = 254
		},
		{
			param2 = 0,
			name = "air",
			prob = 254
		},
		{
			param2 = 1,
			name = "default:leaves",
			prob = 254
		},
		{
			param2 = 1,
			name = "default:leaves",
			prob = 254
		},
		{
			param2 = 0,
			name = "air",
			prob = 254
		},
		{
			param2 = 0,
			name = "air",
			prob = 254
		},
		{
			param2 = 1,
			name = "default:leaves",
			prob = 254
		},
		{
			param2 = 1,
			name = "default:leaves",
			prob = 254
		},
		{
			param2 = 1,
			name = "default:leaves",
			prob = 254
		},
		{
			param2 = 0,
			name = "air",
			prob = 254
		},
		{
			param2 = 0,
			name = "air",
			prob = 254
		},
		{
			param2 = 1,
			name = "default:leaves",
			prob = 254
		},
		{
			param2 = 1,
			name = "default:leaves",
			prob = 254
		},
		{
			param2 = 1,
			name = "default:leaves",
			prob = 254
		},
		{
			param2 = 0,
			name = "air",
			prob = 254
		},
		{
			param2 = 0,
			name = "air",
			prob = 254
		},
		{
			param2 = 0,
			name = "air",
			prob = 254
		},
		{
			param2 = 0,
			name = "air",
			prob = 254
		},
		{
			param2 = 0,
			name = "air",
			prob = 254
		},
		{
			param2 = 0,
			name = "air",
			prob = 254
		},
		{
			param2 = 0,
			name = "air",
			prob = 254
		},
		{
			param2 = 0,
			name = "air",
			prob = 254
		},
		{
			param2 = 0,
			name = "air",
			prob = 254
		},
		{
			param2 = 0,
			name = "air",
			prob = 254
		},
		{
			param2 = 0,
			name = "air",
			prob = 254
		},
		{
			param2 = 0,
			name = "air",
			prob = 254
		},
		{
			param2 = 0,
			name = "air",
			prob = 254
		},
		{
			param2 = 0,
			name = "air",
			prob = 254
		},
		{
			param2 = 0,
			name = "air",
			prob = 254
		},
		{
			param2 = 0,
			name = "air",
			prob = 254
		},
		{
			param2 = 0,
			name = "air",
			prob = 254
		},
		{
			param2 = 0,
			name = "air",
			prob = 254
		},
		{
			param2 = 0,
			name = "air",
			prob = 254
		},
		{
			param2 = 0,
			name = "air",
			prob = 254
		},
		{
			param2 = 0,
			name = "air",
			prob = 254
		},
		{
			param2 = 0,
			name = "air",
			prob = 254
		},
		{
			param2 = 1,
			name = "default:leaves",
			prob = 254
		},
		{
			param2 = 1,
			name = "default:leaves",
			prob = 254
		},
		{
			param2 = 1,
			name = "default:leaves",
			prob = 254
		},
		{
			param2 = 0,
			name = "air",
			prob = 254
		},
		{
			param2 = 1,
			name = "default:leaves",
			prob = 254
		},
		{
			param2 = 1,
			name = "default:leaves",
			prob = 254
		},
		{
			param2 = 1,
			name = "default:leaves",
			prob = 254
		},
		{
			param2 = 1,
			name = "default:leaves",
			prob = 254
		},
		{
			param2 = 1,
			name = "default:leaves",
			prob = 254
		},
		{
			param2 = 0,
			name = "air",
			prob = 254
		},
		{
			param2 = 1,
			name = "default:leaves",
			prob = 254
		},
		{
			param2 = 1,
			name = "default:leaves",
			prob = 254
		},
		{
			param2 = 1,
			name = "default:leaves",
			prob = 254
		},
		{
			param2 = 1,
			name = "default:leaves",
			prob = 254
		},
		{
			param2 = 0,
			name = "air",
			prob = 254
		},
		{
			param2 = 1,
			name = "default:leaves",
			prob = 254
		},
		{
			param2 = 1,
			name = "default:leaves",
			prob = 254
		},
		{
			param2 = 1,
			name = "default:leaves",
			prob = 254
		},
		{
			param2 = 0,
			name = "air",
			prob = 254
		},
		{
			param2 = 0,
			name = "air",
			prob = 254
		},
		{
			param2 = 0,
			name = "air",
			prob = 254
		},
		{
			param2 = 22,
			name = "default:tree",
			prob = 254
		},
		{
			param2 = 0,
			name = "air",
			prob = 254
		},
		{
			param2 = 0,
			name = "air",
			prob = 254
		},
		{
			param2 = 0,
			name = "air",
			prob = 254
		},
		{
			param2 = 0,
			name = "air",
			prob = 254
		},
		{
			param2 = 1,
			name = "default:tree",
			prob = 254
		},
		{
			param2 = 0,
			name = "air",
			prob = 254
		},
		{
			param2 = 0,
			name = "air",
			prob = 254
		},
		{
			param2 = 0,
			name = "air",
			prob = 254
		},
		{
			param2 = 0,
			name = "air",
			prob = 254
		},
		{
			param2 = 1,
			name = "default:tree",
			prob = 254
		},
		{
			param2 = 0,
			name = "air",
			prob = 254
		},
		{
			param2 = 0,
			name = "air",
			prob = 254
		},
		{
			param2 = 1,
			name = "default:leaves",
			prob = 254
		},
		{
			param2 = 1,
			name = "default:leaves",
			prob = 254
		},
		{
			param2 = 1,
			name = "default:tree",
			prob = 254
		},
		{
			param2 = 1,
			name = "default:leaves",
			prob = 254
		},
		{
			param2 = 1,
			name = "default:leaves",
			prob = 254
		},
		{
			param2 = 1,
			name = "default:leaves",
			prob = 254
		},
		{
			param2 = 1,
			name = "default:leaves",
			prob = 254
		},
		{
			param2 = 1,
			name = "default:tree",
			prob = 254
		},
		{
			param2 = 1,
			name = "default:leaves",
			prob = 254
		},
		{
			param2 = 1,
			name = "default:leaves",
			prob = 254
		},
		{
			param2 = 1,
			name = "default:leaves",
			prob = 254
		},
		{
			param2 = 1,
			name = "default:leaves",
			prob = 254
		},
		{
			param2 = 1,
			name = "default:tree",
			prob = 254
		},
		{
			param2 = 1,
			name = "default:leaves",
			prob = 254
		},
		{
			param2 = 1,
			name = "default:leaves",
			prob = 254
		},
		{
			param2 = 0,
			name = "air",
			prob = 254
		},
		{
			param2 = 1,
			name = "default:leaves",
			prob = 254
		},
		{
			param2 = 1,
			name = "default:leaves",
			prob = 254
		},
		{
			param2 = 1,
			name = "default:leaves",
			prob = 254
		},
		{
			param2 = 0,
			name = "air",
			prob = 254
		},
		{
			param2 = 0,
			name = "air",
			prob = 254
		},
		{
			param2 = 0,
			name = "air",
			prob = 254
		},
		{
			param2 = 0,
			name = "air",
			prob = 254
		},
		{
			param2 = 0,
			name = "air",
			prob = 254
		},
		{
			param2 = 0,
			name = "air",
			prob = 254
		},
		{
			param2 = 0,
			name = "air",
			prob = 254
		},
		{
			param2 = 0,
			name = "air",
			prob = 254
		},
		{
			param2 = 0,
			name = "air",
			prob = 254
		},
		{
			param2 = 0,
			name = "air",
			prob = 254
		},
		{
			param2 = 0,
			name = "air",
			prob = 254
		},
		{
			param2 = 0,
			name = "air",
			prob = 254
		},
		{
			param2 = 0,
			name = "air",
			prob = 254
		},
		{
			param2 = 0,
			name = "air",
			prob = 254
		},
		{
			param2 = 0,
			name = "air",
			prob = 254
		},
		{
			param2 = 0,
			name = "air",
			prob = 254
		},
		{
			param2 = 1,
			name = "default:leaves",
			prob = 254
		},
		{
			param2 = 1,
			name = "default:leaves",
			prob = 254
		},
		{
			param2 = 1,
			name = "default:leaves",
			prob = 254
		},
		{
			param2 = 1,
			name = "default:leaves",
			prob = 254
		},
		{
			param2 = 1,
			name = "default:leaves",
			prob = 254
		},
		{
			param2 = 1,
			name = "default:leaves",
			prob = 254
		},
		{
			param2 = 1,
			name = "default:leaves",
			prob = 254
		},
		{
			param2 = 1,
			name = "default:leaves",
			prob = 254
		},
		{
			param2 = 1,
			name = "default:leaves",
			prob = 254
		},
		{
			param2 = 1,
			name = "default:leaves",
			prob = 254
		},
		{
			param2 = 1,
			name = "default:leaves",
			prob = 254
		},
		{
			param2 = 1,
			name = "default:leaves",
			prob = 254
		},
		{
			param2 = 1,
			name = "default:leaves",
			prob = 254
		},
		{
			param2 = 1,
			name = "default:leaves",
			prob = 254
		},
		{
			param2 = 1,
			name = "default:leaves",
			prob = 254
		},
		{
			param2 = 0,
			name = "air",
			prob = 254
		},
		{
			param2 = 1,
			name = "default:leaves",
			prob = 254
		},
		{
			param2 = 1,
			name = "default:leaves",
			prob = 254
		},
		{
			param2 = 0,
			name = "air",
			prob = 254
		},
		{
			param2 = 0,
			name = "air",
			prob = 254
		},
		{
			param2 = 0,
			name = "air",
			prob = 254
		},
		{
			param2 = 0,
			name = "air",
			prob = 254
		},
		{
			param2 = 0,
			name = "air",
			prob = 254
		},
		{
			param2 = 0,
			name = "air",
			prob = 254
		},
		{
			param2 = 0,
			name = "air",
			prob = 254
		},
		{
			param2 = 0,
			name = "air",
			prob = 254
		},
		{
			param2 = 0,
			name = "air",
			prob = 254
		},
		{
			param2 = 0,
			name = "air",
			prob = 254
		},
		{
			param2 = 0,
			name = "air",
			prob = 254
		},
		{
			param2 = 0,
			name = "air",
			prob = 254
		},
		{
			param2 = 0,
			name = "air",
			prob = 254
		},
		{
			param2 = 0,
			name = "air",
			prob = 254
		},
		{
			param2 = 0,
			name = "air",
			prob = 254
		},
		{
			param2 = 0,
			name = "air",
			prob = 254
		},
		{
			param2 = 0,
			name = "air",
			prob = 254
		},
		{
			param2 = 0,
			name = "air",
			prob = 254
		},
		{
			param2 = 1,
			name = "default:leaves",
			prob = 254
		},
		{
			param2 = 1,
			name = "default:leaves",
			prob = 254
		},
		{
			param2 = 1,
			name = "default:leaves",
			prob = 254
		},
		{
			param2 = 0,
			name = "air",
			prob = 254
		},
		{
			param2 = 0,
			name = "air",
			prob = 254
		},
		{
			param2 = 1,
			name = "default:leaves",
			prob = 254
		},
		{
			param2 = 1,
			name = "default:leaves",
			prob = 254
		},
		{
			param2 = 1,
			name = "default:leaves",
			prob = 254
		},
		{
			param2 = 0,
			name = "air",
			prob = 254
		},
		{
			param2 = 0,
			name = "air",
			prob = 254
		},
		{
			param2 = 1,
			name = "default:leaves",
			prob = 254
		},
		{
			param2 = 1,
			name = "default:leaves",
			prob = 254
		},
		{
			param2 = 0,
			name = "air",
			prob = 254
		},
		{
			param2 = 0,
			name = "air",
			prob = 254
		},
		{
			param2 = 0,
			name = "air",
			prob = 254
		},
		{
			param2 = 0,
			name = "air",
			prob = 254
		},
		{
			param2 = 0,
			name = "air",
			prob = 254
		},
		{
			param2 = 0,
			name = "air",
			prob = 254
		},
		{
			param2 = 0,
			name = "air",
			prob = 254
		}
	},
	size = {
		y = 7,
		x = 5,
		z = 5
	}
}