{
	yslice_prob = {
		{
			prob = 254,
			ypos = 0
		},
		{
			prob = 254,
			ypos = 1
		},
		{
			prob = 254,
			ypos = 2
		},
		{
			prob = 254,
			ypos = 3
		},
		{
			prob = 254,
			ypos = 4
		},
		{
			prob = 254,
			ypos = 5
		},
		{
			prob = 254,
			ypos = 6
		},
		{
			prob = 254,
			ypos = 7
		},
		{
			prob = 254,
			ypos = 8
		},
		{
			prob = 254,
			ypos = 9
		},
		{
			prob = 254,
			ypos = 10
		}
	},
	data = {
		{
			param2 = 0,
			name = "air",
			prob = 254
		},
		{
			param2 = 0,
			name = "air",
			prob = 254
		},
		{
			param2 = 0,
			name = "air",
			prob = 254
		},
		{
			param2 = 0,
			name = "air",
			prob = 254
		},
		{
			param2 = 0,
			name = "air",
			prob = 254
		},
		{
			param2 = 0,
			name = "air",
			prob = 254
		},
		{
			param2 = 0,
			name = "air",
			prob = 254
		},
		{
			param2 = 0,
			name = "air",
			prob = 254
		},
		{
			param2 = 0,
			name = "air",
			prob = 254
		},
		{
			param2 = 0,
			name = "air",
			prob = 254
		},
		{
			param2 = 0,
			name = "air",
			prob = 254
		},
		{
			param2 = 0,
			name = "air",
			prob = 254
		},
		{
			param2 = 0,
			name = "air",
			prob = 254
		},
		{
			param2 = 0,
			name = "air",
			prob = 254
		},
		{
			param2 = 0,
			name = "air",
			prob = 254
		},
		{
			param2 = 0,
			name = "air",
			prob = 254
		},
		{
			param2 = 0,
			name = "air",
			prob = 254
		},
		{
			param2 = 0,
			name = "air",
			prob = 254
		},
		{
			param2 = 0,
			name = "air",
			prob = 254
		},
		{
			param2 = 0,
			name = "air",
			prob = 254
		},
		{
			param2 = 0,
			name = "air",
			prob = 254
		},
		{
			param2 = 0,
			name = "air",
			prob = 254
		},
		{
			param2 = 0,
			name = "air",
			prob = 254
		},
		{
			param2 = 0,
			name = "air",
			prob = 254
		},
		{
			param2 = 0,
			name = "air",
			prob = 254
		},
		{
			param2 = 0,
			name = "air",
			prob = 254
		},
		{
			param2 = 0,
			name = "air",
			prob = 254
		},
		{
			param2 = 0,
			name = "air",
			prob = 254
		},
		{
			param2 = 0,
			name = "air",
			prob = 254
		},
		{
			param2 = 0,
			name = "air",
			prob = 254
		},
		{
			param2 = 0,
			name = "air",
			prob = 254
		},
		{
			param2 = 0,
			name = "air",
			prob = 254
		},
		{
			param2 = 0,
			name = "air",
			prob = 254
		},
		{
			param2 = 0,
			name = "air",
			prob = 254
		},
		{
			param2 = 0,
			name = "air",
			prob = 254
		},
		{
			param2 = 0,
			name = "air",
			prob = 254
		},
		{
			param2 = 0,
			name = "air",
			prob = 254
		},
		{
			param2 = 0,
			name = "air",
			prob = 254
		},
		{
			param2 = 0,
			name = "air",
			prob = 254
		},
		{
			param2 = 0,
			name = "air",
			prob = 254
		},
		{
			param2 = 0,
			name = "air",
			prob = 254
		},
		{
			param2 = 0,
			name = "air",
			prob = 254
		},
		{
			param2 = 0,
			name = "air",
			prob = 254
		},
		{
			param2 = 0,
			name = "air",
			prob = 254
		},
		{
			param2 = 0,
			name = "air",
			prob = 254
		},
		{
			param2 = 0,
			name = "air",
			prob = 254
		},
		{
			param2 = 0,
			name = "air",
			prob = 254
		},
		{
			param2 = 0,
			name = "air",
			prob = 254
		},
		{
			param2 = 0,
			name = "air",
			prob = 254
		},
		{
			param2 = 0,
			name = "air",
			prob = 254
		},
		{
			param2 = 0,
			name = "air",
			prob = 254
		},
		{
			param2 = 0,
			name = "air",
			prob = 254
		},
		{
			param2 = 0,
			name = "air",
			prob = 254
		},
		{
			param2 = 0,
			name = "air",
			prob = 254
		},
		{
			param2 = 0,
			name = "air",
			prob = 254
		},
		{
			param2 = 0,
			name = "air",
			prob = 254
		},
		{
			param2 = 0,
			name = "air",
			prob = 254
		},
		{
			param2 = 0,
			name = "air",
			prob = 254
		},
		{
			param2 = 0,
			name = "air",
			prob = 254
		},
		{
			param2 = 0,
			name = "mapgen:palm_leaves",
			prob = 254
		},
		{
			param2 = 0,
			name = "air",
			prob = 254
		},
		{
			param2 = 0,
			name = "air",
			prob = 254
		},
		{
			param2 = 0,
			name = "air",
			prob = 254
		},
		{
			param2 = 0,
			name = "air",
			prob = 254
		},
		{
			param2 = 0,
			name = "air",
			prob = 254
		},
		{
			param2 = 0,
			name = "air",
			prob = 254
		},
		{
			param2 = 0,
			name = "mapgen:palm_leaves",
			prob = 254
		},
		{
			param2 = 0,
			name = "air",
			prob = 254
		},
		{
			param2 = 0,
			name = "air",
			prob = 254
		},
		{
			param2 = 0,
			name = "air",
			prob = 254
		},
		{
			param2 = 0,
			name = "air",
			prob = 254
		},
		{
			param2 = 0,
			name = "air",
			prob = 254
		},
		{
			param2 = 0,
			name = "air",
			prob = 254
		},
		{
			param2 = 0,
			name = "air",
			prob = 254
		},
		{
			param2 = 0,
			name = "air",
			prob = 254
		},
		{
			param2 = 0,
			name = "air",
			prob = 254
		},
		{
			param2 = 0,
			name = "air",
			prob = 254
		},
		{
			param2 = 0,
			name = "air",
			prob = 254
		},
		{
			param2 = 0,
			name = "air",
			prob = 254
		},
		{
			param2 = 0,
			name = "air",
			prob = 254
		},
		{
			param2 = 0,
			name = "air",
			prob = 254
		},
		{
			param2 = 0,
			name = "air",
			prob = 254
		},
		{
			param2 = 0,
			name = "air",
			prob = 254
		},
		{
			param2 = 0,
			name = "air",
			prob = 254
		},
		{
			param2 = 0,
			name = "air",
			prob = 254
		},
		{
			param2 = 0,
			name = "air",
			prob = 254
		},
		{
			param2 = 0,
			name = "air",
			prob = 254
		},
		{
			param2 = 0,
			name = "air",
			prob = 254
		},
		{
			param2 = 0,
			name = "air",
			prob = 254
		},
		{
			param2 = 0,
			name = "air",
			prob = 254
		},
		{
			param2 = 0,
			name = "air",
			prob = 254
		},
		{
			param2 = 0,
			name = "air",
			prob = 254
		},
		{
			param2 = 0,
			name = "air",
			prob = 254
		},
		{
			param2 = 0,
			name = "air",
			prob = 254
		},
		{
			param2 = 0,
			name = "air",
			prob = 254
		},
		{
			param2 = 0,
			name = "air",
			prob = 254
		},
		{
			param2 = 0,
			name = "air",
			prob = 254
		},
		{
			param2 = 0,
			name = "air",
			prob = 254
		},
		{
			param2 = 0,
			name = "air",
			prob = 254
		},
		{
			param2 = 0,
			name = "air",
			prob = 254
		},
		{
			param2 = 0,
			name = "air",
			prob = 254
		},
		{
			param2 = 0,
			name = "air",
			prob = 254
		},
		{
			param2 = 0,
			name = "air",
			prob = 254
		},
		{
			param2 = 0,
			name = "air",
			prob = 254
		},
		{
			param2 = 0,
			name = "air",
			prob = 254
		},
		{
			param2 = 0,
			name = "air",
			prob = 254
		},
		{
			param2 = 0,
			name = "air",
			prob = 254
		},
		{
			param2 = 0,
			name = "air",
			prob = 254
		},
		{
			param2 = 0,
			name = "air",
			prob = 254
		},
		{
			param2 = 0,
			name = "air",
			prob = 254
		},
		{
			param2 = 0,
			name = "air",
			prob = 254
		},
		{
			param2 = 0,
			name = "air",
			prob = 254
		},
		{
			param2 = 0,
			name = "air",
			prob = 254
		},
		{
			param2 = 0,
			name = "air",
			prob = 254
		},
		{
			param2 = 0,
			name = "air",
			prob = 254
		},
		{
			param2 = 0,
			name = "air",
			prob = 254
		},
		{
			param2 = 0,
			name = "air",
			prob = 254
		},
		{
			param2 = 0,
			name = "air",
			prob = 254
		},
		{
			param2 = 0,
			name = "air",
			prob = 254
		},
		{
			param2 = 0,
			name = "air",
			prob = 254
		},
		{
			param2 = 0,
			name = "air",
			prob = 254
		},
		{
			param2 = 0,
			name = "air",
			prob = 254
		},
		{
			param2 = 0,
			name = "air",
			prob = 254
		},
		{
			param2 = 0,
			name = "air",
			prob = 254
		},
		{
			param2 = 0,
			name = "air",
			prob = 254
		},
		{
			param2 = 0,
			name = "air",
			prob = 254
		},
		{
			param2 = 0,
			name = "air",
			prob = 254
		},
		{
			param2 = 0,
			name = "air",
			prob = 254
		},
		{
			param2 = 0,
			name = "air",
			prob = 254
		},
		{
			param2 = 0,
			name = "air",
			prob = 254
		},
		{
			param2 = 0,
			name = "air",
			prob = 254
		},
		{
			param2 = 0,
			name = "air",
			prob = 254
		},
		{
			param2 = 0,
			name = "air",
			prob = 254
		},
		{
			param2 = 0,
			name = "air",
			prob = 254
		},
		{
			param2 = 0,
			name = "air",
			prob = 254
		},
		{
			param2 = 0,
			name = "air",
			prob = 254
		},
		{
			param2 = 0,
			name = "air",
			prob = 254
		},
		{
			param2 = 0,
			name = "air",
			prob = 254
		},
		{
			param2 = 0,
			name = "air",
			prob = 254
		},
		{
			param2 = 0,
			name = "air",
			prob = 254
		},
		{
			param2 = 0,
			name = "air",
			prob = 254
		},
		{
			param2 = 0,
			name = "air",
			prob = 254
		},
		{
			param2 = 0,
			name = "air",
			prob = 254
		},
		{
			param2 = 0,
			name = "mapgen:palm_leaves",
			prob = 254
		},
		{
			param2 = 0,
			name = "air",
			prob = 254
		},
		{
			param2 = 0,
			name = "air",
			prob = 254
		},
		{
			param2 = 0,
			name = "air",
			prob = 254
		},
		{
			param2 = 0,
			name = "air",
			prob = 254
		},
		{
			param2 = 0,
			name = "air",
			prob = 254
		},
		{
			param2 = 0,
			name = "air",
			prob = 254
		},
		{
			param2 = 0,
			name = "mapgen:palm_leaves",
			prob = 254
		},
		{
			param2 = 0,
			name = "air",
			prob = 254
		},
		{
			param2 = 0,
			name = "air",
			prob = 254
		},
		{
			param2 = 0,
			name = "air",
			prob = 254
		},
		{
			param2 = 0,
			name = "air",
			prob = 254
		},
		{
			param2 = 0,
			name = "air",
			prob = 254
		},
		{
			param2 = 0,
			name = "air",
			prob = 254
		},
		{
			param2 = 0,
			name = "air",
			prob = 254
		},
		{
			param2 = 0,
			name = "air",
			prob = 254
		},
		{
			param2 = 0,
			name = "air",
			prob = 254
		},
		{
			param2 = 0,
			name = "air",
			prob = 254
		},
		{
			param2 = 0,
			name = "air",
			prob = 254
		},
		{
			param2 = 0,
			name = "air",
			prob = 254
		},
		{
			param2 = 0,
			name = "air",
			prob = 254
		},
		{
			param2 = 0,
			name = "air",
			prob = 254
		},
		{
			param2 = 0,
			name = "air",
			prob = 254
		},
		{
			param2 = 0,
			name = "air",
			prob = 254
		},
		{
			param2 = 0,
			name = "air",
			prob = 254
		},
		{
			param2 = 0,
			name = "air",
			prob = 254
		},
		{
			param2 = 0,
			name = "air",
			prob = 254
		},
		{
			param2 = 0,
			name = "air",
			prob = 254
		},
		{
			param2 = 0,
			name = "air",
			prob = 254
		},
		{
			param2 = 0,
			name = "air",
			prob = 254
		},
		{
			param2 = 0,
			name = "air",
			prob = 254
		},
		{
			param2 = 0,
			name = "air",
			prob = 254
		},
		{
			param2 = 0,
			name = "air",
			prob = 254
		},
		{
			param2 = 0,
			name = "air",
			prob = 254
		},
		{
			param2 = 0,
			name = "air",
			prob = 254
		},
		{
			param2 = 0,
			name = "air",
			prob = 254
		},
		{
			param2 = 0,
			name = "air",
			prob = 254
		},
		{
			param2 = 0,
			name = "air",
			prob = 254
		},
		{
			param2 = 0,
			name = "air",
			prob = 254
		},
		{
			param2 = 0,
			name = "air",
			prob = 254
		},
		{
			param2 = 0,
			name = "air",
			prob = 254
		},
		{
			param2 = 0,
			name = "air",
			prob = 254
		},
		{
			param2 = 0,
			name = "air",
			prob = 254
		},
		{
			param2 = 0,
			name = "air",
			prob = 254
		},
		{
			param2 = 0,
			name = "air",
			prob = 254
		},
		{
			param2 = 0,
			name = "air",
			prob = 254
		},
		{
			param2 = 0,
			name = "air",
			prob = 254
		},
		{
			param2 = 0,
			name = "air",
			prob = 254
		},
		{
			param2 = 0,
			name = "air",
			prob = 254
		},
		{
			param2 = 0,
			name = "air",
			prob = 254
		},
		{
			param2 = 0,
			name = "air",
			prob = 254
		},
		{
			param2 = 0,
			name = "air",
			prob = 254
		},
		{
			param2 = 0,
			name = "air",
			prob = 254
		},
		{
			param2 = 0,
			name = "air",
			prob = 254
		},
		{
			param2 = 0,
			name = "air",
			prob = 254
		},
		{
			param2 = 0,
			name = "air",
			prob = 254
		},
		{
			param2 = 0,
			name = "air",
			prob = 254
		},
		{
			param2 = 0,
			name = "air",
			prob = 254
		},
		{
			param2 = 0,
			name = "air",
			prob = 254
		},
		{
			param2 = 0,
			name = "air",
			prob = 254
		},
		{
			param2 = 0,
			name = "air",
			prob = 254
		},
		{
			param2 = 0,
			name = "air",
			prob = 254
		},
		{
			param2 = 0,
			name = "air",
			prob = 254
		},
		{
			param2 = 0,
			name = "air",
			prob = 254
		},
		{
			param2 = 0,
			name = "air",
			prob = 254
		},
		{
			param2 = 0,
			name = "air",
			prob = 254
		},
		{
			param2 = 0,
			name = "air",
			prob = 254
		},
		{
			param2 = 0,
			name = "air",
			prob = 254
		},
		{
			param2 = 0,
			name = "air",
			prob = 254
		},
		{
			param2 = 0,
			name = "air",
			prob = 254
		},
		{
			param2 = 0,
			name = "air",
			prob = 254
		},
		{
			param2 = 0,
			name = "air",
			prob = 254
		},
		{
			param2 = 0,
			name = "air",
			prob = 254
		},
		{
			param2 = 0,
			name = "air",
			prob = 254
		},
		{
			param2 = 0,
			name = "air",
			prob = 254
		},
		{
			param2 = 0,
			name = "air",
			prob = 254
		},
		{
			param2 = 0,
			name = "air",
			prob = 254
		},
		{
			param2 = 0,
			name = "mapgen:palm_leaves_coconut",
			prob = 254
		},
		{
			param2 = 0,
			name = "air",
			prob = 254
		},
		{
			param2 = 0,
			name = "air",
			prob = 254
		},
		{
			param2 = 0,
			name = "air",
			prob = 254
		},
		{
			param2 = 0,
			name = "air",
			prob = 254
		},
		{
			param2 = 0,
			name = "air",
			prob = 254
		},
		{
			param2 = 0,
			name = "air",
			prob = 254
		},
		{
			param2 = 0,
			name = "mapgen:palm_leaves",
			prob = 254
		},
		{
			param2 = 0,
			name = "mapgen:palm_leaves_coconut",
			prob = 254
		},
		{
			param2 = 0,
			name = "air",
			prob = 254
		},
		{
			param2 = 0,
			name = "air",
			prob = 254
		},
		{
			param2 = 0,
			name = "air",
			prob = 254
		},
		{
			param2 = 0,
			name = "air",
			prob = 254
		},
		{
			param2 = 0,
			name = "air",
			prob = 254
		},
		{
			param2 = 3,
			name = "mapgen:palm_tree",
			prob = 254
		},
		{
			param2 = 0,
			name = "air",
			prob = 254
		},
		{
			param2 = 0,
			name = "air",
			prob = 254
		},
		{
			param2 = 0,
			name = "air",
			prob = 254
		},
		{
			param2 = 0,
			name = "air",
			prob = 254
		},
		{
			param2 = 0,
			name = "air",
			prob = 254
		},
		{
			param2 = 0,
			name = "air",
			prob = 254
		},
		{
			param2 = 3,
			name = "mapgen:palm_tree",
			prob = 254
		},
		{
			param2 = 0,
			name = "air",
			prob = 254
		},
		{
			param2 = 0,
			name = "air",
			prob = 254
		},
		{
			param2 = 0,
			name = "air",
			prob = 254
		},
		{
			param2 = 0,
			name = "air",
			prob = 254
		},
		{
			param2 = 0,
			name = "air",
			prob = 254
		},
		{
			param2 = 0,
			name = "air",
			prob = 254
		},
		{
			param2 = 3,
			name = "mapgen:palm_tree",
			prob = 254
		},
		{
			param2 = 0,
			name = "air",
			prob = 254
		},
		{
			param2 = 0,
			name = "air",
			prob = 254
		},
		{
			param2 = 0,
			name = "air",
			prob = 254
		},
		{
			param2 = 0,
			name = "air",
			prob = 254
		},
		{
			param2 = 0,
			name = "air",
			prob = 254
		},
		{
			param2 = 0,
			name = "air",
			prob = 254
		},
		{
			param2 = 3,
			name = "mapgen:palm_tree",
			prob = 254
		},
		{
			param2 = 0,
			name = "air",
			prob = 254
		},
		{
			param2 = 0,
			name = "air",
			prob = 254
		},
		{
			param2 = 0,
			name = "air",
			prob = 254
		},
		{
			param2 = 0,
			name = "air",
			prob = 254
		},
		{
			param2 = 0,
			name = "air",
			prob = 254
		},
		{
			param2 = 0,
			name = "air",
			prob = 254
		},
		{
			param2 = 3,
			name = "mapgen:palm_tree",
			prob = 254
		},
		{
			param2 = 0,
			name = "air",
			prob = 254
		},
		{
			param2 = 0,
			name = "air",
			prob = 254
		},
		{
			param2 = 0,
			name = "air",
			prob = 254
		},
		{
			param2 = 0,
			name = "air",
			prob = 254
		},
		{
			param2 = 0,
			name = "air",
			prob = 254
		},
		{
			param2 = 0,
			name = "air",
			prob = 254
		},
		{
			param2 = 3,
			name = "mapgen:palm_tree",
			prob = 254
		},
		{
			param2 = 0,
			name = "air",
			prob = 254
		},
		{
			param2 = 0,
			name = "air",
			prob = 254
		},
		{
			param2 = 0,
			name = "air",
			prob = 254
		},
		{
			param2 = 0,
			name = "air",
			prob = 254
		},
		{
			param2 = 0,
			name = "air",
			prob = 254
		},
		{
			param2 = 0,
			name = "air",
			prob = 254
		},
		{
			param2 = 3,
			name = "mapgen:palm_tree",
			prob = 254
		},
		{
			param2 = 0,
			name = "air",
			prob = 254
		},
		{
			param2 = 0,
			name = "air",
			prob = 254
		},
		{
			param2 = 0,
			name = "air",
			prob = 254
		},
		{
			param2 = 0,
			name = "air",
			prob = 254
		},
		{
			param2 = 0,
			name = "air",
			prob = 254
		},
		{
			param2 = 0,
			name = "air",
			prob = 254
		},
		{
			param2 = 3,
			name = "mapgen:palm_tree",
			prob = 254
		},
		{
			param2 = 0,
			name = "air",
			prob = 254
		},
		{
			param2 = 0,
			name = "air",
			prob = 254
		},
		{
			param2 = 0,
			name = "air",
			prob = 254
		},
		{
			param2 = 0,
			name = "mapgen:palm_leaves",
			prob = 254
		},
		{
			param2 = 0,
			name = "air",
			prob = 254
		},
		{
			param2 = 0,
			name = "air",
			prob = 254
		},
		{
			param2 = 3,
			name = "mapgen:palm_tree",
			prob = 254
		},
		{
			param2 = 0,
			name = "air",
			prob = 254
		},
		{
			param2 = 0,
			name = "air",
			prob = 254
		},
		{
			param2 = 0,
			name = "mapgen:palm_leaves",
			prob = 254
		},
		{
			param2 = 0,
			name = "mapgen:palm_leaves",
			prob = 254
		},
		{
			param2 = 0,
			name = "mapgen:palm_leaves",
			prob = 254
		},
		{
			param2 = 0,
			name = "air",
			prob = 254
		},
		{
			param2 = 2,
			name = "mapgen:palm_tree",
			prob = 254
		},
		{
			param2 = 0,
			name = "air",
			prob = 254
		},
		{
			param2 = 0,
			name = "mapgen:palm_leaves",
			prob = 254
		},
		{
			param2 = 0,
			name = "mapgen:palm_leaves",
			prob = 254
		},
		{
			param2 = 0,
			name = "air",
			prob = 254
		},
		{
			param2 = 0,
			name = "mapgen:palm_leaves",
			prob = 254
		},
		{
			param2 = 0,
			name = "mapgen:palm_leaves",
			prob = 254
		},
		{
			param2 = 0,
			name = "air",
			prob = 254
		},
		{
			param2 = 0,
			name = "mapgen:palm_leaves",
			prob = 254
		},
		{
			param2 = 0,
			name = "mapgen:palm_leaves",
			prob = 254
		},
		{
			param2 = 0,
			name = "air",
			prob = 254
		},
		{
			param2 = 0,
			name = "air",
			prob = 254
		},
		{
			param2 = 0,
			name = "air",
			prob = 254
		},
		{
			param2 = 0,
			name = "air",
			prob = 254
		},
		{
			param2 = 0,
			name = "air",
			prob = 254
		},
		{
			param2 = 0,
			name = "air",
			prob = 254
		},
		{
			param2 = 0,
			name = "air",
			prob = 254
		},
		{
			param2 = 0,
			name = "air",
			prob = 254
		},
		{
			param2 = 0,
			name = "air",
			prob = 254
		},
		{
			param2 = 0,
			name = "air",
			prob = 254
		},
		{
			param2 = 0,
			name = "air",
			prob = 254
		},
		{
			param2 = 0,
			name = "air",
			prob = 254
		},
		{
			param2 = 0,
			name = "air",
			prob = 254
		},
		{
			param2 = 0,
			name = "air",
			prob = 254
		},
		{
			param2 = 0,
			name = "air",
			prob = 254
		},
		{
			param2 = 0,
			name = "air",
			prob = 254
		},
		{
			param2 = 0,
			name = "air",
			prob = 254
		},
		{
			param2 = 0,
			name = "air",
			prob = 254
		},
		{
			param2 = 0,
			name = "air",
			prob = 254
		},
		{
			param2 = 0,
			name = "air",
			prob = 254
		},
		{
			param2 = 0,
			name = "air",
			prob = 254
		},
		{
			param2 = 0,
			name = "air",
			prob = 254
		},
		{
			param2 = 0,
			name = "air",
			prob = 254
		},
		{
			param2 = 0,
			name = "air",
			prob = 254
		},
		{
			param2 = 0,
			name = "air",
			prob = 254
		},
		{
			param2 = 0,
			name = "air",
			prob = 254
		},
		{
			param2 = 0,
			name = "air",
			prob = 254
		},
		{
			param2 = 0,
			name = "air",
			prob = 254
		},
		{
			param2 = 0,
			name = "air",
			prob = 254
		},
		{
			param2 = 0,
			name = "air",
			prob = 254
		},
		{
			param2 = 0,
			name = "air",
			prob = 254
		},
		{
			param2 = 0,
			name = "air",
			prob = 254
		},
		{
			param2 = 0,
			name = "air",
			prob = 254
		},
		{
			param2 = 0,
			name = "air",
			prob = 254
		},
		{
			param2 = 0,
			name = "air",
			prob = 254
		},
		{
			param2 = 0,
			name = "air",
			prob = 254
		},
		{
			param2 = 0,
			name = "air",
			prob = 254
		},
		{
			param2 = 0,
			name = "air",
			prob = 254
		},
		{
			param2 = 0,
			name = "air",
			prob = 254
		},
		{
			param2 = 0,
			name = "air",
			prob = 254
		},
		{
			param2 = 0,
			name = "air",
			prob = 254
		},
		{
			param2 = 0,
			name = "air",
			prob = 254
		},
		{
			param2 = 0,
			name = "air",
			prob = 254
		},
		{
			param2 = 0,
			name = "air",
			prob = 254
		},
		{
			param2 = 0,
			name = "air",
			prob = 254
		},
		{
			param2 = 0,
			name = "air",
			prob = 254
		},
		{
			param2 = 0,
			name = "air",
			prob = 254
		},
		{
			param2 = 0,
			name = "air",
			prob = 254
		},
		{
			param2 = 0,
			name = "air",
			prob = 254
		},
		{
			param2 = 0,
			name = "air",
			prob = 254
		},
		{
			param2 = 0,
			name = "air",
			prob = 254
		},
		{
			param2 = 0,
			name = "air",
			prob = 254
		},
		{
			param2 = 0,
			name = "air",
			prob = 254
		},
		{
			param2 = 0,
			name = "air",
			prob = 254
		},
		{
			param2 = 0,
			name = "air",
			prob = 254
		},
		{
			param2 = 0,
			name = "air",
			prob = 254
		},
		{
			param2 = 0,
			name = "air",
			prob = 254
		},
		{
			param2 = 0,
			name = "air",
			prob = 254
		},
		{
			param2 = 0,
			name = "air",
			prob = 254
		},
		{
			param2 = 0,
			name = "air",
			prob = 254
		},
		{
			param2 = 0,
			name = "air",
			prob = 254
		},
		{
			param2 = 0,
			name = "air",
			prob = 254
		},
		{
			param2 = 0,
			name = "air",
			prob = 254
		},
		{
			param2 = 0,
			name = "air",
			prob = 254
		},
		{
			param2 = 0,
			name = "air",
			prob = 254
		},
		{
			param2 = 0,
			name = "air",
			prob = 254
		},
		{
			param2 = 0,
			name = "air",
			prob = 254
		},
		{
			param2 = 0,
			name = "mapgen:palm_leaves_coconut",
			prob = 254
		},
		{
			param2 = 0,
			name = "air",
			prob = 254
		},
		{
			param2 = 0,
			name = "air",
			prob = 254
		},
		{
			param2 = 0,
			name = "air",
			prob = 254
		},
		{
			param2 = 0,
			name = "air",
			prob = 254
		},
		{
			param2 = 0,
			name = "air",
			prob = 254
		},
		{
			param2 = 0,
			name = "mapgen:palm_leaves_coconut",
			prob = 254
		},
		{
			param2 = 0,
			name = "mapgen:palm_leaves",
			prob = 254
		},
		{
			param2 = 0,
			name = "air",
			prob = 254
		},
		{
			param2 = 0,
			name = "air",
			prob = 254
		},
		{
			param2 = 0,
			name = "air",
			prob = 254
		},
		{
			param2 = 0,
			name = "air",
			prob = 254
		},
		{
			param2 = 0,
			name = "air",
			prob = 254
		},
		{
			param2 = 0,
			name = "air",
			prob = 254
		},
		{
			param2 = 0,
			name = "air",
			prob = 254
		},
		{
			param2 = 0,
			name = "air",
			prob = 254
		},
		{
			param2 = 0,
			name = "air",
			prob = 254
		},
		{
			param2 = 0,
			name = "air",
			prob = 254
		},
		{
			param2 = 0,
			name = "air",
			prob = 254
		},
		{
			param2 = 0,
			name = "air",
			prob = 254
		},
		{
			param2 = 0,
			name = "air",
			prob = 254
		},
		{
			param2 = 0,
			name = "air",
			prob = 254
		},
		{
			param2 = 0,
			name = "air",
			prob = 254
		},
		{
			param2 = 0,
			name = "air",
			prob = 254
		},
		{
			param2 = 0,
			name = "air",
			prob = 254
		},
		{
			param2 = 0,
			name = "air",
			prob = 254
		},
		{
			param2 = 0,
			name = "air",
			prob = 254
		},
		{
			param2 = 0,
			name = "air",
			prob = 254
		},
		{
			param2 = 0,
			name = "air",
			prob = 254
		},
		{
			param2 = 0,
			name = "air",
			prob = 254
		},
		{
			param2 = 0,
			name = "air",
			prob = 254
		},
		{
			param2 = 0,
			name = "air",
			prob = 254
		},
		{
			param2 = 0,
			name = "air",
			prob = 254
		},
		{
			param2 = 0,
			name = "air",
			prob = 254
		},
		{
			param2 = 0,
			name = "air",
			prob = 254
		},
		{
			param2 = 0,
			name = "air",
			prob = 254
		},
		{
			param2 = 0,
			name = "air",
			prob = 254
		},
		{
			param2 = 0,
			name = "air",
			prob = 254
		},
		{
			param2 = 0,
			name = "air",
			prob = 254
		},
		{
			param2 = 0,
			name = "air",
			prob = 254
		},
		{
			param2 = 0,
			name = "air",
			prob = 254
		},
		{
			param2 = 0,
			name = "air",
			prob = 254
		},
		{
			param2 = 0,
			name = "air",
			prob = 254
		},
		{
			param2 = 0,
			name = "air",
			prob = 254
		},
		{
			param2 = 0,
			name = "air",
			prob = 254
		},
		{
			param2 = 0,
			name = "air",
			prob = 254
		},
		{
			param2 = 0,
			name = "air",
			prob = 254
		},
		{
			param2 = 0,
			name = "air",
			prob = 254
		},
		{
			param2 = 0,
			name = "air",
			prob = 254
		},
		{
			param2 = 0,
			name = "air",
			prob = 254
		},
		{
			param2 = 0,
			name = "air",
			prob = 254
		},
		{
			param2 = 0,
			name = "air",
			prob = 254
		},
		{
			param2 = 0,
			name = "air",
			prob = 254
		},
		{
			param2 = 0,
			name = "air",
			prob = 254
		},
		{
			param2 = 0,
			name = "air",
			prob = 254
		},
		{
			param2 = 0,
			name = "air",
			prob = 254
		},
		{
			param2 = 0,
			name = "air",
			prob = 254
		},
		{
			param2 = 0,
			name = "air",
			prob = 254
		},
		{
			param2 = 0,
			name = "air",
			prob = 254
		},
		{
			param2 = 0,
			name = "air",
			prob = 254
		},
		{
			param2 = 0,
			name = "air",
			prob = 254
		},
		{
			param2 = 0,
			name = "air",
			prob = 254
		},
		{
			param2 = 0,
			name = "air",
			prob = 254
		},
		{
			param2 = 0,
			name = "air",
			prob = 254
		},
		{
			param2 = 0,
			name = "air",
			prob = 254
		},
		{
			param2 = 0,
			name = "air",
			prob = 254
		},
		{
			param2 = 0,
			name = "air",
			prob = 254
		},
		{
			param2 = 0,
			name = "air",
			prob = 254
		},
		{
			param2 = 0,
			name = "air",
			prob = 254
		},
		{
			param2 = 0,
			name = "air",
			prob = 254
		},
		{
			param2 = 0,
			name = "air",
			prob = 254
		},
		{
			param2 = 0,
			name = "air",
			prob = 254
		},
		{
			param2 = 0,
			name = "air",
			prob = 254
		},
		{
			param2 = 0,
			name = "air",
			prob = 254
		},
		{
			param2 = 0,
			name = "air",
			prob = 254
		},
		{
			param2 = 0,
			name = "air",
			prob = 254
		},
		{
			param2 = 0,
			name = "air",
			prob = 254
		},
		{
			param2 = 0,
			name = "mapgen:palm_leaves",
			prob = 254
		},
		{
			param2 = 0,
			name = "air",
			prob = 254
		},
		{
			param2 = 0,
			name = "air",
			prob = 254
		},
		{
			param2 = 0,
			name = "air",
			prob = 254
		},
		{
			param2 = 0,
			name = "air",
			prob = 254
		},
		{
			param2 = 0,
			name = "air",
			prob = 254
		},
		{
			param2 = 0,
			name = "air",
			prob = 254
		},
		{
			param2 = 0,
			name = "mapgen:palm_leaves",
			prob = 254
		},
		{
			param2 = 0,
			name = "air",
			prob = 254
		},
		{
			param2 = 0,
			name = "air",
			prob = 254
		},
		{
			param2 = 0,
			name = "air",
			prob = 254
		},
		{
			param2 = 0,
			name = "air",
			prob = 254
		},
		{
			param2 = 0,
			name = "air",
			prob = 254
		},
		{
			param2 = 0,
			name = "air",
			prob = 254
		},
		{
			param2 = 0,
			name = "air",
			prob = 254
		},
		{
			param2 = 0,
			name = "air",
			prob = 254
		},
		{
			param2 = 0,
			name = "air",
			prob = 254
		},
		{
			param2 = 0,
			name = "air",
			prob = 254
		},
		{
			param2 = 0,
			name = "air",
			prob = 254
		},
		{
			param2 = 0,
			name = "air",
			prob = 254
		},
		{
			param2 = 0,
			name = "air",
			prob = 254
		},
		{
			param2 = 0,
			name = "air",
			prob = 254
		},
		{
			param2 = 0,
			name = "air",
			prob = 254
		},
		{
			param2 = 0,
			name = "air",
			prob = 254
		},
		{
			param2 = 0,
			name = "air",
			prob = 254
		},
		{
			param2 = 0,
			name = "air",
			prob = 254
		},
		{
			param2 = 0,
			name = "air",
			prob = 254
		},
		{
			param2 = 0,
			name = "air",
			prob = 254
		},
		{
			param2 = 0,
			name = "air",
			prob = 254
		},
		{
			param2 = 0,
			name = "air",
			prob = 254
		},
		{
			param2 = 0,
			name = "air",
			prob = 254
		},
		{
			param2 = 0,
			name = "air",
			prob = 254
		},
		{
			param2 = 0,
			name = "air",
			prob = 254
		},
		{
			param2 = 0,
			name = "air",
			prob = 254
		},
		{
			param2 = 0,
			name = "air",
			prob = 254
		},
		{
			param2 = 0,
			name = "air",
			prob = 254
		},
		{
			param2 = 0,
			name = "air",
			prob = 254
		},
		{
			param2 = 0,
			name = "air",
			prob = 254
		},
		{
			param2 = 0,
			name = "air",
			prob = 254
		},
		{
			param2 = 0,
			name = "air",
			prob = 254
		},
		{
			param2 = 0,
			name = "air",
			prob = 254
		},
		{
			param2 = 0,
			name = "air",
			prob = 254
		},
		{
			param2 = 0,
			name = "air",
			prob = 254
		},
		{
			param2 = 0,
			name = "air",
			prob = 254
		},
		{
			param2 = 0,
			name = "air",
			prob = 254
		},
		{
			param2 = 0,
			name = "air",
			prob = 254
		},
		{
			param2 = 0,
			name = "air",
			prob = 254
		},
		{
			param2 = 0,
			name = "air",
			prob = 254
		},
		{
			param2 = 0,
			name = "air",
			prob = 254
		},
		{
			param2 = 0,
			name = "air",
			prob = 254
		},
		{
			param2 = 0,
			name = "air",
			prob = 254
		},
		{
			param2 = 0,
			name = "air",
			prob = 254
		},
		{
			param2 = 0,
			name = "air",
			prob = 254
		},
		{
			param2 = 0,
			name = "air",
			prob = 254
		},
		{
			param2 = 0,
			name = "air",
			prob = 254
		},
		{
			param2 = 0,
			name = "air",
			prob = 254
		},
		{
			param2 = 0,
			name = "air",
			prob = 254
		},
		{
			param2 = 0,
			name = "air",
			prob = 254
		},
		{
			param2 = 0,
			name = "air",
			prob = 254
		},
		{
			param2 = 0,
			name = "air",
			prob = 254
		},
		{
			param2 = 0,
			name = "air",
			prob = 254
		},
		{
			param2 = 0,
			name = "air",
			prob = 254
		},
		{
			param2 = 0,
			name = "air",
			prob = 254
		},
		{
			param2 = 0,
			name = "air",
			prob = 254
		},
		{
			param2 = 0,
			name = "air",
			prob = 254
		},
		{
			param2 = 0,
			name = "air",
			prob = 254
		},
		{
			param2 = 0,
			name = "air",
			prob = 254
		},
		{
			param2 = 0,
			name = "air",
			prob = 254
		},
		{
			param2 = 0,
			name = "air",
			prob = 254
		},
		{
			param2 = 0,
			name = "air",
			prob = 254
		},
		{
			param2 = 0,
			name = "mapgen:palm_leaves",
			prob = 254
		},
		{
			param2 = 0,
			name = "air",
			prob = 254
		},
		{
			param2 = 0,
			name = "air",
			prob = 254
		},
		{
			param2 = 0,
			name = "air",
			prob = 254
		},
		{
			param2 = 0,
			name = "air",
			prob = 254
		},
		{
			param2 = 0,
			name = "air",
			prob = 254
		},
		{
			param2 = 0,
			name = "air",
			prob = 254
		},
		{
			param2 = 0,
			name = "mapgen:palm_leaves",
			prob = 254
		},
		{
			param2 = 0,
			name = "air",
			prob = 254
		},
		{
			param2 = 0,
			name = "air",
			prob = 254
		},
		{
			param2 = 0,
			name = "air",
			prob = 254
		},
		{
			param2 = 0,
			name = "air",
			prob = 254
		},
		{
			param2 = 0,
			name = "air",
			prob = 254
		},
		{
			param2 = 0,
			name = "air",
			prob = 254
		},
		{
			param2 = 0,
			name = "air",
			prob = 254
		},
		{
			param2 = 0,
			name = "air",
			prob = 254
		},
		{
			param2 = 0,
			name = "air",
			prob = 254
		},
		{
			param2 = 0,
			name = "air",
			prob = 254
		}
	},
	size = {
		y = 11,
		x = 7,
		z = 7
	}
}