{
	yslice_prob = {
		{
			prob = 254,
			ypos = 0
		},
		{
			prob = 254,
			ypos = 1
		},
		{
			prob = 254,
			ypos = 2
		},
		{
			prob = 254,
			ypos = 3
		},
		{
			prob = 254,
			ypos = 4
		},
		{
			prob = 254,
			ypos = 5
		},
		{
			prob = 254,
			ypos = 6
		},
		{
			prob = 254,
			ypos = 7
		},
		{
			prob = 254,
			ypos = 8
		},
		{
			prob = 254,
			ypos = 9
		},
		{
			prob = 254,
			ypos = 10
		},
		{
			prob = 254,
			ypos = 11
		}
	},
	data = {
		{
			param2 = 0,
			name = "default:sandstonebrick",
			prob = 254
		},
		{
			param2 = 0,
			name = "default:sandstonebrick",
			prob = 254
		},
		{
			param2 = 0,
			name = "default:sandstonebrick",
			prob = 254
		},
		{
			param2 = 0,
			name = "default:sandstonebrick",
			prob = 254
		},
		{
			param2 = 0,
			name = "default:sandstonebrick",
			prob = 254
		},
		{
			param2 = 0,
			name = "default:sandstonebrick",
			prob = 254
		},
		{
			param2 = 0,
			name = "default:sandstonebrick",
			prob = 254
		},
		{
			param2 = 0,
			name = "default:sandstonebrick",
			prob = 254
		},
		{
			param2 = 0,
			name = "default:sandstonebrick",
			prob = 254
		},
		{
			param2 = 0,
			name = "default:sandstonebrick",
			prob = 254
		},
		{
			param2 = 0,
			name = "default:sandstonebrick",
			prob = 254
		},
		{
			param2 = 0,
			name = "default:sandstonebrick",
			prob = 254
		},
		{
			param2 = 0,
			name = "default:sandstonebrick",
			prob = 254
		},
		{
			param2 = 0,
			name = "default:sandstonebrick",
			prob = 254
		},
		{
			param2 = 0,
			name = "default:sandstonebrick",
			prob = 254
		},
		{
			param2 = 0,
			name = "default:sandstonebrick",
			prob = 254
		},
		{
			param2 = 0,
			name = "default:sandstonebrick",
			prob = 254
		},
		{
			param2 = 0,
			name = "default:sandstonebrick",
			prob = 254
		},
		{
			param2 = 0,
			name = "default:sandstonebrick",
			prob = 254
		},
		{
			param2 = 0,
			name = "default:sandstonebrick",
			prob = 254
		},
		{
			param2 = 0,
			name = "default:sandstonebrick",
			prob = 254
		},
		{
			param2 = 0,
			name = "default:sandstone_block",
			prob = 254
		},
		{
			param2 = 0,
			name = "default:sandstonebrick",
			prob = 254
		},
		{
			param2 = 0,
			name = "default:sandstonebrick",
			prob = 254
		},
		{
			param2 = 0,
			name = "default:sandstonebrick",
			prob = 254
		},
		{
			param2 = 0,
			name = "default:sandstonebrick",
			prob = 254
		},
		{
			param2 = 0,
			name = "default:sandstonebrick",
			prob = 254
		},
		{
			param2 = 0,
			name = "default:sandstonebrick",
			prob = 254
		},
		{
			param2 = 0,
			name = "default:sandstonebrick",
			prob = 254
		},
		{
			param2 = 0,
			name = "default:sandstonebrick",
			prob = 254
		},
		{
			param2 = 0,
			name = "default:sandstonebrick",
			prob = 254
		},
		{
			param2 = 0,
			name = "default:sandstonebrick",
			prob = 254
		},
		{
			param2 = 0,
			name = "default:sandstonebrick",
			prob = 254
		},
		{
			param2 = 0,
			name = "default:sandstonebrick",
			prob = 254
		},
		{
			param2 = 0,
			name = "default:sandstonebrick",
			prob = 254
		},
		{
			param2 = 0,
			name = "default:sandstonebrick",
			prob = 254
		},
		{
			param2 = 0,
			name = "default:sandstonebrick",
			prob = 254
		},
		{
			param2 = 0,
			name = "default:sandstonebrick",
			prob = 254
		},
		{
			param2 = 0,
			name = "default:sandstonebrick",
			prob = 254
		},
		{
			param2 = 0,
			name = "default:sandstonebrick",
			prob = 254
		},
		{
			param2 = 0,
			name = "default:sandstonebrick",
			prob = 254
		},
		{
			param2 = 0,
			name = "default:sandstone_block",
			prob = 254
		},
		{
			param2 = 0,
			name = "air",
			prob = 254
		},
		{
			param2 = 0,
			name = "air",
			prob = 254
		},
		{
			param2 = 0,
			name = "air",
			prob = 254
		},
		{
			param2 = 0,
			name = "air",
			prob = 254
		},
		{
			param2 = 0,
			name = "air",
			prob = 254
		},
		{
			param2 = 0,
			name = "air",
			prob = 254
		},
		{
			param2 = 0,
			name = "air",
			prob = 254
		},
		{
			param2 = 0,
			name = "air",
			prob = 254
		},
		{
			param2 = 0,
			name = "air",
			prob = 254
		},
		{
			param2 = 0,
			name = "air",
			prob = 254
		},
		{
			param2 = 0,
			name = "air",
			prob = 254
		},
		{
			param2 = 0,
			name = "air",
			prob = 254
		},
		{
			param2 = 0,
			name = "air",
			prob = 254
		},
		{
			param2 = 0,
			name = "air",
			prob = 254
		},
		{
			param2 = 0,
			name = "air",
			prob = 254
		},
		{
			param2 = 0,
			name = "air",
			prob = 254
		},
		{
			param2 = 0,
			name = "air",
			prob = 254
		},
		{
			param2 = 0,
			name = "air",
			prob = 254
		},
		{
			param2 = 0,
			name = "air",
			prob = 254
		},
		{
			param2 = 0,
			name = "air",
			prob = 254
		},
		{
			param2 = 0,
			name = "air",
			prob = 254
		},
		{
			param2 = 0,
			name = "air",
			prob = 254
		},
		{
			param2 = 0,
			name = "air",
			prob = 254
		},
		{
			param2 = 0,
			name = "air",
			prob = 254
		},
		{
			param2 = 0,
			name = "air",
			prob = 254
		},
		{
			param2 = 0,
			name = "air",
			prob = 254
		},
		{
			param2 = 0,
			name = "air",
			prob = 254
		},
		{
			param2 = 0,
			name = "air",
			prob = 254
		},
		{
			param2 = 0,
			name = "air",
			prob = 254
		},
		{
			param2 = 0,
			name = "air",
			prob = 254
		},
		{
			param2 = 0,
			name = "air",
			prob = 254
		},
		{
			param2 = 0,
			name = "air",
			prob = 254
		},
		{
			param2 = 0,
			name = "air",
			prob = 254
		},
		{
			param2 = 0,
			name = "air",
			prob = 254
		},
		{
			param2 = 0,
			name = "air",
			prob = 254
		},
		{
			param2 = 0,
			name = "air",
			prob = 254
		},
		{
			param2 = 0,
			name = "air",
			prob = 254
		},
		{
			param2 = 0,
			name = "air",
			prob = 254
		},
		{
			param2 = 0,
			name = "air",
			prob = 254
		},
		{
			param2 = 0,
			name = "air",
			prob = 254
		},
		{
			param2 = 0,
			name = "air",
			prob = 254
		},
		{
			param2 = 0,
			name = "air",
			prob = 254
		},
		{
			param2 = 0,
			name = "air",
			prob = 254
		},
		{
			param2 = 0,
			name = "air",
			prob = 254
		},
		{
			param2 = 0,
			name = "air",
			prob = 254
		},
		{
			param2 = 0,
			name = "air",
			prob = 254
		},
		{
			param2 = 0,
			name = "air",
			prob = 254
		},
		{
			param2 = 0,
			name = "air",
			prob = 254
		},
		{
			param2 = 0,
			name = "air",
			prob = 254
		},
		{
			param2 = 0,
			name = "air",
			prob = 254
		},
		{
			param2 = 0,
			name = "air",
			prob = 254
		},
		{
			param2 = 0,
			name = "air",
			prob = 254
		},
		{
			param2 = 0,
			name = "air",
			prob = 254
		},
		{
			param2 = 0,
			name = "air",
			prob = 254
		},
		{
			param2 = 0,
			name = "air",
			prob = 254
		},
		{
			param2 = 0,
			name = "air",
			prob = 254
		},
		{
			param2 = 0,
			name = "air",
			prob = 254
		},
		{
			param2 = 0,
			name = "air",
			prob = 254
		},
		{
			param2 = 0,
			name = "air",
			prob = 254
		},
		{
			param2 = 0,
			name = "air",
			prob = 254
		},
		{
			param2 = 0,
			name = "air",
			prob = 254
		},
		{
			param2 = 0,
			name = "air",
			prob = 254
		},
		{
			param2 = 0,
			name = "air",
			prob = 254
		},
		{
			param2 = 0,
			name = "air",
			prob = 254
		},
		{
			param2 = 0,
			name = "air",
			prob = 254
		},
		{
			param2 = 0,
			name = "air",
			prob = 254
		},
		{
			param2 = 0,
			name = "air",
			prob = 254
		},
		{
			param2 = 0,
			name = "air",
			prob = 254
		},
		{
			param2 = 0,
			name = "air",
			prob = 254
		},
		{
			param2 = 0,
			name = "air",
			prob = 254
		},
		{
			param2 = 0,
			name = "air",
			prob = 254
		},
		{
			param2 = 0,
			name = "air",
			prob = 254
		},
		{
			param2 = 0,
			name = "air",
			prob = 254
		},
		{
			param2 = 0,
			name = "air",
			prob = 254
		},
		{
			param2 = 0,
			name = "air",
			prob = 254
		},
		{
			param2 = 0,
			name = "air",
			prob = 254
		},
		{
			param2 = 0,
			name = "air",
			prob = 254
		},
		{
			param2 = 0,
			name = "air",
			prob = 254
		},
		{
			param2 = 0,
			name = "air",
			prob = 254
		},
		{
			param2 = 0,
			name = "air",
			prob = 254
		},
		{
			param2 = 0,
			name = "air",
			prob = 254
		},
		{
			param2 = 0,
			name = "air",
			prob = 254
		},
		{
			param2 = 0,
			name = "air",
			prob = 254
		},
		{
			param2 = 0,
			name = "air",
			prob = 254
		},
		{
			param2 = 0,
			name = "air",
			prob = 254
		},
		{
			param2 = 0,
			name = "air",
			prob = 254
		},
		{
			param2 = 0,
			name = "air",
			prob = 254
		},
		{
			param2 = 0,
			name = "air",
			prob = 254
		},
		{
			param2 = 0,
			name = "air",
			prob = 254
		},
		{
			param2 = 0,
			name = "air",
			prob = 254
		},
		{
			param2 = 0,
			name = "air",
			prob = 254
		},
		{
			param2 = 0,
			name = "air",
			prob = 254
		},
		{
			param2 = 0,
			name = "air",
			prob = 254
		},
		{
			param2 = 0,
			name = "air",
			prob = 254
		},
		{
			param2 = 0,
			name = "air",
			prob = 254
		},
		{
			param2 = 0,
			name = "air",
			prob = 254
		},
		{
			param2 = 0,
			name = "air",
			prob = 254
		},
		{
			param2 = 0,
			name = "air",
			prob = 254
		},
		{
			param2 = 0,
			name = "air",
			prob = 254
		},
		{
			param2 = 0,
			name = "air",
			prob = 254
		},
		{
			param2 = 0,
			name = "air",
			prob = 254
		},
		{
			param2 = 0,
			name = "air",
			prob = 254
		},
		{
			param2 = 0,
			name = "air",
			prob = 254
		},
		{
			param2 = 0,
			name = "air",
			prob = 254
		},
		{
			param2 = 0,
			name = "air",
			prob = 254
		},
		{
			param2 = 0,
			name = "air",
			prob = 254
		},
		{
			param2 = 0,
			name = "air",
			prob = 254
		},
		{
			param2 = 0,
			name = "air",
			prob = 254
		},
		{
			param2 = 0,
			name = "air",
			prob = 254
		},
		{
			param2 = 0,
			name = "air",
			prob = 254
		},
		{
			param2 = 0,
			name = "air",
			prob = 254
		},
		{
			param2 = 0,
			name = "air",
			prob = 254
		},
		{
			param2 = 0,
			name = "air",
			prob = 254
		},
		{
			param2 = 0,
			name = "air",
			prob = 254
		},
		{
			param2 = 0,
			name = "air",
			prob = 254
		},
		{
			param2 = 0,
			name = "air",
			prob = 254
		},
		{
			param2 = 0,
			name = "air",
			prob = 254
		},
		{
			param2 = 0,
			name = "air",
			prob = 254
		},
		{
			param2 = 0,
			name = "air",
			prob = 254
		},
		{
			param2 = 0,
			name = "air",
			prob = 254
		},
		{
			param2 = 0,
			name = "air",
			prob = 254
		},
		{
			param2 = 0,
			name = "air",
			prob = 254
		},
		{
			param2 = 0,
			name = "air",
			prob = 254
		},
		{
			param2 = 0,
			name = "air",
			prob = 254
		},
		{
			param2 = 0,
			name = "air",
			prob = 254
		},
		{
			param2 = 0,
			name = "air",
			prob = 254
		},
		{
			param2 = 0,
			name = "air",
			prob = 254
		},
		{
			param2 = 0,
			name = "air",
			prob = 254
		},
		{
			param2 = 0,
			name = "air",
			prob = 254
		},
		{
			param2 = 0,
			name = "air",
			prob = 254
		},
		{
			param2 = 0,
			name = "air",
			prob = 254
		},
		{
			param2 = 0,
			name = "air",
			prob = 254
		},
		{
			param2 = 0,
			name = "air",
			prob = 254
		},
		{
			param2 = 0,
			name = "air",
			prob = 254
		},
		{
			param2 = 0,
			name = "air",
			prob = 254
		},
		{
			param2 = 0,
			name = "air",
			prob = 254
		},
		{
			param2 = 0,
			name = "air",
			prob = 254
		},
		{
			param2 = 0,
			name = "air",
			prob = 254
		},
		{
			param2 = 0,
			name = "air",
			prob = 254
		},
		{
			param2 = 0,
			name = "air",
			prob = 254
		},
		{
			param2 = 0,
			name = "air",
			prob = 254
		},
		{
			param2 = 0,
			name = "air",
			prob = 254
		},
		{
			param2 = 0,
			name = "air",
			prob = 254
		},
		{
			param2 = 0,
			name = "air",
			prob = 254
		},
		{
			param2 = 0,
			name = "air",
			prob = 254
		},
		{
			param2 = 0,
			name = "air",
			prob = 254
		},
		{
			param2 = 0,
			name = "air",
			prob = 254
		},
		{
			param2 = 0,
			name = "air",
			prob = 254
		},
		{
			param2 = 0,
			name = "air",
			prob = 254
		},
		{
			param2 = 0,
			name = "air",
			prob = 254
		},
		{
			param2 = 0,
			name = "air",
			prob = 254
		},
		{
			param2 = 0,
			name = "air",
			prob = 254
		},
		{
			param2 = 0,
			name = "air",
			prob = 254
		},
		{
			param2 = 0,
			name = "air",
			prob = 254
		},
		{
			param2 = 0,
			name = "air",
			prob = 254
		},
		{
			param2 = 0,
			name = "air",
			prob = 254
		},
		{
			param2 = 0,
			name = "air",
			prob = 254
		},
		{
			param2 = 0,
			name = "air",
			prob = 254
		},
		{
			param2 = 0,
			name = "air",
			prob = 254
		},
		{
			param2 = 0,
			name = "air",
			prob = 254
		},
		{
			param2 = 0,
			name = "air",
			prob = 254
		},
		{
			param2 = 0,
			name = "air",
			prob = 254
		},
		{
			param2 = 0,
			name = "air",
			prob = 254
		},
		{
			param2 = 0,
			name = "air",
			prob = 254
		},
		{
			param2 = 0,
			name = "air",
			prob = 254
		},
		{
			param2 = 0,
			name = "air",
			prob = 254
		},
		{
			param2 = 0,
			name = "air",
			prob = 254
		},
		{
			param2 = 0,
			name = "air",
			prob = 254
		},
		{
			param2 = 0,
			name = "air",
			prob = 254
		},
		{
			param2 = 0,
			name = "air",
			prob = 254
		},
		{
			param2 = 0,
			name = "air",
			prob = 254
		},
		{
			param2 = 0,
			name = "air",
			prob = 254
		},
		{
			param2 = 0,
			name = "air",
			prob = 254
		},
		{
			param2 = 0,
			name = "air",
			prob = 254
		},
		{
			param2 = 0,
			name = "air",
			prob = 254
		},
		{
			param2 = 0,
			name = "air",
			prob = 254
		},
		{
			param2 = 0,
			name = "air",
			prob = 254
		},
		{
			param2 = 0,
			name = "air",
			prob = 254
		},
		{
			param2 = 0,
			name = "air",
			prob = 254
		},
		{
			param2 = 0,
			name = "air",
			prob = 254
		},
		{
			param2 = 0,
			name = "air",
			prob = 254
		},
		{
			param2 = 0,
			name = "air",
			prob = 254
		},
		{
			param2 = 0,
			name = "air",
			prob = 254
		},
		{
			param2 = 0,
			name = "air",
			prob = 254
		},
		{
			param2 = 0,
			name = "air",
			prob = 254
		},
		{
			param2 = 0,
			name = "air",
			prob = 254
		},
		{
			param2 = 0,
			name = "air",
			prob = 254
		},
		{
			param2 = 0,
			name = "air",
			prob = 254
		},
		{
			param2 = 0,
			name = "air",
			prob = 254
		},
		{
			param2 = 0,
			name = "air",
			prob = 254
		},
		{
			param2 = 0,
			name = "air",
			prob = 254
		},
		{
			param2 = 0,
			name = "air",
			prob = 254
		},
		{
			param2 = 0,
			name = "air",
			prob = 254
		},
		{
			param2 = 0,
			name = "air",
			prob = 254
		},
		{
			param2 = 0,
			name = "air",
			prob = 254
		},
		{
			param2 = 0,
			name = "air",
			prob = 254
		},
		{
			param2 = 0,
			name = "air",
			prob = 254
		},
		{
			param2 = 0,
			name = "air",
			prob = 254
		},
		{
			param2 = 0,
			name = "air",
			prob = 254
		},
		{
			param2 = 0,
			name = "air",
			prob = 254
		},
		{
			param2 = 0,
			name = "air",
			prob = 254
		},
		{
			param2 = 0,
			name = "air",
			prob = 254
		},
		{
			param2 = 0,
			name = "air",
			prob = 254
		},
		{
			param2 = 0,
			name = "air",
			prob = 254
		},
		{
			param2 = 0,
			name = "air",
			prob = 254
		},
		{
			param2 = 0,
			name = "air",
			prob = 254
		},
		{
			param2 = 0,
			name = "air",
			prob = 254
		},
		{
			param2 = 0,
			name = "air",
			prob = 254
		},
		{
			param2 = 0,
			name = "air",
			prob = 254
		},
		{
			param2 = 0,
			name = "air",
			prob = 254
		},
		{
			param2 = 0,
			name = "default:sandstonebrick",
			prob = 254
		},
		{
			param2 = 0,
			name = "default:sandstonebrick",
			prob = 254
		},
		{
			param2 = 0,
			name = "default:sandstonebrick",
			prob = 254
		},
		{
			param2 = 0,
			name = "default:sandstonebrick",
			prob = 254
		},
		{
			param2 = 0,
			name = "default:sandstonebrick",
			prob = 254
		},
		{
			param2 = 0,
			name = "default:sandstonebrick",
			prob = 254
		},
		{
			param2 = 0,
			name = "default:sandstonebrick",
			prob = 254
		},
		{
			param2 = 0,
			name = "default:sandstonebrick",
			prob = 254
		},
		{
			param2 = 0,
			name = "default:sandstonebrick",
			prob = 254
		},
		{
			param2 = 0,
			name = "default:sandstonebrick",
			prob = 254
		},
		{
			param2 = 0,
			name = "default:sandstonebrick",
			prob = 254
		},
		{
			param2 = 0,
			name = "default:sandstonebrick",
			prob = 254
		},
		{
			param2 = 0,
			name = "default:sandstonebrick",
			prob = 254
		},
		{
			param2 = 0,
			name = "default:sandstonebrick",
			prob = 254
		},
		{
			param2 = 0,
			name = "default:sandstonebrick",
			prob = 254
		},
		{
			param2 = 0,
			name = "default:sandstonebrick",
			prob = 254
		},
		{
			param2 = 0,
			name = "default:sandstonebrick",
			prob = 254
		},
		{
			param2 = 0,
			name = "default:sandstonebrick",
			prob = 254
		},
		{
			param2 = 0,
			name = "default:sandstonebrick",
			prob = 254
		},
		{
			param2 = 0,
			name = "default:sandstonebrick",
			prob = 254
		},
		{
			param2 = 0,
			name = "default:sandstonebrick",
			prob = 254
		},
		{
			param2 = 0,
			name = "default:sandstonebrick",
			prob = 254
		},
		{
			param2 = 0,
			name = "default:sandstonebrick",
			prob = 254
		},
		{
			param2 = 0,
			name = "default:sandstonebrick",
			prob = 254
		},
		{
			param2 = 0,
			name = "default:sandstonebrick",
			prob = 254
		},
		{
			param2 = 0,
			name = "default:sandstonebrick",
			prob = 254
		},
		{
			param2 = 0,
			name = "default:sandstonebrick",
			prob = 254
		},
		{
			param2 = 0,
			name = "default:sandstonebrick",
			prob = 254
		},
		{
			param2 = 0,
			name = "default:sandstonebrick",
			prob = 254
		},
		{
			param2 = 0,
			name = "default:sandstonebrick",
			prob = 254
		},
		{
			param2 = 0,
			name = "default:sandstonebrick",
			prob = 254
		},
		{
			param2 = 0,
			name = "default:sandstonebrick",
			prob = 254
		},
		{
			param2 = 0,
			name = "default:sandstonebrick",
			prob = 254
		},
		{
			param2 = 0,
			name = "default:sandstonebrick",
			prob = 254
		},
		{
			param2 = 0,
			name = "default:sandstonebrick",
			prob = 254
		},
		{
			param2 = 0,
			name = "default:sandstonebrick",
			prob = 254
		},
		{
			param2 = 0,
			name = "default:sandstonebrick",
			prob = 254
		},
		{
			param2 = 0,
			name = "default:sandstonebrick",
			prob = 254
		},
		{
			param2 = 0,
			name = "default:sandstonebrick",
			prob = 254
		},
		{
			param2 = 0,
			name = "default:sandstonebrick",
			prob = 254
		},
		{
			param2 = 0,
			name = "default:sandstonebrick",
			prob = 254
		},
		{
			param2 = 0,
			name = "default:sandstonebrick",
			prob = 254
		},
		{
			param2 = 0,
			name = "air",
			prob = 254
		},
		{
			param2 = 0,
			name = "default:sandstone_block",
			prob = 254
		},
		{
			param2 = 0,
			name = "default:sandstonebrick",
			prob = 254
		},
		{
			param2 = 0,
			name = "default:sandstonebrick",
			prob = 254
		},
		{
			param2 = 0,
			name = "default:sandstonebrick",
			prob = 254
		},
		{
			param2 = 0,
			name = "default:sandstonebrick",
			prob = 254
		},
		{
			param2 = 0,
			name = "default:sandstonebrick",
			prob = 254
		},
		{
			param2 = 0,
			name = "default:sandstonebrick",
			prob = 254
		},
		{
			param2 = 0,
			name = "default:sandstonebrick",
			prob = 254
		},
		{
			param2 = 0,
			name = "default:sandstonebrick",
			prob = 254
		},
		{
			param2 = 0,
			name = "default:sandstone_block",
			prob = 254
		},
		{
			param2 = 0,
			name = "default:sandstonebrick",
			prob = 254
		},
		{
			param2 = 0,
			name = "default:sandstonebrick",
			prob = 254
		},
		{
			param2 = 0,
			name = "default:sandstonebrick",
			prob = 254
		},
		{
			param2 = 0,
			name = "default:sandstonebrick",
			prob = 254
		},
		{
			param2 = 0,
			name = "default:sandstonebrick",
			prob = 254
		},
		{
			param2 = 0,
			name = "default:sandstonebrick",
			prob = 254
		},
		{
			param2 = 0,
			name = "default:sandstonebrick",
			prob = 254
		},
		{
			param2 = 0,
			name = "default:sandstonebrick",
			prob = 254
		},
		{
			param2 = 0,
			name = "default:sandstone_block",
			prob = 254
		},
		{
			param2 = 0,
			name = "air",
			prob = 254
		},
		{
			param2 = 0,
			name = "air",
			prob = 254
		},
		{
			param2 = 0,
			name = "air",
			prob = 254
		},
		{
			param2 = 0,
			name = "air",
			prob = 254
		},
		{
			param2 = 0,
			name = "air",
			prob = 254
		},
		{
			param2 = 0,
			name = "air",
			prob = 254
		},
		{
			param2 = 0,
			name = "air",
			prob = 254
		},
		{
			param2 = 0,
			name = "air",
			prob = 254
		},
		{
			param2 = 0,
			name = "air",
			prob = 254
		},
		{
			param2 = 0,
			name = "air",
			prob = 254
		},
		{
			param2 = 0,
			name = "air",
			prob = 254
		},
		{
			param2 = 0,
			name = "air",
			prob = 254
		},
		{
			param2 = 0,
			name = "air",
			prob = 254
		},
		{
			param2 = 0,
			name = "air",
			prob = 254
		},
		{
			param2 = 0,
			name = "air",
			prob = 254
		},
		{
			param2 = 0,
			name = "air",
			prob = 254
		},
		{
			param2 = 0,
			name = "air",
			prob = 254
		},
		{
			param2 = 0,
			name = "air",
			prob = 254
		},
		{
			param2 = 0,
			name = "air",
			prob = 254
		},
		{
			param2 = 0,
			name = "air",
			prob = 254
		},
		{
			param2 = 0,
			name = "air",
			prob = 254
		},
		{
			param2 = 0,
			name = "air",
			prob = 254
		},
		{
			param2 = 0,
			name = "air",
			prob = 254
		},
		{
			param2 = 0,
			name = "air",
			prob = 254
		},
		{
			param2 = 0,
			name = "air",
			prob = 254
		},
		{
			param2 = 0,
			name = "air",
			prob = 254
		},
		{
			param2 = 0,
			name = "air",
			prob = 254
		},
		{
			param2 = 0,
			name = "air",
			prob = 254
		},
		{
			param2 = 0,
			name = "air",
			prob = 254
		},
		{
			param2 = 0,
			name = "air",
			prob = 254
		},
		{
			param2 = 0,
			name = "air",
			prob = 254
		},
		{
			param2 = 0,
			name = "air",
			prob = 254
		},
		{
			param2 = 0,
			name = "air",
			prob = 254
		},
		{
			param2 = 0,
			name = "air",
			prob = 254
		},
		{
			param2 = 0,
			name = "air",
			prob = 254
		},
		{
			param2 = 0,
			name = "air",
			prob = 254
		},
		{
			param2 = 0,
			name = "air",
			prob = 254
		},
		{
			param2 = 0,
			name = "air",
			prob = 254
		},
		{
			param2 = 0,
			name = "air",
			prob = 254
		},
		{
			param2 = 0,
			name = "air",
			prob = 254
		},
		{
			param2 = 0,
			name = "air",
			prob = 254
		},
		{
			param2 = 0,
			name = "air",
			prob = 254
		},
		{
			param2 = 0,
			name = "air",
			prob = 254
		},
		{
			param2 = 0,
			name = "air",
			prob = 254
		},
		{
			param2 = 0,
			name = "air",
			prob = 254
		},
		{
			param2 = 0,
			name = "air",
			prob = 254
		},
		{
			param2 = 0,
			name = "air",
			prob = 254
		},
		{
			param2 = 0,
			name = "air",
			prob = 254
		},
		{
			param2 = 0,
			name = "air",
			prob = 254
		},
		{
			param2 = 0,
			name = "air",
			prob = 254
		},
		{
			param2 = 0,
			name = "air",
			prob = 254
		},
		{
			param2 = 0,
			name = "air",
			prob = 254
		},
		{
			param2 = 0,
			name = "air",
			prob = 254
		},
		{
			param2 = 0,
			name = "air",
			prob = 254
		},
		{
			param2 = 0,
			name = "air",
			prob = 254
		},
		{
			param2 = 0,
			name = "air",
			prob = 254
		},
		{
			param2 = 0,
			name = "air",
			prob = 254
		},
		{
			param2 = 0,
			name = "air",
			prob = 254
		},
		{
			param2 = 0,
			name = "air",
			prob = 254
		},
		{
			param2 = 0,
			name = "air",
			prob = 254
		},
		{
			param2 = 0,
			name = "air",
			prob = 254
		},
		{
			param2 = 0,
			name = "air",
			prob = 254
		},
		{
			param2 = 0,
			name = "air",
			prob = 254
		},
		{
			param2 = 0,
			name = "air",
			prob = 254
		},
		{
			param2 = 0,
			name = "air",
			prob = 254
		},
		{
			param2 = 0,
			name = "air",
			prob = 254
		},
		{
			param2 = 0,
			name = "air",
			prob = 254
		},
		{
			param2 = 0,
			name = "air",
			prob = 254
		},
		{
			param2 = 0,
			name = "air",
			prob = 254
		},
		{
			param2 = 0,
			name = "air",
			prob = 254
		},
		{
			param2 = 0,
			name = "air",
			prob = 254
		},
		{
			param2 = 0,
			name = "air",
			prob = 254
		},
		{
			param2 = 0,
			name = "air",
			prob = 254
		},
		{
			param2 = 0,
			name = "air",
			prob = 254
		},
		{
			param2 = 0,
			name = "air",
			prob = 254
		},
		{
			param2 = 0,
			name = "air",
			prob = 254
		},
		{
			param2 = 0,
			name = "air",
			prob = 254
		},
		{
			param2 = 0,
			name = "air",
			prob = 254
		},
		{
			param2 = 0,
			name = "air",
			prob = 254
		},
		{
			param2 = 0,
			name = "air",
			prob = 254
		},
		{
			param2 = 0,
			name = "air",
			prob = 254
		},
		{
			param2 = 0,
			name = "air",
			prob = 254
		},
		{
			param2 = 0,
			name = "air",
			prob = 254
		},
		{
			param2 = 0,
			name = "air",
			prob = 254
		},
		{
			param2 = 0,
			name = "air",
			prob = 254
		},
		{
			param2 = 0,
			name = "air",
			prob = 254
		},
		{
			param2 = 0,
			name = "air",
			prob = 254
		},
		{
			param2 = 0,
			name = "air",
			prob = 254
		},
		{
			param2 = 0,
			name = "air",
			prob = 254
		},
		{
			param2 = 0,
			name = "air",
			prob = 254
		},
		{
			param2 = 0,
			name = "air",
			prob = 254
		},
		{
			param2 = 0,
			name = "air",
			prob = 254
		},
		{
			param2 = 0,
			name = "air",
			prob = 254
		},
		{
			param2 = 0,
			name = "air",
			prob = 254
		},
		{
			param2 = 0,
			name = "air",
			prob = 254
		},
		{
			param2 = 0,
			name = "air",
			prob = 254
		},
		{
			param2 = 0,
			name = "air",
			prob = 254
		},
		{
			param2 = 0,
			name = "air",
			prob = 254
		},
		{
			param2 = 0,
			name = "air",
			prob = 254
		},
		{
			param2 = 0,
			name = "air",
			prob = 254
		},
		{
			param2 = 0,
			name = "air",
			prob = 254
		},
		{
			param2 = 0,
			name = "air",
			prob = 254
		},
		{
			param2 = 0,
			name = "air",
			prob = 254
		},
		{
			param2 = 0,
			name = "air",
			prob = 254
		},
		{
			param2 = 0,
			name = "air",
			prob = 254
		},
		{
			param2 = 0,
			name = "air",
			prob = 254
		},
		{
			param2 = 0,
			name = "air",
			prob = 254
		},
		{
			param2 = 0,
			name = "air",
			prob = 254
		},
		{
			param2 = 0,
			name = "air",
			prob = 254
		},
		{
			param2 = 0,
			name = "air",
			prob = 254
		},
		{
			param2 = 0,
			name = "air",
			prob = 254
		},
		{
			param2 = 0,
			name = "air",
			prob = 254
		},
		{
			param2 = 0,
			name = "air",
			prob = 254
		},
		{
			param2 = 0,
			name = "air",
			prob = 254
		},
		{
			param2 = 0,
			name = "air",
			prob = 254
		},
		{
			param2 = 0,
			name = "air",
			prob = 254
		},
		{
			param2 = 0,
			name = "air",
			prob = 254
		},
		{
			param2 = 0,
			name = "air",
			prob = 254
		},
		{
			param2 = 0,
			name = "air",
			prob = 254
		},
		{
			param2 = 0,
			name = "air",
			prob = 254
		},
		{
			param2 = 0,
			name = "air",
			prob = 254
		},
		{
			param2 = 0,
			name = "air",
			prob = 254
		},
		{
			param2 = 0,
			name = "air",
			prob = 254
		},
		{
			param2 = 0,
			name = "air",
			prob = 254
		},
		{
			param2 = 0,
			name = "air",
			prob = 254
		},
		{
			param2 = 0,
			name = "air",
			prob = 254
		},
		{
			param2 = 0,
			name = "air",
			prob = 254
		},
		{
			param2 = 0,
			name = "air",
			prob = 254
		},
		{
			param2 = 0,
			name = "air",
			prob = 254
		},
		{
			param2 = 0,
			name = "air",
			prob = 254
		},
		{
			param2 = 0,
			name = "air",
			prob = 254
		},
		{
			param2 = 0,
			name = "air",
			prob = 254
		},
		{
			param2 = 0,
			name = "air",
			prob = 254
		},
		{
			param2 = 0,
			name = "air",
			prob = 254
		},
		{
			param2 = 0,
			name = "air",
			prob = 254
		},
		{
			param2 = 0,
			name = "air",
			prob = 254
		},
		{
			param2 = 0,
			name = "air",
			prob = 254
		},
		{
			param2 = 0,
			name = "air",
			prob = 254
		},
		{
			param2 = 0,
			name = "air",
			prob = 254
		},
		{
			param2 = 0,
			name = "air",
			prob = 254
		},
		{
			param2 = 0,
			name = "air",
			prob = 254
		},
		{
			param2 = 0,
			name = "air",
			prob = 254
		},
		{
			param2 = 0,
			name = "air",
			prob = 254
		},
		{
			param2 = 0,
			name = "air",
			prob = 254
		},
		{
			param2 = 0,
			name = "air",
			prob = 254
		},
		{
			param2 = 0,
			name = "air",
			prob = 254
		},
		{
			param2 = 0,
			name = "air",
			prob = 254
		},
		{
			param2 = 0,
			name = "air",
			prob = 254
		},
		{
			param2 = 0,
			name = "air",
			prob = 254
		},
		{
			param2 = 0,
			name = "air",
			prob = 254
		},
		{
			param2 = 0,
			name = "air",
			prob = 254
		},
		{
			param2 = 0,
			name = "air",
			prob = 254
		},
		{
			param2 = 0,
			name = "air",
			prob = 254
		},
		{
			param2 = 0,
			name = "air",
			prob = 254
		},
		{
			param2 = 0,
			name = "air",
			prob = 254
		},
		{
			param2 = 0,
			name = "air",
			prob = 254
		},
		{
			param2 = 0,
			name = "air",
			prob = 254
		},
		{
			param2 = 0,
			name = "air",
			prob = 254
		},
		{
			param2 = 0,
			name = "air",
			prob = 254
		},
		{
			param2 = 0,
			name = "air",
			prob = 254
		},
		{
			param2 = 0,
			name = "air",
			prob = 254
		},
		{
			param2 = 0,
			name = "air",
			prob = 254
		},
		{
			param2 = 0,
			name = "air",
			prob = 254
		},
		{
			param2 = 0,
			name = "air",
			prob = 254
		},
		{
			param2 = 0,
			name = "air",
			prob = 254
		},
		{
			param2 = 0,
			name = "air",
			prob = 254
		},
		{
			param2 = 0,
			name = "air",
			prob = 254
		},
		{
			param2 = 0,
			name = "air",
			prob = 254
		},
		{
			param2 = 0,
			name = "air",
			prob = 254
		},
		{
			param2 = 0,
			name = "air",
			prob = 254
		},
		{
			param2 = 0,
			name = "air",
			prob = 254
		},
		{
			param2 = 0,
			name = "air",
			prob = 254
		},
		{
			param2 = 0,
			name = "air",
			prob = 254
		},
		{
			param2 = 0,
			name = "air",
			prob = 254
		},
		{
			param2 = 0,
			name = "air",
			prob = 254
		},
		{
			param2 = 0,
			name = "air",
			prob = 254
		},
		{
			param2 = 0,
			name = "air",
			prob = 254
		},
		{
			param2 = 0,
			name = "air",
			prob = 254
		},
		{
			param2 = 0,
			name = "air",
			prob = 254
		},
		{
			param2 = 0,
			name = "air",
			prob = 254
		},
		{
			param2 = 0,
			name = "air",
			prob = 254
		},
		{
			param2 = 0,
			name = "air",
			prob = 254
		},
		{
			param2 = 0,
			name = "air",
			prob = 254
		},
		{
			param2 = 0,
			name = "air",
			prob = 254
		},
		{
			param2 = 0,
			name = "air",
			prob = 254
		},
		{
			param2 = 0,
			name = "air",
			prob = 254
		},
		{
			param2 = 0,
			name = "air",
			prob = 254
		},
		{
			param2 = 0,
			name = "air",
			prob = 254
		},
		{
			param2 = 0,
			name = "air",
			prob = 254
		},
		{
			param2 = 0,
			name = "air",
			prob = 254
		},
		{
			param2 = 0,
			name = "default:sandstonebrick",
			prob = 254
		},
		{
			param2 = 0,
			name = "default:sandstonebrick",
			prob = 254
		},
		{
			param2 = 0,
			name = "default:sandstonebrick",
			prob = 254
		},
		{
			param2 = 0,
			name = "default:sandstonebrick",
			prob = 254
		},
		{
			param2 = 0,
			name = "default:sandstonebrick",
			prob = 254
		},
		{
			param2 = 0,
			name = "default:sandstonebrick",
			prob = 254
		},
		{
			param2 = 0,
			name = "default:sandstonebrick",
			prob = 254
		},
		{
			param2 = 0,
			name = "default:sandstonebrick",
			prob = 254
		},
		{
			param2 = 0,
			name = "default:sandstonebrick",
			prob = 254
		},
		{
			param2 = 0,
			name = "default:sandstonebrick",
			prob = 254
		},
		{
			param2 = 0,
			name = "default:sandstonebrick",
			prob = 254
		},
		{
			param2 = 0,
			name = "default:sandstonebrick",
			prob = 254
		},
		{
			param2 = 0,
			name = "default:sandstonebrick",
			prob = 254
		},
		{
			param2 = 0,
			name = "default:sandstonebrick",
			prob = 254
		},
		{
			param2 = 0,
			name = "default:sandstonebrick",
			prob = 254
		},
		{
			param2 = 0,
			name = "default:sandstonebrick",
			prob = 254
		},
		{
			param2 = 0,
			name = "default:sandstonebrick",
			prob = 254
		},
		{
			param2 = 0,
			name = "default:sandstonebrick",
			prob = 254
		},
		{
			param2 = 0,
			name = "default:sandstonebrick",
			prob = 254
		},
		{
			param2 = 0,
			name = "default:sandstonebrick",
			prob = 254
		},
		{
			param2 = 0,
			name = "default:sandstonebrick",
			prob = 254
		},
		{
			param2 = 0,
			name = "default:sandstonebrick",
			prob = 254
		},
		{
			param2 = 0,
			name = "default:sandstonebrick",
			prob = 254
		},
		{
			param2 = 0,
			name = "default:sandstonebrick",
			prob = 254
		},
		{
			param2 = 0,
			name = "default:sandstonebrick",
			prob = 254
		},
		{
			param2 = 0,
			name = "default:sandstonebrick",
			prob = 254
		},
		{
			param2 = 0,
			name = "default:sandstonebrick",
			prob = 254
		},
		{
			param2 = 0,
			name = "default:sandstonebrick",
			prob = 254
		},
		{
			param2 = 0,
			name = "default:sandstonebrick",
			prob = 254
		},
		{
			param2 = 0,
			name = "default:sandstonebrick",
			prob = 254
		},
		{
			param2 = 0,
			name = "default:sandstonebrick",
			prob = 254
		},
		{
			param2 = 0,
			name = "default:sandstonebrick",
			prob = 254
		},
		{
			param2 = 0,
			name = "default:sandstonebrick",
			prob = 254
		},
		{
			param2 = 0,
			name = "default:sandstonebrick",
			prob = 254
		},
		{
			param2 = 0,
			name = "default:sandstonebrick",
			prob = 254
		},
		{
			param2 = 0,
			name = "default:sandstonebrick",
			prob = 254
		},
		{
			param2 = 0,
			name = "default:sandstonebrick",
			prob = 254
		},
		{
			param2 = 0,
			name = "default:sandstonebrick",
			prob = 254
		},
		{
			param2 = 0,
			name = "default:sandstonebrick",
			prob = 254
		},
		{
			param2 = 0,
			name = "default:sandstonebrick",
			prob = 254
		},
		{
			param2 = 0,
			name = "default:sandstonebrick",
			prob = 254
		},
		{
			param2 = 0,
			name = "default:sandstonebrick",
			prob = 254
		},
		{
			param2 = 0,
			name = "air",
			prob = 254
		},
		{
			param2 = 0,
			name = "default:sandstonebrick",
			prob = 254
		},
		{
			param2 = 0,
			name = "default:sandstonebrick",
			prob = 254
		},
		{
			param2 = 0,
			name = "default:sandstonebrick",
			prob = 254
		},
		{
			param2 = 0,
			name = "default:sandstonebrick",
			prob = 254
		},
		{
			param2 = 0,
			name = "default:sandstonebrick",
			prob = 254
		},
		{
			param2 = 0,
			name = "default:sandstonebrick",
			prob = 254
		},
		{
			param2 = 0,
			name = "default:sandstonebrick",
			prob = 254
		},
		{
			param2 = 0,
			name = "default:sandstonebrick",
			prob = 254
		},
		{
			param2 = 0,
			name = "default:sandstonebrick",
			prob = 254
		},
		{
			param2 = 0,
			name = "air",
			prob = 254
		},
		{
			param2 = 0,
			name = "default:sandstonebrick",
			prob = 254
		},
		{
			param2 = 0,
			name = "default:sandstonebrick",
			prob = 254
		},
		{
			param2 = 0,
			name = "default:sandstonebrick",
			prob = 254
		},
		{
			param2 = 0,
			name = "default:sandstonebrick",
			prob = 254
		},
		{
			param2 = 0,
			name = "default:sandstonebrick",
			prob = 254
		},
		{
			param2 = 0,
			name = "default:sandstonebrick",
			prob = 254
		},
		{
			param2 = 0,
			name = "default:sandstonebrick",
			prob = 254
		},
		{
			param2 = 0,
			name = "default:sandstonebrick",
			prob = 254
		},
		{
			param2 = 0,
			name = "default:sandstonebrick",
			prob = 254
		},
		{
			param2 = 0,
			name = "air",
			prob = 254
		},
		{
			param2 = 0,
			name = "air",
			prob = 254
		},
		{
			param2 = 0,
			name = "air",
			prob = 254
		},
		{
			param2 = 0,
			name = "default:sandstone_block",
			prob = 254
		},
		{
			param2 = 0,
			name = "default:sandstonebrick",
			prob = 254
		},
		{
			param2 = 0,
			name = "default:sandstonebrick",
			prob = 254
		},
		{
			param2 = 0,
			name = "default:sandstonebrick",
			prob = 254
		},
		{
			param2 = 0,
			name = "default:sandstonebrick",
			prob = 254
		},
		{
			param2 = 0,
			name = "default:sandstonebrick",
			prob = 254
		},
		{
			param2 = 0,
			name = "default:sandstonebrick",
			prob = 254
		},
		{
			param2 = 0,
			name = "default:sandstonebrick",
			prob = 254
		},
		{
			param2 = 0,
			name = "default:sandstone_block",
			prob = 254
		},
		{
			param2 = 0,
			name = "default:sandstonebrick",
			prob = 254
		},
		{
			param2 = 0,
			name = "default:sandstonebrick",
			prob = 254
		},
		{
			param2 = 0,
			name = "default:sandstonebrick",
			prob = 254
		},
		{
			param2 = 0,
			name = "default:sandstonebrick",
			prob = 254
		},
		{
			param2 = 0,
			name = "default:sandstonebrick",
			prob = 254
		},
		{
			param2 = 0,
			name = "default:sandstonebrick",
			prob = 254
		},
		{
			param2 = 0,
			name = "default:sandstonebrick",
			prob = 254
		},
		{
			param2 = 0,
			name = "default:sandstone_block",
			prob = 254
		},
		{
			param2 = 0,
			name = "air",
			prob = 254
		},
		{
			param2 = 0,
			name = "air",
			prob = 254
		},
		{
			param2 = 0,
			name = "air",
			prob = 254
		},
		{
			param2 = 0,
			name = "air",
			prob = 254
		},
		{
			param2 = 0,
			name = "air",
			prob = 254
		},
		{
			param2 = 0,
			name = "air",
			prob = 254
		},
		{
			param2 = 0,
			name = "air",
			prob = 254
		},
		{
			param2 = 0,
			name = "air",
			prob = 254
		},
		{
			param2 = 0,
			name = "air",
			prob = 254
		},
		{
			param2 = 0,
			name = "air",
			prob = 254
		},
		{
			param2 = 0,
			name = "air",
			prob = 254
		},
		{
			param2 = 0,
			name = "air",
			prob = 254
		},
		{
			param2 = 0,
			name = "air",
			prob = 254
		},
		{
			param2 = 0,
			name = "air",
			prob = 254
		},
		{
			param2 = 0,
			name = "air",
			prob = 254
		},
		{
			param2 = 0,
			name = "air",
			prob = 254
		},
		{
			param2 = 0,
			name = "air",
			prob = 254
		},
		{
			param2 = 0,
			name = "air",
			prob = 254
		},
		{
			param2 = 0,
			name = "air",
			prob = 254
		},
		{
			param2 = 0,
			name = "air",
			prob = 254
		},
		{
			param2 = 0,
			name = "air",
			prob = 254
		},
		{
			param2 = 0,
			name = "air",
			prob = 254
		},
		{
			param2 = 0,
			name = "air",
			prob = 254
		},
		{
			param2 = 0,
			name = "air",
			prob = 254
		},
		{
			param2 = 0,
			name = "air",
			prob = 254
		},
		{
			param2 = 0,
			name = "air",
			prob = 254
		},
		{
			param2 = 0,
			name = "air",
			prob = 254
		},
		{
			param2 = 0,
			name = "air",
			prob = 254
		},
		{
			param2 = 0,
			name = "air",
			prob = 254
		},
		{
			param2 = 0,
			name = "air",
			prob = 254
		},
		{
			param2 = 0,
			name = "air",
			prob = 254
		},
		{
			param2 = 0,
			name = "air",
			prob = 254
		},
		{
			param2 = 0,
			name = "air",
			prob = 254
		},
		{
			param2 = 0,
			name = "air",
			prob = 254
		},
		{
			param2 = 0,
			name = "air",
			prob = 254
		},
		{
			param2 = 0,
			name = "air",
			prob = 254
		},
		{
			param2 = 0,
			name = "air",
			prob = 254
		},
		{
			param2 = 0,
			name = "air",
			prob = 254
		},
		{
			param2 = 0,
			name = "air",
			prob = 254
		},
		{
			param2 = 0,
			name = "air",
			prob = 254
		},
		{
			param2 = 0,
			name = "air",
			prob = 254
		},
		{
			param2 = 0,
			name = "air",
			prob = 254
		},
		{
			param2 = 0,
			name = "air",
			prob = 254
		},
		{
			param2 = 0,
			name = "air",
			prob = 254
		},
		{
			param2 = 0,
			name = "air",
			prob = 254
		},
		{
			param2 = 0,
			name = "air",
			prob = 254
		},
		{
			param2 = 0,
			name = "air",
			prob = 254
		},
		{
			param2 = 0,
			name = "air",
			prob = 254
		},
		{
			param2 = 0,
			name = "air",
			prob = 254
		},
		{
			param2 = 0,
			name = "air",
			prob = 254
		},
		{
			param2 = 0,
			name = "air",
			prob = 254
		},
		{
			param2 = 0,
			name = "air",
			prob = 254
		},
		{
			param2 = 0,
			name = "air",
			prob = 254
		},
		{
			param2 = 0,
			name = "air",
			prob = 254
		},
		{
			param2 = 0,
			name = "air",
			prob = 254
		},
		{
			param2 = 0,
			name = "air",
			prob = 254
		},
		{
			param2 = 0,
			name = "air",
			prob = 254
		},
		{
			param2 = 0,
			name = "air",
			prob = 254
		},
		{
			param2 = 0,
			name = "air",
			prob = 254
		},
		{
			param2 = 0,
			name = "air",
			prob = 254
		},
		{
			param2 = 0,
			name = "air",
			prob = 254
		},
		{
			param2 = 0,
			name = "air",
			prob = 254
		},
		{
			param2 = 0,
			name = "air",
			prob = 254
		},
		{
			param2 = 0,
			name = "air",
			prob = 254
		},
		{
			param2 = 0,
			name = "air",
			prob = 254
		},
		{
			param2 = 0,
			name = "air",
			prob = 254
		},
		{
			param2 = 0,
			name = "air",
			prob = 254
		},
		{
			param2 = 0,
			name = "air",
			prob = 254
		},
		{
			param2 = 0,
			name = "air",
			prob = 254
		},
		{
			param2 = 0,
			name = "air",
			prob = 254
		},
		{
			param2 = 0,
			name = "air",
			prob = 254
		},
		{
			param2 = 0,
			name = "air",
			prob = 254
		},
		{
			param2 = 0,
			name = "air",
			prob = 254
		},
		{
			param2 = 0,
			name = "air",
			prob = 254
		},
		{
			param2 = 0,
			name = "air",
			prob = 254
		},
		{
			param2 = 0,
			name = "air",
			prob = 254
		},
		{
			param2 = 0,
			name = "air",
			prob = 254
		},
		{
			param2 = 0,
			name = "air",
			prob = 254
		},
		{
			param2 = 0,
			name = "air",
			prob = 254
		},
		{
			param2 = 0,
			name = "air",
			prob = 254
		},
		{
			param2 = 0,
			name = "air",
			prob = 254
		},
		{
			param2 = 0,
			name = "air",
			prob = 254
		},
		{
			param2 = 0,
			name = "air",
			prob = 254
		},
		{
			param2 = 0,
			name = "air",
			prob = 254
		},
		{
			param2 = 0,
			name = "air",
			prob = 254
		},
		{
			param2 = 0,
			name = "air",
			prob = 254
		},
		{
			param2 = 0,
			name = "air",
			prob = 254
		},
		{
			param2 = 0,
			name = "air",
			prob = 254
		},
		{
			param2 = 0,
			name = "air",
			prob = 254
		},
		{
			param2 = 0,
			name = "air",
			prob = 254
		},
		{
			param2 = 0,
			name = "air",
			prob = 254
		},
		{
			param2 = 0,
			name = "air",
			prob = 254
		},
		{
			param2 = 0,
			name = "air",
			prob = 254
		},
		{
			param2 = 0,
			name = "air",
			prob = 254
		},
		{
			param2 = 0,
			name = "air",
			prob = 254
		},
		{
			param2 = 0,
			name = "air",
			prob = 254
		},
		{
			param2 = 0,
			name = "air",
			prob = 254
		},
		{
			param2 = 0,
			name = "air",
			prob = 254
		},
		{
			param2 = 0,
			name = "air",
			prob = 254
		},
		{
			param2 = 0,
			name = "air",
			prob = 254
		},
		{
			param2 = 0,
			name = "air",
			prob = 254
		},
		{
			param2 = 0,
			name = "air",
			prob = 254
		},
		{
			param2 = 0,
			name = "air",
			prob = 254
		},
		{
			param2 = 0,
			name = "air",
			prob = 254
		},
		{
			param2 = 0,
			name = "air",
			prob = 254
		},
		{
			param2 = 0,
			name = "air",
			prob = 254
		},
		{
			param2 = 0,
			name = "air",
			prob = 254
		},
		{
			param2 = 0,
			name = "air",
			prob = 254
		},
		{
			param2 = 0,
			name = "air",
			prob = 254
		},
		{
			param2 = 0,
			name = "air",
			prob = 254
		},
		{
			param2 = 0,
			name = "air",
			prob = 254
		},
		{
			param2 = 0,
			name = "air",
			prob = 254
		},
		{
			param2 = 0,
			name = "air",
			prob = 254
		},
		{
			param2 = 0,
			name = "air",
			prob = 254
		},
		{
			param2 = 0,
			name = "air",
			prob = 254
		},
		{
			param2 = 0,
			name = "air",
			prob = 254
		},
		{
			param2 = 0,
			name = "air",
			prob = 254
		},
		{
			param2 = 0,
			name = "air",
			prob = 254
		},
		{
			param2 = 0,
			name = "air",
			prob = 254
		},
		{
			param2 = 0,
			name = "air",
			prob = 254
		},
		{
			param2 = 0,
			name = "air",
			prob = 254
		},
		{
			param2 = 0,
			name = "air",
			prob = 254
		},
		{
			param2 = 0,
			name = "air",
			prob = 254
		},
		{
			param2 = 0,
			name = "air",
			prob = 254
		},
		{
			param2 = 0,
			name = "air",
			prob = 254
		},
		{
			param2 = 0,
			name = "air",
			prob = 254
		},
		{
			param2 = 0,
			name = "air",
			prob = 254
		},
		{
			param2 = 0,
			name = "air",
			prob = 254
		},
		{
			param2 = 0,
			name = "air",
			prob = 254
		},
		{
			param2 = 0,
			name = "air",
			prob = 254
		},
		{
			param2 = 0,
			name = "air",
			prob = 254
		},
		{
			param2 = 0,
			name = "air",
			prob = 254
		},
		{
			param2 = 0,
			name = "air",
			prob = 254
		},
		{
			param2 = 0,
			name = "air",
			prob = 254
		},
		{
			param2 = 0,
			name = "air",
			prob = 254
		},
		{
			param2 = 0,
			name = "air",
			prob = 254
		},
		{
			param2 = 0,
			name = "air",
			prob = 254
		},
		{
			param2 = 0,
			name = "air",
			prob = 254
		},
		{
			param2 = 0,
			name = "air",
			prob = 254
		},
		{
			param2 = 0,
			name = "air",
			prob = 254
		},
		{
			param2 = 0,
			name = "air",
			prob = 254
		},
		{
			param2 = 0,
			name = "air",
			prob = 254
		},
		{
			param2 = 0,
			name = "air",
			prob = 254
		},
		{
			param2 = 0,
			name = "air",
			prob = 254
		},
		{
			param2 = 0,
			name = "air",
			prob = 254
		},
		{
			param2 = 0,
			name = "air",
			prob = 254
		},
		{
			param2 = 0,
			name = "air",
			prob = 254
		},
		{
			param2 = 0,
			name = "air",
			prob = 254
		},
		{
			param2 = 0,
			name = "air",
			prob = 254
		},
		{
			param2 = 0,
			name = "air",
			prob = 254
		},
		{
			param2 = 0,
			name = "air",
			prob = 254
		},
		{
			param2 = 0,
			name = "air",
			prob = 254
		},
		{
			param2 = 0,
			name = "air",
			prob = 254
		},
		{
			param2 = 0,
			name = "air",
			prob = 254
		},
		{
			param2 = 0,
			name = "air",
			prob = 254
		},
		{
			param2 = 0,
			name = "air",
			prob = 254
		},
		{
			param2 = 0,
			name = "air",
			prob = 254
		},
		{
			param2 = 0,
			name = "air",
			prob = 254
		},
		{
			param2 = 0,
			name = "air",
			prob = 254
		},
		{
			param2 = 0,
			name = "air",
			prob = 254
		},
		{
			param2 = 0,
			name = "air",
			prob = 254
		},
		{
			param2 = 0,
			name = "air",
			prob = 254
		},
		{
			param2 = 0,
			name = "air",
			prob = 254
		},
		{
			param2 = 0,
			name = "air",
			prob = 254
		},
		{
			param2 = 0,
			name = "air",
			prob = 254
		},
		{
			param2 = 0,
			name = "air",
			prob = 254
		},
		{
			param2 = 0,
			name = "air",
			prob = 254
		},
		{
			param2 = 0,
			name = "air",
			prob = 254
		},
		{
			param2 = 0,
			name = "air",
			prob = 254
		},
		{
			param2 = 0,
			name = "air",
			prob = 254
		},
		{
			param2 = 0,
			name = "default:sandstonebrick",
			prob = 254
		},
		{
			param2 = 0,
			name = "default:sandstonebrick",
			prob = 254
		},
		{
			param2 = 0,
			name = "default:sandstonebrick",
			prob = 254
		},
		{
			param2 = 0,
			name = "default:sandstonebrick",
			prob = 254
		},
		{
			param2 = 0,
			name = "default:sandstonebrick",
			prob = 254
		},
		{
			param2 = 0,
			name = "default:sandstonebrick",
			prob = 254
		},
		{
			param2 = 0,
			name = "default:sandstonebrick",
			prob = 254
		},
		{
			param2 = 0,
			name = "default:sandstonebrick",
			prob = 254
		},
		{
			param2 = 0,
			name = "default:sandstonebrick",
			prob = 254
		},
		{
			param2 = 0,
			name = "default:sandstonebrick",
			prob = 254
		},
		{
			param2 = 0,
			name = "default:sandstonebrick",
			prob = 254
		},
		{
			param2 = 0,
			name = "default:sandstonebrick",
			prob = 254
		},
		{
			param2 = 0,
			name = "default:sandstonebrick",
			prob = 254
		},
		{
			param2 = 0,
			name = "default:sandstonebrick",
			prob = 254
		},
		{
			param2 = 0,
			name = "default:sandstonebrick",
			prob = 254
		},
		{
			param2 = 0,
			name = "default:sandstonebrick",
			prob = 254
		},
		{
			param2 = 0,
			name = "default:sandstonebrick",
			prob = 254
		},
		{
			param2 = 0,
			name = "default:sandstonebrick",
			prob = 254
		},
		{
			param2 = 0,
			name = "default:sandstonebrick",
			prob = 254
		},
		{
			param2 = 0,
			name = "default:sandstonebrick",
			prob = 254
		},
		{
			param2 = 0,
			name = "default:sandstonebrick",
			prob = 254
		},
		{
			param2 = 0,
			name = "default:sandstonebrick",
			prob = 254
		},
		{
			param2 = 0,
			name = "default:sandstonebrick",
			prob = 254
		},
		{
			param2 = 0,
			name = "default:sandstonebrick",
			prob = 254
		},
		{
			param2 = 0,
			name = "default:sandstonebrick",
			prob = 254
		},
		{
			param2 = 0,
			name = "default:sandstonebrick",
			prob = 254
		},
		{
			param2 = 0,
			name = "default:sandstonebrick",
			prob = 254
		},
		{
			param2 = 0,
			name = "default:sandstonebrick",
			prob = 254
		},
		{
			param2 = 0,
			name = "default:sandstonebrick",
			prob = 254
		},
		{
			param2 = 0,
			name = "default:sandstonebrick",
			prob = 254
		},
		{
			param2 = 0,
			name = "default:sandstonebrick",
			prob = 254
		},
		{
			param2 = 0,
			name = "default:sandstonebrick",
			prob = 254
		},
		{
			param2 = 0,
			name = "default:sandstonebrick",
			prob = 254
		},
		{
			param2 = 0,
			name = "default:sandstonebrick",
			prob = 254
		},
		{
			param2 = 0,
			name = "default:sandstonebrick",
			prob = 254
		},
		{
			param2 = 0,
			name = "default:sandstonebrick",
			prob = 254
		},
		{
			param2 = 0,
			name = "default:sandstonebrick",
			prob = 254
		},
		{
			param2 = 0,
			name = "default:sandstonebrick",
			prob = 254
		},
		{
			param2 = 0,
			name = "default:sandstonebrick",
			prob = 254
		},
		{
			param2 = 0,
			name = "default:sandstonebrick",
			prob = 254
		},
		{
			param2 = 0,
			name = "default:sandstonebrick",
			prob = 254
		},
		{
			param2 = 0,
			name = "default:sandstonebrick",
			prob = 254
		},
		{
			param2 = 0,
			name = "air",
			prob = 254
		},
		{
			param2 = 0,
			name = "default:sandstonebrick",
			prob = 254
		},
		{
			param2 = 0,
			name = "default:sandstonebrick",
			prob = 254
		},
		{
			param2 = 0,
			name = "default:sandstonebrick",
			prob = 254
		},
		{
			param2 = 0,
			name = "default:sandstonebrick",
			prob = 254
		},
		{
			param2 = 0,
			name = "default:sandstonebrick",
			prob = 254
		},
		{
			param2 = 0,
			name = "default:sandstonebrick",
			prob = 254
		},
		{
			param2 = 0,
			name = "default:sandstonebrick",
			prob = 254
		},
		{
			param2 = 0,
			name = "default:sandstonebrick",
			prob = 254
		},
		{
			param2 = 2,
			name = "decoblocks:sandstone_wall",
			prob = 254
		},
		{
			param2 = 0,
			name = "air",
			prob = 254
		},
		{
			param2 = 1,
			name = "decoblocks:sandstone_wall",
			prob = 254
		},
		{
			param2 = 0,
			name = "default:sandstonebrick",
			prob = 254
		},
		{
			param2 = 0,
			name = "default:sandstonebrick",
			prob = 254
		},
		{
			param2 = 0,
			name = "default:sandstonebrick",
			prob = 254
		},
		{
			param2 = 0,
			name = "default:sandstonebrick",
			prob = 254
		},
		{
			param2 = 0,
			name = "default:sandstonebrick",
			prob = 254
		},
		{
			param2 = 0,
			name = "default:sandstonebrick",
			prob = 254
		},
		{
			param2 = 0,
			name = "default:sandstonebrick",
			prob = 254
		},
		{
			param2 = 0,
			name = "default:sandstonebrick",
			prob = 254
		},
		{
			param2 = 0,
			name = "air",
			prob = 254
		},
		{
			param2 = 0,
			name = "air",
			prob = 254
		},
		{
			param2 = 0,
			name = "air",
			prob = 254
		},
		{
			param2 = 0,
			name = "default:sandstonebrick",
			prob = 254
		},
		{
			param2 = 0,
			name = "default:sandstonebrick",
			prob = 254
		},
		{
			param2 = 0,
			name = "default:sandstonebrick",
			prob = 254
		},
		{
			param2 = 0,
			name = "default:sandstonebrick",
			prob = 254
		},
		{
			param2 = 0,
			name = "default:sandstonebrick",
			prob = 254
		},
		{
			param2 = 0,
			name = "default:sandstonebrick",
			prob = 254
		},
		{
			param2 = 0,
			name = "default:sandstonebrick",
			prob = 254
		},
		{
			param2 = 1,
			name = "decoblocks:sandstone_wall",
			prob = 254
		},
		{
			param2 = 0,
			name = "air",
			prob = 254
		},
		{
			param2 = 0,
			name = "decoblocks:sandstone_wall",
			prob = 254
		},
		{
			param2 = 0,
			name = "default:sandstonebrick",
			prob = 254
		},
		{
			param2 = 0,
			name = "default:sandstonebrick",
			prob = 254
		},
		{
			param2 = 0,
			name = "default:sandstonebrick",
			prob = 254
		},
		{
			param2 = 0,
			name = "default:sandstonebrick",
			prob = 254
		},
		{
			param2 = 0,
			name = "default:sandstonebrick",
			prob = 254
		},
		{
			param2 = 0,
			name = "default:sandstonebrick",
			prob = 254
		},
		{
			param2 = 0,
			name = "default:sandstonebrick",
			prob = 254
		},
		{
			param2 = 0,
			name = "air",
			prob = 254
		},
		{
			param2 = 0,
			name = "air",
			prob = 254
		},
		{
			param2 = 0,
			name = "air",
			prob = 254
		},
		{
			param2 = 0,
			name = "air",
			prob = 254
		},
		{
			param2 = 0,
			name = "air",
			prob = 254
		},
		{
			param2 = 0,
			name = "default:sandstone_block",
			prob = 254
		},
		{
			param2 = 0,
			name = "default:sandstonebrick",
			prob = 254
		},
		{
			param2 = 0,
			name = "default:sandstonebrick",
			prob = 254
		},
		{
			param2 = 0,
			name = "default:sandstonebrick",
			prob = 254
		},
		{
			param2 = 0,
			name = "default:sandstonebrick",
			prob = 254
		},
		{
			param2 = 0,
			name = "default:sandstonebrick",
			prob = 254
		},
		{
			param2 = 0,
			name = "default:sandstonebrick",
			prob = 254
		},
		{
			param2 = 0,
			name = "default:sandstonebrick",
			prob = 254
		},
		{
			param2 = 0,
			name = "default:sandstonebrick",
			prob = 254
		},
		{
			param2 = 0,
			name = "default:sandstonebrick",
			prob = 254
		},
		{
			param2 = 0,
			name = "default:sandstonebrick",
			prob = 254
		},
		{
			param2 = 0,
			name = "default:sandstonebrick",
			prob = 254
		},
		{
			param2 = 0,
			name = "default:sandstonebrick",
			prob = 254
		},
		{
			param2 = 0,
			name = "default:sandstonebrick",
			prob = 254
		},
		{
			param2 = 0,
			name = "default:sandstone_block",
			prob = 254
		},
		{
			param2 = 0,
			name = "air",
			prob = 254
		},
		{
			param2 = 0,
			name = "air",
			prob = 254
		},
		{
			param2 = 0,
			name = "air",
			prob = 254
		},
		{
			param2 = 0,
			name = "air",
			prob = 254
		},
		{
			param2 = 0,
			name = "air",
			prob = 254
		},
		{
			param2 = 0,
			name = "air",
			prob = 254
		},
		{
			param2 = 0,
			name = "air",
			prob = 254
		},
		{
			param2 = 0,
			name = "air",
			prob = 254
		},
		{
			param2 = 0,
			name = "air",
			prob = 254
		},
		{
			param2 = 0,
			name = "air",
			prob = 254
		},
		{
			param2 = 0,
			name = "air",
			prob = 254
		},
		{
			param2 = 0,
			name = "air",
			prob = 254
		},
		{
			param2 = 0,
			name = "air",
			prob = 254
		},
		{
			param2 = 0,
			name = "air",
			prob = 254
		},
		{
			param2 = 0,
			name = "air",
			prob = 254
		},
		{
			param2 = 0,
			name = "air",
			prob = 254
		},
		{
			param2 = 0,
			name = "air",
			prob = 254
		},
		{
			param2 = 0,
			name = "air",
			prob = 254
		},
		{
			param2 = 0,
			name = "air",
			prob = 254
		},
		{
			param2 = 0,
			name = "air",
			prob = 254
		},
		{
			param2 = 0,
			name = "air",
			prob = 254
		},
		{
			param2 = 0,
			name = "air",
			prob = 254
		},
		{
			param2 = 0,
			name = "air",
			prob = 254
		},
		{
			param2 = 0,
			name = "air",
			prob = 254
		},
		{
			param2 = 0,
			name = "air",
			prob = 254
		},
		{
			param2 = 0,
			name = "air",
			prob = 254
		},
		{
			param2 = 0,
			name = "air",
			prob = 254
		},
		{
			param2 = 0,
			name = "air",
			prob = 254
		},
		{
			param2 = 0,
			name = "air",
			prob = 254
		},
		{
			param2 = 0,
			name = "air",
			prob = 254
		},
		{
			param2 = 0,
			name = "air",
			prob = 254
		},
		{
			param2 = 0,
			name = "air",
			prob = 254
		},
		{
			param2 = 0,
			name = "air",
			prob = 254
		},
		{
			param2 = 0,
			name = "air",
			prob = 254
		},
		{
			param2 = 0,
			name = "air",
			prob = 254
		},
		{
			param2 = 0,
			name = "air",
			prob = 254
		},
		{
			param2 = 0,
			name = "air",
			prob = 254
		},
		{
			param2 = 0,
			name = "air",
			prob = 254
		},
		{
			param2 = 0,
			name = "air",
			prob = 254
		},
		{
			param2 = 0,
			name = "air",
			prob = 254
		},
		{
			param2 = 0,
			name = "air",
			prob = 254
		},
		{
			param2 = 0,
			name = "air",
			prob = 254
		},
		{
			param2 = 0,
			name = "air",
			prob = 254
		},
		{
			param2 = 0,
			name = "air",
			prob = 254
		},
		{
			param2 = 0,
			name = "air",
			prob = 254
		},
		{
			param2 = 0,
			name = "air",
			prob = 254
		},
		{
			param2 = 0,
			name = "air",
			prob = 254
		},
		{
			param2 = 0,
			name = "air",
			prob = 254
		},
		{
			param2 = 0,
			name = "air",
			prob = 254
		},
		{
			param2 = 0,
			name = "air",
			prob = 254
		},
		{
			param2 = 0,
			name = "air",
			prob = 254
		},
		{
			param2 = 0,
			name = "air",
			prob = 254
		},
		{
			param2 = 0,
			name = "air",
			prob = 254
		},
		{
			param2 = 0,
			name = "air",
			prob = 254
		},
		{
			param2 = 0,
			name = "air",
			prob = 254
		},
		{
			param2 = 0,
			name = "air",
			prob = 254
		},
		{
			param2 = 0,
			name = "air",
			prob = 254
		},
		{
			param2 = 0,
			name = "air",
			prob = 254
		},
		{
			param2 = 0,
			name = "air",
			prob = 254
		},
		{
			param2 = 0,
			name = "air",
			prob = 254
		},
		{
			param2 = 0,
			name = "air",
			prob = 254
		},
		{
			param2 = 0,
			name = "air",
			prob = 254
		},
		{
			param2 = 0,
			name = "air",
			prob = 254
		},
		{
			param2 = 0,
			name = "air",
			prob = 254
		},
		{
			param2 = 0,
			name = "air",
			prob = 254
		},
		{
			param2 = 0,
			name = "air",
			prob = 254
		},
		{
			param2 = 0,
			name = "air",
			prob = 254
		},
		{
			param2 = 0,
			name = "air",
			prob = 254
		},
		{
			param2 = 0,
			name = "air",
			prob = 254
		},
		{
			param2 = 0,
			name = "air",
			prob = 254
		},
		{
			param2 = 0,
			name = "air",
			prob = 254
		},
		{
			param2 = 0,
			name = "air",
			prob = 254
		},
		{
			param2 = 0,
			name = "air",
			prob = 254
		},
		{
			param2 = 0,
			name = "air",
			prob = 254
		},
		{
			param2 = 0,
			name = "air",
			prob = 254
		},
		{
			param2 = 0,
			name = "air",
			prob = 254
		},
		{
			param2 = 0,
			name = "air",
			prob = 254
		},
		{
			param2 = 0,
			name = "air",
			prob = 254
		},
		{
			param2 = 0,
			name = "air",
			prob = 254
		},
		{
			param2 = 0,
			name = "air",
			prob = 254
		},
		{
			param2 = 0,
			name = "air",
			prob = 254
		},
		{
			param2 = 0,
			name = "air",
			prob = 254
		},
		{
			param2 = 0,
			name = "air",
			prob = 254
		},
		{
			param2 = 0,
			name = "air",
			prob = 254
		},
		{
			param2 = 0,
			name = "air",
			prob = 254
		},
		{
			param2 = 0,
			name = "air",
			prob = 254
		},
		{
			param2 = 0,
			name = "air",
			prob = 254
		},
		{
			param2 = 0,
			name = "air",
			prob = 254
		},
		{
			param2 = 0,
			name = "air",
			prob = 254
		},
		{
			param2 = 0,
			name = "air",
			prob = 254
		},
		{
			param2 = 0,
			name = "air",
			prob = 254
		},
		{
			param2 = 0,
			name = "air",
			prob = 254
		},
		{
			param2 = 0,
			name = "air",
			prob = 254
		},
		{
			param2 = 0,
			name = "air",
			prob = 254
		},
		{
			param2 = 0,
			name = "air",
			prob = 254
		},
		{
			param2 = 0,
			name = "air",
			prob = 254
		},
		{
			param2 = 0,
			name = "air",
			prob = 254
		},
		{
			param2 = 0,
			name = "air",
			prob = 254
		},
		{
			param2 = 0,
			name = "air",
			prob = 254
		},
		{
			param2 = 0,
			name = "air",
			prob = 254
		},
		{
			param2 = 0,
			name = "air",
			prob = 254
		},
		{
			param2 = 0,
			name = "air",
			prob = 254
		},
		{
			param2 = 0,
			name = "air",
			prob = 254
		},
		{
			param2 = 0,
			name = "air",
			prob = 254
		},
		{
			param2 = 0,
			name = "air",
			prob = 254
		},
		{
			param2 = 0,
			name = "air",
			prob = 254
		},
		{
			param2 = 0,
			name = "air",
			prob = 254
		},
		{
			param2 = 0,
			name = "air",
			prob = 254
		},
		{
			param2 = 0,
			name = "air",
			prob = 254
		},
		{
			param2 = 0,
			name = "air",
			prob = 254
		},
		{
			param2 = 0,
			name = "air",
			prob = 254
		},
		{
			param2 = 0,
			name = "air",
			prob = 254
		},
		{
			param2 = 0,
			name = "air",
			prob = 254
		},
		{
			param2 = 0,
			name = "air",
			prob = 254
		},
		{
			param2 = 0,
			name = "air",
			prob = 254
		},
		{
			param2 = 0,
			name = "air",
			prob = 254
		},
		{
			param2 = 0,
			name = "air",
			prob = 254
		},
		{
			param2 = 0,
			name = "air",
			prob = 254
		},
		{
			param2 = 0,
			name = "air",
			prob = 254
		},
		{
			param2 = 0,
			name = "air",
			prob = 254
		},
		{
			param2 = 0,
			name = "air",
			prob = 254
		},
		{
			param2 = 0,
			name = "air",
			prob = 254
		},
		{
			param2 = 0,
			name = "air",
			prob = 254
		},
		{
			param2 = 0,
			name = "air",
			prob = 254
		},
		{
			param2 = 0,
			name = "air",
			prob = 254
		},
		{
			param2 = 0,
			name = "air",
			prob = 254
		},
		{
			param2 = 0,
			name = "air",
			prob = 254
		},
		{
			param2 = 0,
			name = "air",
			prob = 254
		},
		{
			param2 = 0,
			name = "air",
			prob = 254
		},
		{
			param2 = 0,
			name = "air",
			prob = 254
		},
		{
			param2 = 0,
			name = "air",
			prob = 254
		},
		{
			param2 = 0,
			name = "air",
			prob = 254
		},
		{
			param2 = 0,
			name = "air",
			prob = 254
		},
		{
			param2 = 0,
			name = "air",
			prob = 254
		},
		{
			param2 = 0,
			name = "air",
			prob = 254
		},
		{
			param2 = 0,
			name = "air",
			prob = 254
		},
		{
			param2 = 0,
			name = "air",
			prob = 254
		},
		{
			param2 = 0,
			name = "air",
			prob = 254
		},
		{
			param2 = 0,
			name = "air",
			prob = 254
		},
		{
			param2 = 0,
			name = "air",
			prob = 254
		},
		{
			param2 = 0,
			name = "air",
			prob = 254
		},
		{
			param2 = 0,
			name = "air",
			prob = 254
		},
		{
			param2 = 0,
			name = "air",
			prob = 254
		},
		{
			param2 = 0,
			name = "air",
			prob = 254
		},
		{
			param2 = 0,
			name = "air",
			prob = 254
		},
		{
			param2 = 0,
			name = "air",
			prob = 254
		},
		{
			param2 = 0,
			name = "air",
			prob = 254
		},
		{
			param2 = 0,
			name = "air",
			prob = 254
		},
		{
			param2 = 0,
			name = "air",
			prob = 254
		},
		{
			param2 = 0,
			name = "air",
			prob = 254
		},
		{
			param2 = 0,
			name = "default:sandstonebrick",
			prob = 254
		},
		{
			param2 = 0,
			name = "default:sandstonebrick",
			prob = 254
		},
		{
			param2 = 0,
			name = "default:sandstonebrick",
			prob = 254
		},
		{
			param2 = 0,
			name = "default:sandstonebrick",
			prob = 254
		},
		{
			param2 = 0,
			name = "default:sandstonebrick",
			prob = 254
		},
		{
			param2 = 0,
			name = "default:sandstonebrick",
			prob = 254
		},
		{
			param2 = 0,
			name = "default:sandstonebrick",
			prob = 254
		},
		{
			param2 = 0,
			name = "default:sandstonebrick",
			prob = 254
		},
		{
			param2 = 0,
			name = "default:sandstonebrick",
			prob = 254
		},
		{
			param2 = 0,
			name = "default:sandstonebrick",
			prob = 254
		},
		{
			param2 = 0,
			name = "default:sandstonebrick",
			prob = 254
		},
		{
			param2 = 0,
			name = "default:sandstonebrick",
			prob = 254
		},
		{
			param2 = 0,
			name = "default:sandstonebrick",
			prob = 254
		},
		{
			param2 = 0,
			name = "default:sandstonebrick",
			prob = 254
		},
		{
			param2 = 0,
			name = "default:sandstonebrick",
			prob = 254
		},
		{
			param2 = 0,
			name = "default:sandstonebrick",
			prob = 254
		},
		{
			param2 = 0,
			name = "default:sandstonebrick",
			prob = 254
		},
		{
			param2 = 0,
			name = "default:sandstonebrick",
			prob = 254
		},
		{
			param2 = 0,
			name = "default:sandstonebrick",
			prob = 254
		},
		{
			param2 = 0,
			name = "default:sandstonebrick",
			prob = 254
		},
		{
			param2 = 0,
			name = "default:sandstonebrick",
			prob = 254
		},
		{
			param2 = 0,
			name = "default:sandstonebrick",
			prob = 254
		},
		{
			param2 = 0,
			name = "default:sandstonebrick",
			prob = 254
		},
		{
			param2 = 0,
			name = "default:sandstonebrick",
			prob = 254
		},
		{
			param2 = 0,
			name = "default:sandstonebrick",
			prob = 254
		},
		{
			param2 = 0,
			name = "default:sandstonebrick",
			prob = 254
		},
		{
			param2 = 0,
			name = "default:sandstonebrick",
			prob = 254
		},
		{
			param2 = 0,
			name = "default:sandstonebrick",
			prob = 254
		},
		{
			param2 = 0,
			name = "default:sandstonebrick",
			prob = 254
		},
		{
			param2 = 0,
			name = "default:sandstonebrick",
			prob = 254
		},
		{
			param2 = 0,
			name = "default:sandstonebrick",
			prob = 254
		},
		{
			param2 = 0,
			name = "default:sandstonebrick",
			prob = 254
		},
		{
			param2 = 0,
			name = "default:sandstonebrick",
			prob = 254
		},
		{
			param2 = 0,
			name = "default:sandstonebrick",
			prob = 254
		},
		{
			param2 = 0,
			name = "default:sandstonebrick",
			prob = 254
		},
		{
			param2 = 0,
			name = "default:sandstonebrick",
			prob = 254
		},
		{
			param2 = 0,
			name = "default:sandstonebrick",
			prob = 254
		},
		{
			param2 = 0,
			name = "default:sandstonebrick",
			prob = 254
		},
		{
			param2 = 0,
			name = "default:sandstonebrick",
			prob = 254
		},
		{
			param2 = 0,
			name = "default:sandstonebrick",
			prob = 254
		},
		{
			param2 = 0,
			name = "default:sandstonebrick",
			prob = 254
		},
		{
			param2 = 0,
			name = "default:sandstonebrick",
			prob = 254
		},
		{
			param2 = 0,
			name = "air",
			prob = 254
		},
		{
			param2 = 0,
			name = "default:sandstonebrick",
			prob = 254
		},
		{
			param2 = 0,
			name = "default:sandstonebrick",
			prob = 254
		},
		{
			param2 = 0,
			name = "default:sandstonebrick",
			prob = 254
		},
		{
			param2 = 0,
			name = "default:sandstone",
			prob = 254
		},
		{
			param2 = 0,
			name = "default:sandstone",
			prob = 254
		},
		{
			param2 = 0,
			name = "default:sandstone",
			prob = 254
		},
		{
			param2 = 0,
			name = "default:sandstone",
			prob = 254
		},
		{
			param2 = 0,
			name = "default:sandstone",
			prob = 254
		},
		{
			param2 = 0,
			name = "default:sandstone",
			prob = 254
		},
		{
			param2 = 0,
			name = "air",
			prob = 254
		},
		{
			param2 = 0,
			name = "default:sandstone",
			prob = 254
		},
		{
			param2 = 0,
			name = "default:sandstone",
			prob = 254
		},
		{
			param2 = 0,
			name = "default:sandstone",
			prob = 254
		},
		{
			param2 = 0,
			name = "default:sandstone",
			prob = 254
		},
		{
			param2 = 0,
			name = "default:sandstone",
			prob = 254
		},
		{
			param2 = 0,
			name = "default:sandstone",
			prob = 254
		},
		{
			param2 = 0,
			name = "default:sandstonebrick",
			prob = 254
		},
		{
			param2 = 0,
			name = "default:sandstonebrick",
			prob = 254
		},
		{
			param2 = 0,
			name = "default:sandstonebrick",
			prob = 254
		},
		{
			param2 = 0,
			name = "air",
			prob = 254
		},
		{
			param2 = 0,
			name = "air",
			prob = 254
		},
		{
			param2 = 0,
			name = "air",
			prob = 254
		},
		{
			param2 = 0,
			name = "default:sandstonebrick",
			prob = 254
		},
		{
			param2 = 0,
			name = "default:sandstonebrick",
			prob = 254
		},
		{
			param2 = 0,
			name = "default:sandstone",
			prob = 254
		},
		{
			param2 = 2,
			name = "decoblocks:dartblock",
			prob = 254
		},
		{
			param2 = 2,
			name = "decoblocks:dartblock",
			prob = 254
		},
		{
			param2 = 2,
			name = "decoblocks:dartblock",
			prob = 254
		},
		{
			param2 = 0,
			name = "default:sandstone",
			prob = 254
		},
		{
			param2 = 0,
			name = "default:sandstone",
			prob = 254
		},
		{
			param2 = 0,
			name = "air",
			prob = 254
		},
		{
			param2 = 0,
			name = "default:sandstone",
			prob = 254
		},
		{
			param2 = 0,
			name = "default:sandstone",
			prob = 254
		},
		{
			param2 = 2,
			name = "decoblocks:dartblock",
			prob = 254
		},
		{
			param2 = 2,
			name = "decoblocks:dartblock",
			prob = 254
		},
		{
			param2 = 2,
			name = "decoblocks:dartblock",
			prob = 254
		},
		{
			param2 = 0,
			name = "default:sandstone",
			prob = 254
		},
		{
			param2 = 0,
			name = "default:sandstonebrick",
			prob = 254
		},
		{
			param2 = 0,
			name = "default:sandstonebrick",
			prob = 254
		},
		{
			param2 = 0,
			name = "air",
			prob = 254
		},
		{
			param2 = 0,
			name = "air",
			prob = 254
		},
		{
			param2 = 0,
			name = "air",
			prob = 254
		},
		{
			param2 = 0,
			name = "air",
			prob = 254
		},
		{
			param2 = 0,
			name = "air",
			prob = 254
		},
		{
			param2 = 0,
			name = "default:sandstonebrick",
			prob = 254
		},
		{
			param2 = 0,
			name = "default:sandstonebrick",
			prob = 254
		},
		{
			param2 = 0,
			name = "default:sandstonebrick",
			prob = 254
		},
		{
			param2 = 0,
			name = "default:sandstonebrick",
			prob = 254
		},
		{
			param2 = 0,
			name = "default:sandstonebrick",
			prob = 254
		},
		{
			param2 = 0,
			name = "default:sandstonebrick",
			prob = 254
		},
		{
			param2 = 0,
			name = "default:sandstonebrick",
			prob = 254
		},
		{
			param2 = 2,
			name = "decoblocks:dartblock",
			prob = 254
		},
		{
			param2 = 0,
			name = "default:sandstonebrick",
			prob = 254
		},
		{
			param2 = 0,
			name = "default:sandstonebrick",
			prob = 254
		},
		{
			param2 = 0,
			name = "default:sandstonebrick",
			prob = 254
		},
		{
			param2 = 0,
			name = "default:sandstonebrick",
			prob = 254
		},
		{
			param2 = 0,
			name = "default:sandstonebrick",
			prob = 254
		},
		{
			param2 = 0,
			name = "default:sandstonebrick",
			prob = 254
		},
		{
			param2 = 0,
			name = "default:sandstonebrick",
			prob = 254
		},
		{
			param2 = 0,
			name = "air",
			prob = 254
		},
		{
			param2 = 0,
			name = "air",
			prob = 254
		},
		{
			param2 = 0,
			name = "air",
			prob = 254
		},
		{
			param2 = 0,
			name = "air",
			prob = 254
		},
		{
			param2 = 0,
			name = "air",
			prob = 254
		},
		{
			param2 = 0,
			name = "air",
			prob = 254
		},
		{
			param2 = 0,
			name = "air",
			prob = 254
		},
		{
			param2 = 0,
			name = "default:sandstone_block",
			prob = 254
		},
		{
			param2 = 0,
			name = "default:sandstonebrick",
			prob = 254
		},
		{
			param2 = 0,
			name = "default:sandstonebrick",
			prob = 254
		},
		{
			param2 = 0,
			name = "default:sandstonebrick",
			prob = 254
		},
		{
			param2 = 0,
			name = "default:sandstonebrick",
			prob = 254
		},
		{
			param2 = 0,
			name = "default:sandstonebrick",
			prob = 254
		},
		{
			param2 = 0,
			name = "default:sandstonebrick",
			prob = 254
		},
		{
			param2 = 0,
			name = "default:sandstonebrick",
			prob = 254
		},
		{
			param2 = 0,
			name = "default:sandstonebrick",
			prob = 254
		},
		{
			param2 = 0,
			name = "default:sandstonebrick",
			prob = 254
		},
		{
			param2 = 0,
			name = "default:sandstonebrick",
			prob = 254
		},
		{
			param2 = 0,
			name = "default:sandstonebrick",
			prob = 254
		},
		{
			param2 = 0,
			name = "default:sandstone_block",
			prob = 254
		},
		{
			param2 = 0,
			name = "air",
			prob = 254
		},
		{
			param2 = 0,
			name = "air",
			prob = 254
		},
		{
			param2 = 0,
			name = "air",
			prob = 254
		},
		{
			param2 = 0,
			name = "air",
			prob = 254
		},
		{
			param2 = 0,
			name = "air",
			prob = 254
		},
		{
			param2 = 0,
			name = "air",
			prob = 254
		},
		{
			param2 = 0,
			name = "air",
			prob = 254
		},
		{
			param2 = 0,
			name = "air",
			prob = 254
		},
		{
			param2 = 0,
			name = "air",
			prob = 254
		},
		{
			param2 = 0,
			name = "air",
			prob = 254
		},
		{
			param2 = 0,
			name = "air",
			prob = 254
		},
		{
			param2 = 0,
			name = "air",
			prob = 254
		},
		{
			param2 = 0,
			name = "air",
			prob = 254
		},
		{
			param2 = 0,
			name = "air",
			prob = 254
		},
		{
			param2 = 0,
			name = "air",
			prob = 254
		},
		{
			param2 = 0,
			name = "air",
			prob = 254
		},
		{
			param2 = 0,
			name = "air",
			prob = 254
		},
		{
			param2 = 0,
			name = "air",
			prob = 254
		},
		{
			param2 = 0,
			name = "air",
			prob = 254
		},
		{
			param2 = 0,
			name = "air",
			prob = 254
		},
		{
			param2 = 0,
			name = "air",
			prob = 254
		},
		{
			param2 = 0,
			name = "air",
			prob = 254
		},
		{
			param2 = 0,
			name = "air",
			prob = 254
		},
		{
			param2 = 0,
			name = "air",
			prob = 254
		},
		{
			param2 = 0,
			name = "air",
			prob = 254
		},
		{
			param2 = 0,
			name = "air",
			prob = 254
		},
		{
			param2 = 0,
			name = "air",
			prob = 254
		},
		{
			param2 = 0,
			name = "air",
			prob = 254
		},
		{
			param2 = 0,
			name = "air",
			prob = 254
		},
		{
			param2 = 0,
			name = "air",
			prob = 254
		},
		{
			param2 = 0,
			name = "air",
			prob = 254
		},
		{
			param2 = 0,
			name = "air",
			prob = 254
		},
		{
			param2 = 0,
			name = "air",
			prob = 254
		},
		{
			param2 = 0,
			name = "air",
			prob = 254
		},
		{
			param2 = 0,
			name = "air",
			prob = 254
		},
		{
			param2 = 0,
			name = "air",
			prob = 254
		},
		{
			param2 = 0,
			name = "air",
			prob = 254
		},
		{
			param2 = 0,
			name = "air",
			prob = 254
		},
		{
			param2 = 0,
			name = "air",
			prob = 254
		},
		{
			param2 = 0,
			name = "air",
			prob = 254
		},
		{
			param2 = 0,
			name = "air",
			prob = 254
		},
		{
			param2 = 0,
			name = "air",
			prob = 254
		},
		{
			param2 = 0,
			name = "air",
			prob = 254
		},
		{
			param2 = 0,
			name = "air",
			prob = 254
		},
		{
			param2 = 0,
			name = "air",
			prob = 254
		},
		{
			param2 = 0,
			name = "air",
			prob = 254
		},
		{
			param2 = 0,
			name = "air",
			prob = 254
		},
		{
			param2 = 0,
			name = "air",
			prob = 254
		},
		{
			param2 = 0,
			name = "air",
			prob = 254
		},
		{
			param2 = 0,
			name = "air",
			prob = 254
		},
		{
			param2 = 0,
			name = "air",
			prob = 254
		},
		{
			param2 = 0,
			name = "air",
			prob = 254
		},
		{
			param2 = 0,
			name = "air",
			prob = 254
		},
		{
			param2 = 0,
			name = "air",
			prob = 254
		},
		{
			param2 = 0,
			name = "air",
			prob = 254
		},
		{
			param2 = 0,
			name = "air",
			prob = 254
		},
		{
			param2 = 0,
			name = "air",
			prob = 254
		},
		{
			param2 = 0,
			name = "air",
			prob = 254
		},
		{
			param2 = 0,
			name = "air",
			prob = 254
		},
		{
			param2 = 0,
			name = "air",
			prob = 254
		},
		{
			param2 = 0,
			name = "air",
			prob = 254
		},
		{
			param2 = 0,
			name = "air",
			prob = 254
		},
		{
			param2 = 0,
			name = "air",
			prob = 254
		},
		{
			param2 = 0,
			name = "air",
			prob = 254
		},
		{
			param2 = 0,
			name = "air",
			prob = 254
		},
		{
			param2 = 0,
			name = "air",
			prob = 254
		},
		{
			param2 = 0,
			name = "air",
			prob = 254
		},
		{
			param2 = 0,
			name = "air",
			prob = 254
		},
		{
			param2 = 0,
			name = "air",
			prob = 254
		},
		{
			param2 = 0,
			name = "air",
			prob = 254
		},
		{
			param2 = 0,
			name = "air",
			prob = 254
		},
		{
			param2 = 0,
			name = "air",
			prob = 254
		},
		{
			param2 = 0,
			name = "air",
			prob = 254
		},
		{
			param2 = 0,
			name = "air",
			prob = 254
		},
		{
			param2 = 0,
			name = "air",
			prob = 254
		},
		{
			param2 = 0,
			name = "air",
			prob = 254
		},
		{
			param2 = 0,
			name = "air",
			prob = 254
		},
		{
			param2 = 0,
			name = "air",
			prob = 254
		},
		{
			param2 = 0,
			name = "air",
			prob = 254
		},
		{
			param2 = 0,
			name = "air",
			prob = 254
		},
		{
			param2 = 0,
			name = "air",
			prob = 254
		},
		{
			param2 = 0,
			name = "air",
			prob = 254
		},
		{
			param2 = 0,
			name = "air",
			prob = 254
		},
		{
			param2 = 0,
			name = "air",
			prob = 254
		},
		{
			param2 = 0,
			name = "air",
			prob = 254
		},
		{
			param2 = 0,
			name = "air",
			prob = 254
		},
		{
			param2 = 0,
			name = "air",
			prob = 254
		},
		{
			param2 = 0,
			name = "air",
			prob = 254
		},
		{
			param2 = 0,
			name = "air",
			prob = 254
		},
		{
			param2 = 0,
			name = "air",
			prob = 254
		},
		{
			param2 = 0,
			name = "air",
			prob = 254
		},
		{
			param2 = 0,
			name = "air",
			prob = 254
		},
		{
			param2 = 0,
			name = "air",
			prob = 254
		},
		{
			param2 = 0,
			name = "air",
			prob = 254
		},
		{
			param2 = 0,
			name = "air",
			prob = 254
		},
		{
			param2 = 0,
			name = "air",
			prob = 254
		},
		{
			param2 = 0,
			name = "air",
			prob = 254
		},
		{
			param2 = 0,
			name = "air",
			prob = 254
		},
		{
			param2 = 0,
			name = "air",
			prob = 254
		},
		{
			param2 = 0,
			name = "air",
			prob = 254
		},
		{
			param2 = 0,
			name = "air",
			prob = 254
		},
		{
			param2 = 0,
			name = "air",
			prob = 254
		},
		{
			param2 = 0,
			name = "air",
			prob = 254
		},
		{
			param2 = 0,
			name = "air",
			prob = 254
		},
		{
			param2 = 0,
			name = "air",
			prob = 254
		},
		{
			param2 = 0,
			name = "air",
			prob = 254
		},
		{
			param2 = 0,
			name = "air",
			prob = 254
		},
		{
			param2 = 0,
			name = "air",
			prob = 254
		},
		{
			param2 = 0,
			name = "air",
			prob = 254
		},
		{
			param2 = 0,
			name = "air",
			prob = 254
		},
		{
			param2 = 0,
			name = "air",
			prob = 254
		},
		{
			param2 = 0,
			name = "air",
			prob = 254
		},
		{
			param2 = 0,
			name = "air",
			prob = 254
		},
		{
			param2 = 0,
			name = "air",
			prob = 254
		},
		{
			param2 = 0,
			name = "air",
			prob = 254
		},
		{
			param2 = 0,
			name = "air",
			prob = 254
		},
		{
			param2 = 0,
			name = "air",
			prob = 254
		},
		{
			param2 = 0,
			name = "air",
			prob = 254
		},
		{
			param2 = 0,
			name = "air",
			prob = 254
		},
		{
			param2 = 0,
			name = "air",
			prob = 254
		},
		{
			param2 = 0,
			name = "air",
			prob = 254
		},
		{
			param2 = 0,
			name = "air",
			prob = 254
		},
		{
			param2 = 0,
			name = "air",
			prob = 254
		},
		{
			param2 = 0,
			name = "air",
			prob = 254
		},
		{
			param2 = 0,
			name = "air",
			prob = 254
		},
		{
			param2 = 0,
			name = "air",
			prob = 254
		},
		{
			param2 = 0,
			name = "air",
			prob = 254
		},
		{
			param2 = 0,
			name = "air",
			prob = 254
		},
		{
			param2 = 0,
			name = "air",
			prob = 254
		},
		{
			param2 = 0,
			name = "air",
			prob = 254
		},
		{
			param2 = 0,
			name = "default:sandstonebrick",
			prob = 254
		},
		{
			param2 = 0,
			name = "default:sandstonebrick",
			prob = 254
		},
		{
			param2 = 0,
			name = "default:sandstonebrick",
			prob = 254
		},
		{
			param2 = 0,
			name = "default:sandstonebrick",
			prob = 254
		},
		{
			param2 = 0,
			name = "default:sandstonebrick",
			prob = 254
		},
		{
			param2 = 0,
			name = "default:sandstonebrick",
			prob = 254
		},
		{
			param2 = 0,
			name = "default:sandstonebrick",
			prob = 254
		},
		{
			param2 = 0,
			name = "default:sandstonebrick",
			prob = 254
		},
		{
			param2 = 0,
			name = "default:sandstonebrick",
			prob = 254
		},
		{
			param2 = 0,
			name = "default:sandstonebrick",
			prob = 254
		},
		{
			param2 = 0,
			name = "default:sandstonebrick",
			prob = 254
		},
		{
			param2 = 0,
			name = "default:sandstonebrick",
			prob = 254
		},
		{
			param2 = 0,
			name = "default:sandstonebrick",
			prob = 254
		},
		{
			param2 = 0,
			name = "default:sandstonebrick",
			prob = 254
		},
		{
			param2 = 0,
			name = "default:sandstonebrick",
			prob = 254
		},
		{
			param2 = 0,
			name = "default:sandstonebrick",
			prob = 254
		},
		{
			param2 = 0,
			name = "default:sandstonebrick",
			prob = 254
		},
		{
			param2 = 0,
			name = "default:sandstonebrick",
			prob = 254
		},
		{
			param2 = 0,
			name = "default:sandstonebrick",
			prob = 254
		},
		{
			param2 = 0,
			name = "default:sandstonebrick",
			prob = 254
		},
		{
			param2 = 0,
			name = "default:sandstonebrick",
			prob = 254
		},
		{
			param2 = 0,
			name = "default:sandstonebrick",
			prob = 254
		},
		{
			param2 = 0,
			name = "default:sandstonebrick",
			prob = 254
		},
		{
			param2 = 0,
			name = "default:sandstonebrick",
			prob = 254
		},
		{
			param2 = 0,
			name = "default:sandstonebrick",
			prob = 254
		},
		{
			param2 = 0,
			name = "default:sandstonebrick",
			prob = 254
		},
		{
			param2 = 0,
			name = "default:sandstonebrick",
			prob = 254
		},
		{
			param2 = 0,
			name = "default:sandstonebrick",
			prob = 254
		},
		{
			param2 = 0,
			name = "default:sandstonebrick",
			prob = 254
		},
		{
			param2 = 0,
			name = "default:sandstonebrick",
			prob = 254
		},
		{
			param2 = 0,
			name = "default:sandstonebrick",
			prob = 254
		},
		{
			param2 = 0,
			name = "default:sandstonebrick",
			prob = 254
		},
		{
			param2 = 0,
			name = "default:sandstonebrick",
			prob = 254
		},
		{
			param2 = 0,
			name = "default:sandstonebrick",
			prob = 254
		},
		{
			param2 = 0,
			name = "default:sandstonebrick",
			prob = 254
		},
		{
			param2 = 0,
			name = "default:sandstonebrick",
			prob = 254
		},
		{
			param2 = 0,
			name = "default:sandstonebrick",
			prob = 254
		},
		{
			param2 = 0,
			name = "default:sandstonebrick",
			prob = 254
		},
		{
			param2 = 0,
			name = "default:sandstonebrick",
			prob = 254
		},
		{
			param2 = 0,
			name = "default:sandstonebrick",
			prob = 254
		},
		{
			param2 = 0,
			name = "default:sandstonebrick",
			prob = 254
		},
		{
			param2 = 0,
			name = "default:sandstonebrick",
			prob = 254
		},
		{
			param2 = 0,
			name = "air",
			prob = 254
		},
		{
			param2 = 0,
			name = "default:sandstonebrick",
			prob = 254
		},
		{
			param2 = 0,
			name = "default:sandstonebrick",
			prob = 254
		},
		{
			param2 = 0,
			name = "default:sandstonebrick",
			prob = 254
		},
		{
			param2 = 0,
			name = "default:sandstone",
			prob = 254
		},
		{
			param2 = 3,
			name = "stairs:slab_sandstone_block",
			prob = 254
		},
		{
			param2 = 0,
			name = "decoblocks:Ancient_vase_sand",
			prob = 254
		},
		{
			param2 = 0,
			name = "decoblocks:Ancient_vase_sand",
			prob = 254
		},
		{
			param2 = 3,
			name = "decoblocks:sandstone_wall",
			prob = 254
		},
		{
			param2 = 4,
			name = "stairs:slab_sandstone_block",
			prob = 254
		},
		{
			param2 = 0,
			name = "air",
			prob = 254
		},
		{
			param2 = 4,
			name = "stairs:slab_sandstone_block",
			prob = 254
		},
		{
			param2 = 3,
			name = "decoblocks:sandstone_wall",
			prob = 254
		},
		{
			param2 = 0,
			name = "decoblocks:Ancient_vase_sand",
			prob = 254
		},
		{
			param2 = 0,
			name = "decoblocks:Ancient_vase_sand",
			prob = 254
		},
		{
			param2 = 1,
			name = "stairs:slab_sandstone_block",
			prob = 254
		},
		{
			param2 = 0,
			name = "default:sandstone",
			prob = 254
		},
		{
			param2 = 0,
			name = "default:sandstonebrick",
			prob = 254
		},
		{
			param2 = 0,
			name = "default:sandstonebrick",
			prob = 254
		},
		{
			param2 = 0,
			name = "default:sandstonebrick",
			prob = 254
		},
		{
			param2 = 0,
			name = "air",
			prob = 254
		},
		{
			param2 = 0,
			name = "air",
			prob = 254
		},
		{
			param2 = 0,
			name = "air",
			prob = 254
		},
		{
			param2 = 0,
			name = "default:sandstonebrick",
			prob = 254
		},
		{
			param2 = 0,
			name = "default:sandstonebrick",
			prob = 254
		},
		{
			param2 = 0,
			name = "default:sandstone",
			prob = 254
		},
		{
			param2 = 4,
			name = "stairs:slab_sandstone_block",
			prob = 254
		},
		{
			param2 = 4,
			name = "stairs:slab_sandstone_block",
			prob = 254
		},
		{
			param2 = 4,
			name = "stairs:slab_sandstone_block",
			prob = 254
		},
		{
			param2 = 2,
			name = "decoblocks:sandstone_wall",
			prob = 254
		},
		{
			param2 = 4,
			name = "stairs:slab_sandstone_block",
			prob = 254
		},
		{
			param2 = 0,
			name = "air",
			prob = 254
		},
		{
			param2 = 4,
			name = "stairs:slab_sandstone_block",
			prob = 254
		},
		{
			param2 = 1,
			name = "decoblocks:sandstone_wall",
			prob = 254
		},
		{
			param2 = 4,
			name = "stairs:slab_sandstone_block",
			prob = 254
		},
		{
			param2 = 4,
			name = "stairs:slab_sandstone_block",
			prob = 254
		},
		{
			param2 = 4,
			name = "stairs:slab_sandstone_block",
			prob = 254
		},
		{
			param2 = 0,
			name = "default:sandstone",
			prob = 254
		},
		{
			param2 = 0,
			name = "default:sandstonebrick",
			prob = 254
		},
		{
			param2 = 0,
			name = "default:sandstonebrick",
			prob = 254
		},
		{
			param2 = 0,
			name = "air",
			prob = 254
		},
		{
			param2 = 0,
			name = "air",
			prob = 254
		},
		{
			param2 = 0,
			name = "air",
			prob = 254
		},
		{
			param2 = 0,
			name = "air",
			prob = 254
		},
		{
			param2 = 0,
			name = "air",
			prob = 254
		},
		{
			param2 = 0,
			name = "default:sandstonebrick",
			prob = 254
		},
		{
			param2 = 0,
			name = "default:sandstonebrick",
			prob = 254
		},
		{
			param2 = 0,
			name = "air",
			prob = 254
		},
		{
			param2 = 0,
			name = "air",
			prob = 254
		},
		{
			param2 = 0,
			name = "air",
			prob = 254
		},
		{
			param2 = 1,
			name = "decoblocks:sandstone_wall",
			prob = 254
		},
		{
			param2 = 4,
			name = "stairs:slab_sandstone_block",
			prob = 254
		},
		{
			param2 = 4,
			name = "stairs:slab_sandstone_block",
			prob = 254
		},
		{
			param2 = 4,
			name = "stairs:slab_sandstone_block",
			prob = 254
		},
		{
			param2 = 2,
			name = "decoblocks:sandstone_wall",
			prob = 254
		},
		{
			param2 = 0,
			name = "air",
			prob = 254
		},
		{
			param2 = 0,
			name = "air",
			prob = 254
		},
		{
			param2 = 0,
			name = "air",
			prob = 254
		},
		{
			param2 = 0,
			name = "default:sandstonebrick",
			prob = 254
		},
		{
			param2 = 0,
			name = "default:sandstonebrick",
			prob = 254
		},
		{
			param2 = 0,
			name = "air",
			prob = 254
		},
		{
			param2 = 0,
			name = "air",
			prob = 254
		},
		{
			param2 = 0,
			name = "air",
			prob = 254
		},
		{
			param2 = 0,
			name = "air",
			prob = 254
		},
		{
			param2 = 0,
			name = "air",
			prob = 254
		},
		{
			param2 = 0,
			name = "air",
			prob = 254
		},
		{
			param2 = 0,
			name = "air",
			prob = 254
		},
		{
			param2 = 0,
			name = "default:sandstonebrick",
			prob = 254
		},
		{
			param2 = 0,
			name = "default:sandstonebrick",
			prob = 254
		},
		{
			param2 = 0,
			name = "default:sandstonebrick",
			prob = 254
		},
		{
			param2 = 0,
			name = "default:sandstonebrick",
			prob = 254
		},
		{
			param2 = 0,
			name = "default:sandstonebrick",
			prob = 254
		},
		{
			param2 = 0,
			name = "default:sandstonebrick",
			prob = 254
		},
		{
			param2 = 0,
			name = "default:sandstonebrick",
			prob = 254
		},
		{
			param2 = 0,
			name = "default:sandstonebrick",
			prob = 254
		},
		{
			param2 = 0,
			name = "default:sandstonebrick",
			prob = 254
		},
		{
			param2 = 0,
			name = "default:sandstonebrick",
			prob = 254
		},
		{
			param2 = 0,
			name = "default:sandstonebrick",
			prob = 254
		},
		{
			param2 = 0,
			name = "default:sandstonebrick",
			prob = 254
		},
		{
			param2 = 0,
			name = "default:sandstonebrick",
			prob = 254
		},
		{
			param2 = 0,
			name = "air",
			prob = 254
		},
		{
			param2 = 0,
			name = "air",
			prob = 254
		},
		{
			param2 = 0,
			name = "air",
			prob = 254
		},
		{
			param2 = 0,
			name = "air",
			prob = 254
		},
		{
			param2 = 0,
			name = "air",
			prob = 254
		},
		{
			param2 = 0,
			name = "air",
			prob = 254
		},
		{
			param2 = 0,
			name = "air",
			prob = 254
		},
		{
			param2 = 0,
			name = "air",
			prob = 254
		},
		{
			param2 = 0,
			name = "air",
			prob = 254
		},
		{
			param2 = 0,
			name = "default:sandstone_block",
			prob = 254
		},
		{
			param2 = 0,
			name = "default:sandstonebrick",
			prob = 254
		},
		{
			param2 = 0,
			name = "default:sandstonebrick",
			prob = 254
		},
		{
			param2 = 0,
			name = "default:sandstonebrick",
			prob = 254
		},
		{
			param2 = 0,
			name = "default:sandstonebrick",
			prob = 254
		},
		{
			param2 = 0,
			name = "default:sandstonebrick",
			prob = 254
		},
		{
			param2 = 0,
			name = "default:sandstonebrick",
			prob = 254
		},
		{
			param2 = 0,
			name = "default:sandstonebrick",
			prob = 254
		},
		{
			param2 = 0,
			name = "default:sandstonebrick",
			prob = 254
		},
		{
			param2 = 0,
			name = "default:sandstonebrick",
			prob = 254
		},
		{
			param2 = 0,
			name = "default:sandstone_block",
			prob = 254
		},
		{
			param2 = 0,
			name = "air",
			prob = 254
		},
		{
			param2 = 0,
			name = "air",
			prob = 254
		},
		{
			param2 = 0,
			name = "air",
			prob = 254
		},
		{
			param2 = 0,
			name = "air",
			prob = 254
		},
		{
			param2 = 0,
			name = "air",
			prob = 254
		},
		{
			param2 = 0,
			name = "air",
			prob = 254
		},
		{
			param2 = 0,
			name = "air",
			prob = 254
		},
		{
			param2 = 0,
			name = "air",
			prob = 254
		},
		{
			param2 = 0,
			name = "air",
			prob = 254
		},
		{
			param2 = 0,
			name = "air",
			prob = 254
		},
		{
			param2 = 0,
			name = "air",
			prob = 254
		},
		{
			param2 = 0,
			name = "air",
			prob = 254
		},
		{
			param2 = 0,
			name = "air",
			prob = 254
		},
		{
			param2 = 0,
			name = "air",
			prob = 254
		},
		{
			param2 = 0,
			name = "air",
			prob = 254
		},
		{
			param2 = 0,
			name = "air",
			prob = 254
		},
		{
			param2 = 0,
			name = "air",
			prob = 254
		},
		{
			param2 = 0,
			name = "air",
			prob = 254
		},
		{
			param2 = 0,
			name = "air",
			prob = 254
		},
		{
			param2 = 0,
			name = "air",
			prob = 254
		},
		{
			param2 = 0,
			name = "air",
			prob = 254
		},
		{
			param2 = 0,
			name = "air",
			prob = 254
		},
		{
			param2 = 0,
			name = "air",
			prob = 254
		},
		{
			param2 = 0,
			name = "air",
			prob = 254
		},
		{
			param2 = 0,
			name = "air",
			prob = 254
		},
		{
			param2 = 0,
			name = "air",
			prob = 254
		},
		{
			param2 = 0,
			name = "air",
			prob = 254
		},
		{
			param2 = 0,
			name = "air",
			prob = 254
		},
		{
			param2 = 0,
			name = "air",
			prob = 254
		},
		{
			param2 = 0,
			name = "air",
			prob = 254
		},
		{
			param2 = 0,
			name = "air",
			prob = 254
		},
		{
			param2 = 0,
			name = "air",
			prob = 254
		},
		{
			param2 = 0,
			name = "air",
			prob = 254
		},
		{
			param2 = 0,
			name = "air",
			prob = 254
		},
		{
			param2 = 0,
			name = "air",
			prob = 254
		},
		{
			param2 = 0,
			name = "air",
			prob = 254
		},
		{
			param2 = 0,
			name = "air",
			prob = 254
		},
		{
			param2 = 0,
			name = "air",
			prob = 254
		},
		{
			param2 = 0,
			name = "air",
			prob = 254
		},
		{
			param2 = 0,
			name = "air",
			prob = 254
		},
		{
			param2 = 0,
			name = "air",
			prob = 254
		},
		{
			param2 = 0,
			name = "air",
			prob = 254
		},
		{
			param2 = 0,
			name = "air",
			prob = 254
		},
		{
			param2 = 0,
			name = "air",
			prob = 254
		},
		{
			param2 = 0,
			name = "air",
			prob = 254
		},
		{
			param2 = 0,
			name = "air",
			prob = 254
		},
		{
			param2 = 0,
			name = "air",
			prob = 254
		},
		{
			param2 = 0,
			name = "air",
			prob = 254
		},
		{
			param2 = 0,
			name = "air",
			prob = 254
		},
		{
			param2 = 0,
			name = "air",
			prob = 254
		},
		{
			param2 = 0,
			name = "air",
			prob = 254
		},
		{
			param2 = 0,
			name = "air",
			prob = 254
		},
		{
			param2 = 0,
			name = "air",
			prob = 254
		},
		{
			param2 = 0,
			name = "air",
			prob = 254
		},
		{
			param2 = 0,
			name = "air",
			prob = 254
		},
		{
			param2 = 0,
			name = "air",
			prob = 254
		},
		{
			param2 = 0,
			name = "air",
			prob = 254
		},
		{
			param2 = 0,
			name = "air",
			prob = 254
		},
		{
			param2 = 0,
			name = "air",
			prob = 254
		},
		{
			param2 = 0,
			name = "air",
			prob = 254
		},
		{
			param2 = 0,
			name = "air",
			prob = 254
		},
		{
			param2 = 0,
			name = "air",
			prob = 254
		},
		{
			param2 = 0,
			name = "air",
			prob = 254
		},
		{
			param2 = 0,
			name = "air",
			prob = 254
		},
		{
			param2 = 0,
			name = "air",
			prob = 254
		},
		{
			param2 = 0,
			name = "air",
			prob = 254
		},
		{
			param2 = 0,
			name = "air",
			prob = 254
		},
		{
			param2 = 0,
			name = "air",
			prob = 254
		},
		{
			param2 = 0,
			name = "air",
			prob = 254
		},
		{
			param2 = 0,
			name = "air",
			prob = 254
		},
		{
			param2 = 0,
			name = "air",
			prob = 254
		},
		{
			param2 = 0,
			name = "air",
			prob = 254
		},
		{
			param2 = 0,
			name = "air",
			prob = 254
		},
		{
			param2 = 0,
			name = "air",
			prob = 254
		},
		{
			param2 = 0,
			name = "air",
			prob = 254
		},
		{
			param2 = 0,
			name = "air",
			prob = 254
		},
		{
			param2 = 0,
			name = "air",
			prob = 254
		},
		{
			param2 = 0,
			name = "air",
			prob = 254
		},
		{
			param2 = 0,
			name = "air",
			prob = 254
		},
		{
			param2 = 0,
			name = "air",
			prob = 254
		},
		{
			param2 = 0,
			name = "air",
			prob = 254
		},
		{
			param2 = 0,
			name = "air",
			prob = 254
		},
		{
			param2 = 0,
			name = "air",
			prob = 254
		},
		{
			param2 = 0,
			name = "air",
			prob = 254
		},
		{
			param2 = 0,
			name = "air",
			prob = 254
		},
		{
			param2 = 0,
			name = "air",
			prob = 254
		},
		{
			param2 = 0,
			name = "air",
			prob = 254
		},
		{
			param2 = 0,
			name = "air",
			prob = 254
		},
		{
			param2 = 0,
			name = "air",
			prob = 254
		},
		{
			param2 = 0,
			name = "air",
			prob = 254
		},
		{
			param2 = 0,
			name = "air",
			prob = 254
		},
		{
			param2 = 0,
			name = "air",
			prob = 254
		},
		{
			param2 = 0,
			name = "air",
			prob = 254
		},
		{
			param2 = 0,
			name = "air",
			prob = 254
		},
		{
			param2 = 0,
			name = "air",
			prob = 254
		},
		{
			param2 = 0,
			name = "air",
			prob = 254
		},
		{
			param2 = 0,
			name = "air",
			prob = 254
		},
		{
			param2 = 0,
			name = "air",
			prob = 254
		},
		{
			param2 = 0,
			name = "air",
			prob = 254
		},
		{
			param2 = 0,
			name = "air",
			prob = 254
		},
		{
			param2 = 0,
			name = "air",
			prob = 254
		},
		{
			param2 = 0,
			name = "air",
			prob = 254
		},
		{
			param2 = 0,
			name = "air",
			prob = 254
		},
		{
			param2 = 0,
			name = "air",
			prob = 254
		},
		{
			param2 = 0,
			name = "air",
			prob = 254
		},
		{
			param2 = 0,
			name = "air",
			prob = 254
		},
		{
			param2 = 0,
			name = "air",
			prob = 254
		},
		{
			param2 = 0,
			name = "air",
			prob = 254
		},
		{
			param2 = 0,
			name = "air",
			prob = 254
		},
		{
			param2 = 0,
			name = "air",
			prob = 254
		},
		{
			param2 = 0,
			name = "default:sandstonebrick",
			prob = 254
		},
		{
			param2 = 0,
			name = "default:sandstonebrick",
			prob = 254
		},
		{
			param2 = 0,
			name = "default:sandstonebrick",
			prob = 254
		},
		{
			param2 = 0,
			name = "default:sandstonebrick",
			prob = 254
		},
		{
			param2 = 0,
			name = "default:sandstonebrick",
			prob = 254
		},
		{
			param2 = 0,
			name = "default:sandstonebrick",
			prob = 254
		},
		{
			param2 = 0,
			name = "default:sandstonebrick",
			prob = 254
		},
		{
			param2 = 0,
			name = "default:sandstonebrick",
			prob = 254
		},
		{
			param2 = 0,
			name = "default:sandstonebrick",
			prob = 254
		},
		{
			param2 = 0,
			name = "default:sandstonebrick",
			prob = 254
		},
		{
			param2 = 0,
			name = "default:sandstonebrick",
			prob = 254
		},
		{
			param2 = 0,
			name = "default:sandstonebrick",
			prob = 254
		},
		{
			param2 = 0,
			name = "default:sandstonebrick",
			prob = 254
		},
		{
			param2 = 0,
			name = "default:sandstonebrick",
			prob = 254
		},
		{
			param2 = 0,
			name = "default:sandstonebrick",
			prob = 254
		},
		{
			param2 = 0,
			name = "default:sandstonebrick",
			prob = 254
		},
		{
			param2 = 0,
			name = "default:sandstonebrick",
			prob = 254
		},
		{
			param2 = 0,
			name = "default:sandstonebrick",
			prob = 254
		},
		{
			param2 = 0,
			name = "default:sandstonebrick",
			prob = 254
		},
		{
			param2 = 0,
			name = "default:sandstonebrick",
			prob = 254
		},
		{
			param2 = 0,
			name = "default:sandstonebrick",
			prob = 254
		},
		{
			param2 = 0,
			name = "default:sandstonebrick",
			prob = 254
		},
		{
			param2 = 0,
			name = "default:sandstonebrick",
			prob = 254
		},
		{
			param2 = 0,
			name = "default:sandstonebrick",
			prob = 254
		},
		{
			param2 = 0,
			name = "default:sandstonebrick",
			prob = 254
		},
		{
			param2 = 0,
			name = "default:sandstonebrick",
			prob = 254
		},
		{
			param2 = 0,
			name = "default:sandstonebrick",
			prob = 254
		},
		{
			param2 = 0,
			name = "default:sandstonebrick",
			prob = 254
		},
		{
			param2 = 0,
			name = "default:sandstonebrick",
			prob = 254
		},
		{
			param2 = 0,
			name = "default:sandstonebrick",
			prob = 254
		},
		{
			param2 = 0,
			name = "default:sandstonebrick",
			prob = 254
		},
		{
			param2 = 0,
			name = "default:sandstonebrick",
			prob = 254
		},
		{
			param2 = 0,
			name = "default:sandstonebrick",
			prob = 254
		},
		{
			param2 = 0,
			name = "default:sandstonebrick",
			prob = 254
		},
		{
			param2 = 0,
			name = "default:sandstonebrick",
			prob = 254
		},
		{
			param2 = 0,
			name = "default:sandstonebrick",
			prob = 254
		},
		{
			param2 = 0,
			name = "default:sandstonebrick",
			prob = 254
		},
		{
			param2 = 0,
			name = "default:sandstonebrick",
			prob = 254
		},
		{
			param2 = 0,
			name = "default:sandstonebrick",
			prob = 254
		},
		{
			param2 = 0,
			name = "default:sandstonebrick",
			prob = 254
		},
		{
			param2 = 0,
			name = "default:sandstonebrick",
			prob = 254
		},
		{
			param2 = 0,
			name = "default:sandstonebrick",
			prob = 254
		},
		{
			param2 = 0,
			name = "air",
			prob = 254
		},
		{
			param2 = 0,
			name = "default:sandstonebrick",
			prob = 254
		},
		{
			param2 = 0,
			name = "default:sandstonebrick",
			prob = 254
		},
		{
			param2 = 0,
			name = "default:sandstonebrick",
			prob = 254
		},
		{
			param2 = 0,
			name = "default:sandstone",
			prob = 254
		},
		{
			param2 = 0,
			name = "air",
			prob = 254
		},
		{
			param2 = 0,
			name = "air",
			prob = 254
		},
		{
			param2 = 0,
			name = "air",
			prob = 254
		},
		{
			param2 = 0,
			name = "air",
			prob = 254
		},
		{
			param2 = 0,
			name = "air",
			prob = 254
		},
		{
			param2 = 0,
			name = "air",
			prob = 254
		},
		{
			param2 = 0,
			name = "air",
			prob = 254
		},
		{
			param2 = 0,
			name = "air",
			prob = 254
		},
		{
			param2 = 0,
			name = "air",
			prob = 254
		},
		{
			param2 = 0,
			name = "air",
			prob = 254
		},
		{
			param2 = 0,
			name = "air",
			prob = 254
		},
		{
			param2 = 0,
			name = "default:sandstone",
			prob = 254
		},
		{
			param2 = 0,
			name = "default:sandstonebrick",
			prob = 254
		},
		{
			param2 = 0,
			name = "default:sandstonebrick",
			prob = 254
		},
		{
			param2 = 0,
			name = "default:sandstonebrick",
			prob = 254
		},
		{
			param2 = 0,
			name = "air",
			prob = 254
		},
		{
			param2 = 0,
			name = "air",
			prob = 254
		},
		{
			param2 = 0,
			name = "air",
			prob = 254
		},
		{
			param2 = 0,
			name = "default:sandstonebrick",
			prob = 254
		},
		{
			param2 = 0,
			name = "default:sandstonebrick",
			prob = 254
		},
		{
			param2 = 0,
			name = "default:sandstone",
			prob = 254
		},
		{
			param2 = 0,
			name = "air",
			prob = 254
		},
		{
			param2 = 0,
			name = "air",
			prob = 254
		},
		{
			param2 = 0,
			name = "air",
			prob = 254
		},
		{
			param2 = 0,
			name = "air",
			prob = 254
		},
		{
			param2 = 0,
			name = "air",
			prob = 254
		},
		{
			param2 = 0,
			name = "air",
			prob = 254
		},
		{
			param2 = 0,
			name = "air",
			prob = 254
		},
		{
			param2 = 0,
			name = "air",
			prob = 254
		},
		{
			param2 = 0,
			name = "air",
			prob = 254
		},
		{
			param2 = 0,
			name = "air",
			prob = 254
		},
		{
			param2 = 0,
			name = "air",
			prob = 254
		},
		{
			param2 = 0,
			name = "default:sandstone",
			prob = 254
		},
		{
			param2 = 0,
			name = "default:sandstonebrick",
			prob = 254
		},
		{
			param2 = 0,
			name = "default:sandstonebrick",
			prob = 254
		},
		{
			param2 = 0,
			name = "air",
			prob = 254
		},
		{
			param2 = 0,
			name = "air",
			prob = 254
		},
		{
			param2 = 0,
			name = "air",
			prob = 254
		},
		{
			param2 = 0,
			name = "air",
			prob = 254
		},
		{
			param2 = 0,
			name = "air",
			prob = 254
		},
		{
			param2 = 0,
			name = "default:sandstonebrick",
			prob = 254
		},
		{
			param2 = 0,
			name = "default:sandstonebrick",
			prob = 254
		},
		{
			param2 = 0,
			name = "air",
			prob = 254
		},
		{
			param2 = 0,
			name = "air",
			prob = 254
		},
		{
			param2 = 0,
			name = "air",
			prob = 254
		},
		{
			param2 = 0,
			name = "air",
			prob = 254
		},
		{
			param2 = 0,
			name = "air",
			prob = 254
		},
		{
			param2 = 0,
			name = "air",
			prob = 254
		},
		{
			param2 = 0,
			name = "air",
			prob = 254
		},
		{
			param2 = 0,
			name = "air",
			prob = 254
		},
		{
			param2 = 0,
			name = "air",
			prob = 254
		},
		{
			param2 = 0,
			name = "air",
			prob = 254
		},
		{
			param2 = 0,
			name = "air",
			prob = 254
		},
		{
			param2 = 0,
			name = "default:sandstonebrick",
			prob = 254
		},
		{
			param2 = 0,
			name = "default:sandstonebrick",
			prob = 254
		},
		{
			param2 = 0,
			name = "air",
			prob = 254
		},
		{
			param2 = 0,
			name = "air",
			prob = 254
		},
		{
			param2 = 0,
			name = "air",
			prob = 254
		},
		{
			param2 = 0,
			name = "air",
			prob = 254
		},
		{
			param2 = 0,
			name = "air",
			prob = 254
		},
		{
			param2 = 0,
			name = "air",
			prob = 254
		},
		{
			param2 = 0,
			name = "air",
			prob = 254
		},
		{
			param2 = 0,
