{
	yslice_prob = {
		{
			prob = 254,
			ypos = 0
		},
		{
			prob = 254,
			ypos = 1
		},
		{
			prob = 254,
			ypos = 2
		},
		{
			prob = 254,
			ypos = 3
		},
		{
			prob = 254,
			ypos = 4
		},
		{
			prob = 254,
			ypos = 5
		},
		{
			prob = 254,
			ypos = 6
		},
		{
			prob = 254,
			ypos = 7
		},
		{
			prob = 254,
			ypos = 8
		},
		{
			prob = 254,
			ypos = 9
		}
	},
	data = {
		{
			param2 = 0,
			name = "air",
			prob = 254
		},
		{
			param2 = 0,
			name = "air",
			prob = 254
		},
		{
			param2 = 0,
			name = "air",
			prob = 254
		},
		{
			param2 = 0,
			name = "air",
			prob = 254
		},
		{
			param2 = 0,
			name = "air",
			prob = 254
		},
		{
			param2 = 0,
			name = "air",
			prob = 254
		},
		{
			param2 = 0,
			name = "air",
			prob = 254
		},
		{
			param2 = 0,
			name = "air",
			prob = 254
		},
		{
			param2 = 0,
			name = "air",
			prob = 254
		},
		{
			param2 = 0,
			name = "air",
			prob = 254
		},
		{
			param2 = 0,
			name = "air",
			prob = 254
		},
		{
			param2 = 0,
			name = "air",
			prob = 254
		},
		{
			param2 = 0,
			name = "air",
			prob = 254
		},
		{
			param2 = 0,
			name = "air",
			prob = 254
		},
		{
			param2 = 0,
			name = "air",
			prob = 254
		},
		{
			param2 = 0,
			name = "air",
			prob = 254
		},
		{
			param2 = 0,
			name = "air",
			prob = 254
		},
		{
			param2 = 0,
			name = "air",
			prob = 254
		},
		{
			param2 = 0,
			name = "air",
			prob = 254
		},
		{
			param2 = 0,
			name = "air",
			prob = 254
		},
		{
			param2 = 0,
			name = "air",
			prob = 254
		},
		{
			param2 = 0,
			name = "air",
			prob = 254
		},
		{
			param2 = 0,
			name = "mapgen:willow_leaves",
			prob = 254
		},
		{
			param2 = 0,
			name = "air",
			prob = 254
		},
		{
			param2 = 0,
			name = "air",
			prob = 254
		},
		{
			param2 = 0,
			name = "air",
			prob = 254
		},
		{
			param2 = 0,
			name = "air",
			prob = 254
		},
		{
			param2 = 0,
			name = "air",
			prob = 254
		},
		{
			param2 = 0,
			name = "air",
			prob = 254
		},
		{
			param2 = 0,
			name = "mapgen:willow_leaves",
			prob = 254
		},
		{
			param2 = 0,
			name = "air",
			prob = 254
		},
		{
			param2 = 0,
			name = "mapgen:willow_leaves",
			prob = 254
		},
		{
			param2 = 0,
			name = "air",
			prob = 254
		},
		{
			param2 = 0,
			name = "air",
			prob = 254
		},
		{
			param2 = 0,
			name = "air",
			prob = 254
		},
		{
			param2 = 0,
			name = "air",
			prob = 254
		},
		{
			param2 = 0,
			name = "mapgen:willow_leaves",
			prob = 254
		},
		{
			param2 = 0,
			name = "mapgen:willow_leaves",
			prob = 254
		},
		{
			param2 = 0,
			name = "mapgen:willow_leaves",
			prob = 254
		},
		{
			param2 = 0,
			name = "air",
			prob = 254
		},
		{
			param2 = 0,
			name = "mapgen:willow_leaves",
			prob = 254
		},
		{
			param2 = 0,
			name = "air",
			prob = 254
		},
		{
			param2 = 0,
			name = "air",
			prob = 254
		},
		{
			param2 = 0,
			name = "mapgen:willow_leaves",
			prob = 254
		},
		{
			param2 = 0,
			name = "mapgen:willow_leaves",
			prob = 254
		},
		{
			param2 = 0,
			name = "mapgen:willow_leaves",
			prob = 254
		},
		{
			param2 = 0,
			name = "mapgen:willow_leaves",
			prob = 254
		},
		{
			param2 = 0,
			name = "mapgen:willow_leaves",
			prob = 254
		},
		{
			param2 = 0,
			name = "air",
			prob = 254
		},
		{
			param2 = 0,
			name = "air",
			prob = 254
		},
		{
			param2 = 0,
			name = "mapgen:willow_leaves",
			prob = 254
		},
		{
			param2 = 0,
			name = "mapgen:willow_leaves",
			prob = 254
		},
		{
			param2 = 0,
			name = "mapgen:willow_leaves",
			prob = 254
		},
		{
			param2 = 0,
			name = "mapgen:willow_leaves",
			prob = 254
		},
		{
			param2 = 0,
			name = "mapgen:willow_leaves",
			prob = 254
		},
		{
			param2 = 0,
			name = "air",
			prob = 254
		},
		{
			param2 = 0,
			name = "air",
			prob = 254
		},
		{
			param2 = 0,
			name = "mapgen:willow_leaves",
			prob = 254
		},
		{
			param2 = 0,
			name = "mapgen:willow_leaves",
			prob = 254
		},
		{
			param2 = 0,
			name = "mapgen:willow_leaves",
			prob = 254
		},
		{
			param2 = 0,
			name = "mapgen:willow_leaves",
			prob = 254
		},
		{
			param2 = 0,
			name = "mapgen:willow_leaves",
			prob = 254
		},
		{
			param2 = 0,
			name = "air",
			prob = 254
		},
		{
			param2 = 0,
			name = "air",
			prob = 254
		},
		{
			param2 = 0,
			name = "air",
			prob = 254
		},
		{
			param2 = 0,
			name = "air",
			prob = 254
		},
		{
			param2 = 0,
			name = "air",
			prob = 254
		},
		{
			param2 = 0,
			name = "air",
			prob = 254
		},
		{
			param2 = 0,
			name = "air",
			prob = 254
		},
		{
			param2 = 0,
			name = "air",
			prob = 254
		},
		{
			param2 = 0,
			name = "air",
			prob = 254
		},
		{
			param2 = 0,
			name = "air",
			prob = 254
		},
		{
			param2 = 0,
			name = "air",
			prob = 254
		},
		{
			param2 = 0,
			name = "air",
			prob = 254
		},
		{
			param2 = 0,
			name = "air",
			prob = 254
		},
		{
			param2 = 0,
			name = "air",
			prob = 254
		},
		{
			param2 = 0,
			name = "air",
			prob = 254
		},
		{
			param2 = 0,
			name = "air",
			prob = 254
		},
		{
			param2 = 0,
			name = "air",
			prob = 254
		},
		{
			param2 = 0,
			name = "air",
			prob = 254
		},
		{
			param2 = 0,
			name = "air",
			prob = 254
		},
		{
			param2 = 0,
			name = "air",
			prob = 254
		},
		{
			param2 = 0,
			name = "air",
			prob = 254
		},
		{
			param2 = 0,
			name = "air",
			prob = 254
		},
		{
			param2 = 0,
			name = "air",
			prob = 254
		},
		{
			param2 = 0,
			name = "air",
			prob = 254
		},
		{
			param2 = 0,
			name = "air",
			prob = 254
		},
		{
			param2 = 0,
			name = "air",
			prob = 254
		},
		{
			param2 = 0,
			name = "air",
			prob = 254
		},
		{
			param2 = 0,
			name = "air",
			prob = 254
		},
		{
			param2 = 0,
			name = "air",
			prob = 254
		},
		{
			param2 = 0,
			name = "air",
			prob = 254
		},
		{
			param2 = 0,
			name = "air",
			prob = 254
		},
		{
			param2 = 0,
			name = "air",
			prob = 254
		},
		{
			param2 = 0,
			name = "air",
			prob = 254
		},
		{
			param2 = 0,
			name = "air",
			prob = 254
		},
		{
			param2 = 0,
			name = "air",
			prob = 254
		},
		{
			param2 = 0,
			name = "mapgen:willow_leaves",
			prob = 254
		},
		{
			param2 = 0,
			name = "mapgen:willow_leaves",
			prob = 254
		},
		{
			param2 = 0,
			name = "air",
			prob = 254
		},
		{
			param2 = 0,
			name = "air",
			prob = 254
		},
		{
			param2 = 0,
			name = "air",
			prob = 254
		},
		{
			param2 = 0,
			name = "air",
			prob = 254
		},
		{
			param2 = 0,
			name = "air",
			prob = 254
		},
		{
			param2 = 0,
			name = "mapgen:willow_leaves",
			prob = 254
		},
		{
			param2 = 0,
			name = "mapgen:willow_leaves",
			prob = 254
		},
		{
			param2 = 0,
			name = "air",
			prob = 254
		},
		{
			param2 = 0,
			name = "air",
			prob = 254
		},
		{
			param2 = 0,
			name = "air",
			prob = 254
		},
		{
			param2 = 0,
			name = "air",
			prob = 254
		},
		{
			param2 = 0,
			name = "air",
			prob = 254
		},
		{
			param2 = 0,
			name = "mapgen:willow_leaves",
			prob = 254
		},
		{
			param2 = 0,
			name = "mapgen:willow_leaves",
			prob = 254
		},
		{
			param2 = 0,
			name = "air",
			prob = 254
		},
		{
			param2 = 0,
			name = "air",
			prob = 254
		},
		{
			param2 = 0,
			name = "air",
			prob = 254
		},
		{
			param2 = 0,
			name = "air",
			prob = 254
		},
		{
			param2 = 0,
			name = "air",
			prob = 254
		},
		{
			param2 = 0,
			name = "mapgen:willow_leaves",
			prob = 254
		},
		{
			param2 = 0,
			name = "mapgen:willow_leaves",
			prob = 254
		},
		{
			param2 = 0,
			name = "mapgen:willow_leaves",
			prob = 254
		},
		{
			param2 = 0,
			name = "air",
			prob = 254
		},
		{
			param2 = 0,
			name = "air",
			prob = 254
		},
		{
			param2 = 0,
			name = "air",
			prob = 254
		},
		{
			param2 = 0,
			name = "mapgen:willow_leaves",
			prob = 254
		},
		{
			param2 = 0,
			name = "mapgen:willow_leaves",
			prob = 254
		},
		{
			param2 = 0,
			name = "mapgen:willow_leaves",
			prob = 254
		},
		{
			param2 = 0,
			name = "mapgen:willow_leaves",
			prob = 254
		},
		{
			param2 = 0,
			name = "mapgen:willow_leaves",
			prob = 254
		},
		{
			param2 = 0,
			name = "mapgen:willow_leaves",
			prob = 254
		},
		{
			param2 = 0,
			name = "mapgen:willow_leaves",
			prob = 254
		},
		{
			param2 = 0,
			name = "mapgen:willow_leaves",
			prob = 254
		},
		{
			param2 = 0,
			name = "mapgen:willow_leaves",
			prob = 254
		},
		{
			param2 = 0,
			name = "air",
			prob = 254
		},
		{
			param2 = 0,
			name = "mapgen:willow_leaves",
			prob = 254
		},
		{
			param2 = 0,
			name = "mapgen:willow_leaves",
			prob = 254
		},
		{
			param2 = 0,
			name = "mapgen:willow_leaves",
			prob = 254
		},
		{
			param2 = 0,
			name = "mapgen:willow_leaves",
			prob = 254
		},
		{
			param2 = 0,
			name = "mapgen:willow_leaves",
			prob = 254
		},
		{
			param2 = 0,
			name = "air",
			prob = 254
		},
		{
			param2 = 0,
			name = "air",
			prob = 254
		},
		{
			param2 = 0,
			name = "air",
			prob = 254
		},
		{
			param2 = 22,
			name = "mapgen:willow_tree",
			prob = 254
		},
		{
			param2 = 0,
			name = "air",
			prob = 254
		},
		{
			param2 = 0,
			name = "air",
			prob = 254
		},
		{
			param2 = 0,
			name = "air",
			prob = 254
		},
		{
			param2 = 0,
			name = "air",
			prob = 254
		},
		{
			param2 = 0,
			name = "air",
			prob = 254
		},
		{
			param2 = 0,
			name = "air",
			prob = 254
		},
		{
			param2 = 18,
			name = "mapgen:willow_tree",
			prob = 254
		},
		{
			param2 = 0,
			name = "air",
			prob = 254
		},
		{
			param2 = 0,
			name = "air",
			prob = 254
		},
		{
			param2 = 0,
			name = "air",
			prob = 254
		},
		{
			param2 = 0,
			name = "air",
			prob = 254
		},
		{
			param2 = 0,
			name = "air",
			prob = 254
		},
		{
			param2 = 0,
			name = "air",
			prob = 254
		},
		{
			param2 = 0,
			name = "air",
			prob = 254
		},
		{
			param2 = 0,
			name = "air",
			prob = 254
		},
		{
			param2 = 0,
			name = "air",
			prob = 254
		},
		{
			param2 = 0,
			name = "air",
			prob = 254
		},
		{
			param2 = 0,
			name = "air",
			prob = 254
		},
		{
			param2 = 0,
			name = "air",
			prob = 254
		},
		{
			param2 = 0,
			name = "air",
			prob = 254
		},
		{
			param2 = 0,
			name = "air",
			prob = 254
		},
		{
			param2 = 0,
			name = "air",
			prob = 254
		},
		{
			param2 = 0,
			name = "air",
			prob = 254
		},
		{
			param2 = 0,
			name = "air",
			prob = 254
		},
		{
			param2 = 0,
			name = "air",
			prob = 254
		},
		{
			param2 = 0,
			name = "air",
			prob = 254
		},
		{
			param2 = 0,
			name = "air",
			prob = 254
		},
		{
			param2 = 0,
			name = "air",
			prob = 254
		},
		{
			param2 = 0,
			name = "air",
			prob = 254
		},
		{
			param2 = 0,
			name = "air",
			prob = 254
		},
		{
			param2 = 0,
			name = "air",
			prob = 254
		},
		{
			param2 = 0,
			name = "air",
			prob = 254
		},
		{
			param2 = 0,
			name = "air",
			prob = 254
		},
		{
			param2 = 0,
			name = "air",
			prob = 254
		},
		{
			param2 = 0,
			name = "air",
			prob = 254
		},
		{
			param2 = 0,
			name = "air",
			prob = 254
		},
		{
			param2 = 0,
			name = "air",
			prob = 254
		},
		{
			param2 = 0,
			name = "air",
			prob = 254
		},
		{
			param2 = 0,
			name = "mapgen:willow_leaves",
			prob = 254
		},
		{
			param2 = 0,
			name = "mapgen:willow_leaves",
			prob = 254
		},
		{
			param2 = 0,
			name = "air",
			prob = 254
		},
		{
			param2 = 0,
			name = "air",
			prob = 254
		},
		{
			param2 = 0,
			name = "air",
			prob = 254
		},
		{
			param2 = 0,
			name = "air",
			prob = 254
		},
		{
			param2 = 0,
			name = "air",
			prob = 254
		},
		{
			param2 = 0,
			name = "mapgen:willow_leaves",
			prob = 254
		},
		{
			param2 = 0,
			name = "mapgen:willow_leaves",
			prob = 254
		},
		{
			param2 = 0,
			name = "air",
			prob = 254
		},
		{
			param2 = 0,
			name = "air",
			prob = 254
		},
		{
			param2 = 0,
			name = "mapgen:willow_leaves",
			prob = 254
		},
		{
			param2 = 0,
			name = "air",
			prob = 254
		},
		{
			param2 = 0,
			name = "air",
			prob = 254
		},
		{
			param2 = 0,
			name = "mapgen:willow_leaves",
			prob = 254
		},
		{
			param2 = 0,
			name = "mapgen:willow_leaves",
			prob = 254
		},
		{
			param2 = 0,
			name = "mapgen:willow_leaves",
			prob = 254
		},
		{
			param2 = 0,
			name = "mapgen:willow_leaves",
			prob = 254
		},
		{
			param2 = 0,
			name = "mapgen:willow_leaves",
			prob = 254
		},
		{
			param2 = 0,
			name = "mapgen:willow_leaves",
			prob = 254
		},
		{
			param2 = 0,
			name = "mapgen:willow_leaves",
			prob = 254
		},
		{
			param2 = 0,
			name = "mapgen:willow_leaves",
			prob = 254
		},
		{
			param2 = 0,
			name = "air",
			prob = 254
		},
		{
			param2 = 0,
			name = "mapgen:willow_leaves",
			prob = 254
		},
		{
			param2 = 0,
			name = "mapgen:willow_leaves",
			prob = 254
		},
		{
			param2 = 0,
			name = "mapgen:willow_leaves",
			prob = 254
		},
		{
			param2 = 0,
			name = "mapgen:willow_leaves",
			prob = 254
		},
		{
			param2 = 0,
			name = "mapgen:willow_leaves",
			prob = 254
		},
		{
			param2 = 0,
			name = "air",
			prob = 254
		},
		{
			param2 = 0,
			name = "air",
			prob = 254
		},
		{
			param2 = 0,
			name = "air",
			prob = 254
		},
		{
			param2 = 0,
			name = "air",
			prob = 254
		},
		{
			param2 = 22,
			name = "mapgen:willow_tree",
			prob = 254
		},
		{
			param2 = 22,
			name = "mapgen:willow_tree",
			prob = 254
		},
		{
			param2 = 0,
			name = "air",
			prob = 254
		},
		{
			param2 = 0,
			name = "air",
			prob = 254
		},
		{
			param2 = 0,
			name = "air",
			prob = 254
		},
		{
			param2 = 0,
			name = "air",
			prob = 254
		},
		{
			param2 = 0,
			name = "air",
			prob = 254
		},
		{
			param2 = 12,
			name = "mapgen:willow_tree",
			prob = 254
		},
		{
			param2 = 7,
			name = "mapgen:willow_tree",
			prob = 254
		},
		{
			param2 = 0,
			name = "air",
			prob = 254
		},
		{
			param2 = 0,
			name = "air",
			prob = 254
		},
		{
			param2 = 0,
			name = "mapgen:willow_leaves",
			prob = 254
		},
		{
			param2 = 0,
			name = "air",
			prob = 254
		},
		{
			param2 = 0,
			name = "air",
			prob = 254
		},
		{
			param2 = 3,
			name = "mapgen:willow_tree",
			prob = 254
		},
		{
			param2 = 0,
			name = "air",
			prob = 254
		},
		{
			param2 = 0,
			name = "air",
			prob = 254
		},
		{
			param2 = 0,
			name = "air",
			prob = 254
		},
		{
			param2 = 0,
			name = "mapgen:willow_leaves",
			prob = 254
		},
		{
			param2 = 0,
			name = "air",
			prob = 254
		},
		{
			param2 = 0,
			name = "air",
			prob = 254
		},
		{
			param2 = 3,
			name = "mapgen:willow_tree",
			prob = 254
		},
		{
			param2 = 0,
			name = "air",
			prob = 254
		},
		{
			param2 = 0,
			name = "air",
			prob = 254
		},
		{
			param2 = 0,
			name = "air",
			prob = 254
		},
		{
			param2 = 0,
			name = "mapgen:willow_leaves",
			prob = 254
		},
		{
			param2 = 0,
			name = "air",
			prob = 254
		},
		{
			param2 = 0,
			name = "air",
			prob = 254
		},
		{
			param2 = 3,
			name = "mapgen:willow_tree",
			prob = 254
		},
		{
			param2 = 0,
			name = "air",
			prob = 254
		},
		{
			param2 = 0,
			name = "air",
			prob = 254
		},
		{
			param2 = 0,
			name = "mapgen:willow_leaves",
			prob = 254
		},
		{
			param2 = 0,
			name = "mapgen:willow_leaves",
			prob = 254
		},
		{
			param2 = 0,
			name = "air",
			prob = 254
		},
		{
			param2 = 0,
			name = "air",
			prob = 254
		},
		{
			param2 = 3,
			name = "mapgen:willow_tree",
			prob = 254
		},
		{
			param2 = 0,
			name = "air",
			prob = 254
		},
		{
			param2 = 0,
			name = "air",
			prob = 254
		},
		{
			param2 = 0,
			name = "mapgen:willow_leaves",
			prob = 254
		},
		{
			param2 = 0,
			name = "mapgen:willow_leaves",
			prob = 254
		},
		{
			param2 = 0,
			name = "air",
			prob = 254
		},
		{
			param2 = 0,
			name = "air",
			prob = 254
		},
		{
			param2 = 3,
			name = "mapgen:willow_tree",
			prob = 254
		},
		{
			param2 = 0,
			name = "air",
			prob = 254
		},
		{
			param2 = 0,
			name = "air",
			prob = 254
		},
		{
			param2 = 0,
			name = "mapgen:willow_leaves",
			prob = 254
		},
		{
			param2 = 0,
			name = "mapgen:willow_leaves",
			prob = 254
		},
		{
			param2 = 0,
			name = "air",
			prob = 254
		},
		{
			param2 = 0,
			name = "mapgen:willow_leaves",
			prob = 254
		},
		{
			param2 = 3,
			name = "mapgen:willow_tree",
			prob = 254
		},
		{
			param2 = 0,
			name = "mapgen:willow_leaves",
			prob = 254
		},
		{
			param2 = 0,
			name = "air",
			prob = 254
		},
		{
			param2 = 0,
			name = "mapgen:willow_leaves",
			prob = 254
		},
		{
			param2 = 0,
			name = "mapgen:willow_leaves",
			prob = 254
		},
		{
			param2 = 0,
			name = "mapgen:willow_leaves",
			prob = 254
		},
		{
			param2 = 0,
			name = "mapgen:willow_leaves",
			prob = 254
		},
		{
			param2 = 3,
			name = "mapgen:willow_tree",
			prob = 254
		},
		{
			param2 = 0,
			name = "mapgen:willow_leaves",
			prob = 254
		},
		{
			param2 = 0,
			name = "mapgen:willow_leaves",
			prob = 254
		},
		{
			param2 = 0,
			name = "mapgen:willow_leaves",
			prob = 254
		},
		{
			param2 = 0,
			name = "air",
			prob = 254
		},
		{
			param2 = 0,
			name = "mapgen:willow_leaves",
			prob = 254
		},
		{
			param2 = 0,
			name = "mapgen:willow_leaves",
			prob = 254
		},
		{
			param2 = 0,
			name = "mapgen:willow_leaves",
			prob = 254
		},
		{
			param2 = 0,
			name = "mapgen:willow_leaves",
			prob = 254
		},
		{
			param2 = 0,
			name = "mapgen:willow_leaves",
			prob = 254
		},
		{
			param2 = 0,
			name = "air",
			prob = 254
		},
		{
			param2 = 0,
			name = "air",
			prob = 254
		},
		{
			param2 = 0,
			name = "air",
			prob = 254
		},
		{
			param2 = 0,
			name = "air",
			prob = 254
		},
		{
			param2 = 22,
			name = "mapgen:willow_tree",
			prob = 254
		},
		{
			param2 = 0,
			name = "air",
			prob = 254
		},
		{
			param2 = 0,
			name = "air",
			prob = 254
		},
		{
			param2 = 0,
			name = "air",
			prob = 254
		},
		{
			param2 = 0,
			name = "air",
			prob = 254
		},
		{
			param2 = 0,
			name = "air",
			prob = 254
		},
		{
			param2 = 0,
			name = "air",
			prob = 254
		},
		{
			param2 = 7,
			name = "mapgen:willow_tree",
			prob = 254
		},
		{
			param2 = 0,
			name = "air",
			prob = 254
		},
		{
			param2 = 0,
			name = "air",
			prob = 254
		},
		{
			param2 = 0,
			name = "air",
			prob = 254
		},
		{
			param2 = 0,
			name = "air",
			prob = 254
		},
		{
			param2 = 0,
			name = "air",
			prob = 254
		},
		{
			param2 = 0,
			name = "air",
			prob = 254
		},
		{
			param2 = 7,
			name = "mapgen:willow_tree",
			prob = 254
		},
		{
			param2 = 0,
			name = "air",
			prob = 254
		},
		{
			param2 = 0,
			name = "air",
			prob = 254
		},
		{
			param2 = 0,
			name = "mapgen:willow_leaves",
			prob = 254
		},
		{
			param2 = 0,
			name = "air",
			prob = 254
		},
		{
			param2 = 0,
			name = "air",
			prob = 254
		},
		{
			param2 = 0,
			name = "air",
			prob = 254
		},
		{
			param2 = 0,
			name = "air",
			prob = 254
		},
		{
			param2 = 0,
			name = "air",
			prob = 254
		},
		{
			param2 = 0,
			name = "air",
			prob = 254
		},
		{
			param2 = 0,
			name = "mapgen:willow_leaves",
			prob = 254
		},
		{
			param2 = 0,
			name = "mapgen:willow_leaves",
			prob = 254
		},
		{
			param2 = 0,
			name = "air",
			prob = 254
		},
		{
			param2 = 0,
			name = "air",
			prob = 254
		},
		{
			param2 = 0,
			name = "air",
			prob = 254
		},
		{
			param2 = 0,
			name = "air",
			prob = 254
		},
		{
			param2 = 0,
			name = "air",
			prob = 254
		},
		{
			param2 = 0,
			name = "mapgen:willow_leaves",
			prob = 254
		},
		{
			param2 = 0,
			name = "mapgen:willow_leaves",
			prob = 254
		},
		{
			param2 = 0,
			name = "air",
			prob = 254
		},
		{
			param2 = 0,
			name = "air",
			prob = 254
		},
		{
			param2 = 0,
			name = "air",
			prob = 254
		},
		{
			param2 = 0,
			name = "air",
			prob = 254
		},
		{
			param2 = 0,
			name = "air",
			prob = 254
		},
		{
			param2 = 0,
			name = "mapgen:willow_leaves",
			prob = 254
		},
		{
			param2 = 0,
			name = "mapgen:willow_leaves",
			prob = 254
		},
		{
			param2 = 0,
			name = "air",
			prob = 254
		},
		{
			param2 = 0,
			name = "air",
			prob = 254
		},
		{
			param2 = 0,
			name = "air",
			prob = 254
		},
		{
			param2 = 0,
			name = "air",
			prob = 254
		},
		{
			param2 = 0,
			name = "air",
			prob = 254
		},
		{
			param2 = 0,
			name = "mapgen:willow_leaves",
			prob = 254
		},
		{
			param2 = 0,
			name = "mapgen:willow_leaves",
			prob = 254
		},
		{
			param2 = 0,
			name = "air",
			prob = 254
		},
		{
			param2 = 0,
			name = "air",
			prob = 254
		},
		{
			param2 = 0,
			name = "mapgen:willow_leaves",
			prob = 254
		},
		{
			param2 = 0,
			name = "air",
			prob = 254
		},
		{
			param2 = 0,
			name = "air",
			prob = 254
		},
		{
			param2 = 0,
			name = "mapgen:willow_leaves",
			prob = 254
		},
		{
			param2 = 0,
			name = "mapgen:willow_leaves",
			prob = 254
		},
		{
			param2 = 0,
			name = "mapgen:willow_leaves",
			prob = 254
		},
		{
			param2 = 0,
			name = "mapgen:willow_leaves",
			prob = 254
		},
		{
			param2 = 0,
			name = "mapgen:willow_leaves",
			prob = 254
		},
		{
			param2 = 0,
			name = "mapgen:willow_leaves",
			prob = 254
		},
		{
			param2 = 0,
			name = "mapgen:willow_leaves",
			prob = 254
		},
		{
			param2 = 0,
			name = "mapgen:willow_leaves",
			prob = 254
		},
		{
			param2 = 0,
			name = "air",
			prob = 254
		},
		{
			param2 = 0,
			name = "mapgen:willow_leaves",
			prob = 254
		},
		{
			param2 = 0,
			name = "mapgen:willow_leaves",
			prob = 254
		},
		{
			param2 = 0,
			name = "mapgen:willow_leaves",
			prob = 254
		},
		{
			param2 = 0,
			name = "mapgen:willow_leaves",
			prob = 254
		},
		{
			param2 = 0,
			name = "mapgen:willow_leaves",
			prob = 254
		},
		{
			param2 = 0,
			name = "air",
			prob = 254
		},
		{
			param2 = 0,
			name = "air",
			prob = 254
		},
		{
			param2 = 0,
			name = "air",
			prob = 254
		},
		{
			param2 = 0,
			name = "air",
			prob = 254
		},
		{
			param2 = 0,
			name = "air",
			prob = 254
		},
		{
			param2 = 0,
			name = "air",
			prob = 254
		},
		{
			param2 = 0,
			name = "air",
			prob = 254
		},
		{
			param2 = 0,
			name = "air",
			prob = 254
		},
		{
			param2 = 0,
			name = "air",
			prob = 254
		},
		{
			param2 = 0,
			name = "air",
			prob = 254
		},
		{
			param2 = 0,
			name = "air",
			prob = 254
		},
		{
			param2 = 0,
			name = "air",
			prob = 254
		},
		{
			param2 = 0,
			name = "air",
			prob = 254
		},
		{
			param2 = 0,
			name = "air",
			prob = 254
		},
		{
			param2 = 0,
			name = "air",
			prob = 254
		},
		{
			param2 = 0,
			name = "air",
			prob = 254
		},
		{
			param2 = 0,
			name = "air",
			prob = 254
		},
		{
			param2 = 0,
			name = "air",
			prob = 254
		},
		{
			param2 = 0,
			name = "air",
			prob = 254
		},
		{
			param2 = 0,
			name = "air",
			prob = 254
		},
		{
			param2 = 0,
			name = "air",
			prob = 254
		},
		{
			param2 = 0,
			name = "air",
			prob = 254
		},
		{
			param2 = 0,
			name = "mapgen:willow_leaves",
			prob = 254
		},
		{
			param2 = 0,
			name = "air",
			prob = 254
		},
		{
			param2 = 0,
			name = "air",
			prob = 254
		},
		{
			param2 = 0,
			name = "air",
			prob = 254
		},
		{
			param2 = 0,
			name = "air",
			prob = 254
		},
		{
			param2 = 0,
			name = "air",
			prob = 254
		},
		{
			param2 = 0,
			name = "air",
			prob = 254
		},
		{
			param2 = 0,
			name = "mapgen:willow_leaves",
			prob = 254
		},
		{
			param2 = 0,
			name = "air",
			prob = 254
		},
		{
			param2 = 0,
			name = "air",
			prob = 254
		},
		{
			param2 = 0,
			name = "air",
			prob = 254
		},
		{
			param2 = 0,
			name = "air",
			prob = 254
		},
		{
			param2 = 0,
			name = "air",
			prob = 254
		},
		{
			param2 = 0,
			name = "air",
			prob = 254
		},
		{
			param2 = 0,
			name = "mapgen:willow_leaves",
			prob = 254
		},
		{
			param2 = 0,
			name = "air",
			prob = 254
		},
		{
			param2 = 0,
			name = "air",
			prob = 254
		},
		{
			param2 = 0,
			name = "air",
			prob = 254
		},
		{
			param2 = 0,
			name = "air",
			prob = 254
		},
		{
			param2 = 0,
			name = "air",
			prob = 254
		},
		{
			param2 = 0,
			name = "mapgen:willow_leaves",
			prob = 254
		},
		{
			param2 = 0,
			name = "mapgen:willow_leaves",
			prob = 254
		},
		{
			param2 = 0,
			name = "air",
			prob = 254
		},
		{
			param2 = 0,
			name = "air",
			prob = 254
		},
		{
			param2 = 0,
			name = "air",
			prob = 254
		},
		{
			param2 = 0,
			name = "air",
			prob = 254
		},
		{
			param2 = 0,
			name = "air",
			prob = 254
		},
		{
			param2 = 0,
			name = "mapgen:willow_leaves",
			prob = 254
		},
		{
			param2 = 0,
			name = "mapgen:willow_leaves",
			prob = 254
		},
		{
			param2 = 0,
			name = "mapgen:willow_leaves",
			prob = 254
		},
		{
			param2 = 0,
			name = "air",
			prob = 254
		},
		{
			param2 = 0,
			name = "air",
			prob = 254
		},
		{
			param2 = 0,
			name = "air",
			prob = 254
		},
		{
			param2 = 0,
			name = "mapgen:willow_leaves",
			prob = 254
		},
		{
			param2 = 0,
			name = "mapgen:willow_leaves",
			prob = 254
		},
		{
			param2 = 0,
			name = "mapgen:willow_leaves",
			prob = 254
		},
		{
			param2 = 0,
			name = "mapgen:willow_leaves",
			prob = 254
		},
		{
			param2 = 0,
			name = "mapgen:willow_leaves",
			prob = 254
		},
		{
			param2 = 0,
			name = "mapgen:willow_leaves",
			prob = 254
		},
		{
			param2 = 0,
			name = "mapgen:willow_leaves",
			prob = 254
		},
		{
			param2 = 0,
			name = "mapgen:willow_leaves",
			prob = 254
		},
		{
			param2 = 0,
			name = "mapgen:willow_leaves",
			prob = 254
		},
		{
			param2 = 0,
			name = "air",
			prob = 254
		},
		{
			param2 = 0,
			name = "mapgen:willow_leaves",
			prob = 254
		},
		{
			param2 = 0,
			name = "mapgen:willow_leaves",
			prob = 254
		},
		{
			param2 = 0,
			name = "mapgen:willow_leaves",
			prob = 254
		},
		{
			param2 = 0,
			name = "mapgen:willow_leaves",
			prob = 254
		},
		{
			param2 = 0,
			name = "mapgen:willow_leaves",
			prob = 254
		},
		{
			param2 = 0,
			name = "air",
			prob = 254
		},
		{
			param2 = 0,
			name = "air",
			prob = 254
		},
		{
			param2 = 0,
			name = "air",
			prob = 254
		},
		{
			param2 = 0,
			name = "air",
			prob = 254
		},
		{
			param2 = 0,
			name = "air",
			prob = 254
		},
		{
			param2 = 0,
			name = "air",
			prob = 254
		},
		{
			param2 = 0,
			name = "air",
			prob = 254
		},
		{
			param2 = 0,
			name = "air",
			prob = 254
		},
		{
			param2 = 0,
			name = "air",
			prob = 254
		},
		{
			param2 = 0,
			name = "air",
			prob = 254
		},
		{
			param2 = 0,
			name = "air",
			prob = 254
		},
		{
			param2 = 0,
			name = "air",
			prob = 254
		},
		{
			param2 = 0,
			name = "air",
			prob = 254
		},
		{
			param2 = 0,
			name = "air",
			prob = 254
		},
		{
			param2 = 0,
			name = "air",
			prob = 254
		},
		{
			param2 = 0,
			name = "air",
			prob = 254
		},
		{
			param2 = 0,
			name = "air",
			prob = 254
		},
		{
			param2 = 0,
			name = "air",
			prob = 254
		},
		{
			param2 = 0,
			name = "air",
			prob = 254
		},
		{
			param2 = 0,
			name = "air",
			prob = 254
		},
		{
			param2 = 0,
			name = "air",
			prob = 254
		},
		{
			param2 = 0,
			name = "air",
			prob = 254
		},
		{
			param2 = 0,
			name = "air",
			prob = 254
		},
		{
			param2 = 0,
			name = "air",
			prob = 254
		},
		{
			param2 = 0,
			name = "air",
			prob = 254
		},
		{
			param2 = 0,
			name = "air",
			prob = 254
		},
		{
			param2 = 0,
			name = "mapgen:willow_leaves",
			prob = 254
		},
		{
			param2 = 0,
			name = "air",
			prob = 254
		},
		{
			param2 = 0,
			name = "air",
			prob = 254
		},
		{
			param2 = 0,
			name = "air",
			prob = 254
		},
		{
			param2 = 0,
			name = "air",
			prob = 254
		},
		{
			param2 = 0,
			name = "mapgen:willow_leaves",
			prob = 254
		},
		{
			param2 = 0,
			name = "air",
			prob = 254
		},
		{
			param2 = 0,
			name = "mapgen:willow_leaves",
			prob = 254
		},
		{
			param2 = 0,
			name = "mapgen:willow_leaves",
			prob = 254
		},
		{
			param2 = 0,
			name = "air",
			prob = 254
		},
		{
			param2 = 0,
			name = "air",
			prob = 254
		},
		{
			param2 = 0,
			name = "mapgen:willow_leaves",
			prob = 254
		},
		{
			param2 = 0,
			name = "mapgen:willow_leaves",
			prob = 254
		},
		{
			param2 = 0,
			name = "mapgen:willow_leaves",
			prob = 254
		},
		{
			param2 = 0,
			name = "mapgen:willow_leaves",
			prob = 254
		},
		{
			param2 = 0,
			name = "mapgen:willow_leaves",
			prob = 254
		},
		{
			param2 = 0,
			name = "air",
			prob = 254
		},
		{
			param2 = 0,
			name = "air",
			prob = 254
		},
		{
			param2 = 0,
			name = "mapgen:willow_leaves",
			prob = 254
		},
		{
			param2 = 0,
			name = "mapgen:willow_leaves",
			prob = 254
		},
		{
			param2 = 0,
			name = "mapgen:willow_leaves",
			prob = 254
		},
		{
			param2 = 0,
			name = "mapgen:willow_leaves",
			prob = 254
		},
		{
			param2 = 0,
			name = "mapgen:willow_leaves",
			prob = 254
		},
		{
			param2 = 0,
			name = "air",
			prob = 254
		},
		{
			param2 = 0,
			name = "air",
			prob = 254
		},
		{
			param2 = 0,
			name = "mapgen:willow_leaves",
			prob = 254
		},
		{
			param2 = 0,
			name = "mapgen:willow_leaves",
			prob = 254
		},
		{
			param2 = 0,
			name = "mapgen:willow_leaves",
			prob = 254
		},
		{
			param2 = 0,
			name = "mapgen:willow_leaves",
			prob = 254
		},
		{
			param2 = 0,
			name = "mapgen:willow_leaves",
			prob = 254
		},
		{
			param2 = 0,
			name = "air",
			prob = 254
		},
		{
			param2 = 0,
			name = "air",
			prob = 254
		},
		{
			param2 = 0,
			name = "mapgen:willow_leaves",
			prob = 254
		},
		{
			param2 = 0,
			name = "mapgen:willow_leaves",
			prob = 254
		},
		{
			param2 = 0,
			name = "mapgen:willow_leaves",
			prob = 254
		},
		{
			param2 = 0,
			name = "mapgen:willow_leaves",
			prob = 254
		},
		{
			param2 = 0,
			name = "mapgen:willow_leaves",
			prob = 254
		},
		{
			param2 = 0,
			name = "air",
			prob = 254
		},
		{
			param2 = 0,
			name = "air",
			prob = 254
		},
		{
			param2 = 0,
			name = "air",
			prob = 254
		},
		{
			param2 = 0,
			name = "air",
			prob = 254
		},
		{
			param2 = 0,
			name = "air",
			prob = 254
		},
		{
			param2 = 0,
			name = "air",
			prob = 254
		},
		{
			param2 = 0,
			name = "air",
			prob = 254
		},
		{
			param2 = 0,
			name = "air",
			prob = 254
		}
	},
	size = {
		y = 10,
		x = 7,
		z = 7
	}
}